Workbook

Sheet COMPURACION EMERGENTE
B1: Participaciones Computacion Emergente - Enero-Marzo 2026
A2: Cédula | B2: Apellidos | C2: Sem 1 | D2: Sem 2 | E2: Sem 3 | F2: Sem 4 | G2: Sem 5 | H2: Sem 6 | I2: Sem 7 | J2: Sem 8 | K2: Sem 9 | L2: Sem 10 | M2: Sem 11 | N2: Sem 12 | O2: TOTAL | P2: percent | Q2: 0.05
A3: 31068474 | B3: SASantiago David Aristimuño Yaguaramay | D3: 1 | O3: =SUM('COMPURACION EMERGENTE'!$C3:$N3) -> 1 | P3: =O3/15 -> 0.066666667 | Q3: =P3*5 -> 0.33333333
A4: 29510447 | B4: Albany Veronica Avila Blanco | O4: =SUM('COMPURACION EMERGENTE'!$C4:$N4) -> 0 | P4: =O4/15 -> 0 | Q4: =P4*5 -> 0
A5: 25947729 | B5: JBJhorman Bloom | O5: =SUM('COMPURACION EMERGENTE'!$C5:$N5) -> 0 | P5: =O5/15 -> 0 | Q5: =P5*5 -> 0
A6: 27849723 | B6: Andrés Alonso Camacho López | E6: 1 | F6: 2 | H6: 1 | J6: 1 | K6: 1 | O6: =SUM('COMPURACION EMERGENTE'!$C6:$N6) -> 6 | P6: =O6/15 -> 0.4 | Q6: =P6*5 -> 2
A7: 30057442 | B7: Beatriz Elena Cardozo López | O7: =SUM('COMPURACION EMERGENTE'!$C7:$N7) -> 0 | P7: =O7/15 -> 0 | Q7: =P7*5 -> 0
A8: 28021957 | B8: CCCarlo Carpentieri Perez | O8: =SUM('COMPURACION EMERGENTE'!$C8:$N8) -> 0 | P8: =O8/15 -> 0 | Q8: =P8*5 -> 0
A9: 29508689 | B9: Ramón Carrasquel | D9: 1 | E9: 2 | F9: 2 | H9: 1 | J9: 1 | K9: 1 | L9: 1 | M9: 1 | O9: =SUM('COMPURACION EMERGENTE'!$C9:$N9) -> 10 | P9: =O9/15 -> 0.66666667 | Q9: =P9*5 -> 3.3333333
A10: 30496325 | B10: LCLuis Carreño | D10: 1 | E10: 1 | O10: =SUM('COMPURACION EMERGENTE'!$C10:$N10) -> 2 | P10: =O10/15 -> 0.13333333 | Q10: =P10*5 -> 0.66666667
A11: 30358773 | B11: Nicola Colarusso | D11: 2 | E11: 2 | F11: 2 | H11: 1 | J11: 1 | K11: 1 | O11: =SUM('COMPURACION EMERGENTE'!$C11:$N11) -> 9 | P11: =O11/15 -> 0.6 | Q11: =P11*5 -> 3
A12: 29741760 | B12: Diego De Jesús | O12: =SUM('COMPURACION EMERGENTE'!$C12:$N12) -> 0 | P12: =O12/15 -> 0 | Q12: =P12*5 -> 0
A13: 29983279 | B13: JDJuan Diaz | O13: =SUM('COMPURACION EMERGENTE'!$C13:$N13) -> 0 | P13: =O13/15 -> 0 | Q13: =P13*5 -> 0
A14: 30497244 | B14: AEAsier Errasti | O14: =SUM('COMPURACION EMERGENTE'!$C14:$N14) -> 0 | P14: =O14/15 -> 0 | Q14: =P14*5 -> 0
A15: 30030632 | B15: Gabriel Jesus Flores Baez | O15: =SUM('COMPURACION EMERGENTE'!$C15:$N15) -> 0 | P15: =O15/15 -> 0 | Q15: =P15*5 -> 0
A16: 30579903 | B16: Jose Ignacio Francisco alvarez | D16: 1 | E16: 1 | G16: 1 | K16: 1 | O16: =SUM('COMPURACION EMERGENTE'!$C16:$N16) -> 4 | P16: =O16/15 -> 0.26666667 | Q16: =P16*5 -> 1.3333333
A17: 31065516 | B17: JGJoel Eduardo Gascón Pulido | H17: 1 | O17: =SUM('COMPURACION EMERGENTE'!$C17:$N17) -> 1 | P17: =O17/15 -> 0.066666667 | Q17: =P17*5 -> 0.33333333
A18: 28127331 | B18: Tomas Enrique Gonzalez Adrian | O18: =SUM('COMPURACION EMERGENTE'!$C18:$N18) -> 0 | P18: =O18/15 -> 0 | Q18: =P18*5 -> 0
A19: 30157257 | B19: Karelin Guzman | C19: 1 | E19: 1 | F19: 2 | K19: 1 | O19: =SUM('COMPURACION EMERGENTE'!$C19:$N19) -> 5 | P19: =O19/15 -> 0.33333333 | Q19: =P19*5 -> 1.6666667
A20: 25736710 | B20: Kevin Hernandez | D20: 1 | O20: =SUM('COMPURACION EMERGENTE'!$C20:$N20) -> 1 | P20: =O20/15 -> 0.066666667 | Q20: =P20*5 -> 0.33333333
A21: 29506315 | B21: Alejo Hernandez | O21: =SUM('COMPURACION EMERGENTE'!$C21:$N21) -> 0 | P21: =O21/15 -> 0 | Q21: =P21*5 -> 0
A22: 29662587 | B22: VKVictoria Knuth | O22: =SUM('COMPURACION EMERGENTE'!$C22:$N22) -> 0 | P22: =O22/15 -> 0 | Q22: =P22*5 -> 0
A23: 28462135 | B23: Verónica Luna | O23: =SUM('COMPURACION EMERGENTE'!$C23:$N23) -> 0 | P23: =O23/15 -> 0 | Q23: =P23*5 -> 0
A24: 26895167 | B24: Rodolfo Marin | E24: 1 | O24: =SUM('COMPURACION EMERGENTE'!$C24:$N24) -> 1 | P24: =O24/15 -> 0.066666667 | Q24: =P24*5 -> 0.33333333
A25: 30727488 | B25: VMVictor Martinez | C25: 1 | O25: =SUM('COMPURACION EMERGENTE'!$C25:$N25) -> 1 | P25: =O25/15 -> 0.066666667 | Q25: =P25*5 -> 0.33333333
A26: 30821945 | B26: DMDavid Alejandro Mavares Delgado | O26: =SUM('COMPURACION EMERGENTE'!$C26:$N26) -> 0 | P26: =O26/15 -> 0 | Q26: =P26*5 -> 0
A27: 30330786 | B27: RMRicardo Mazziotta | O27: =SUM('COMPURACION EMERGENTE'!$C27:$N27) -> 0 | P27: =O27/15 -> 0 | Q27: =P27*5 -> 0
A28: 29850491 | B28: Mauricio Méndez | D28: 1 | O28: =SUM('COMPURACION EMERGENTE'!$C28:$N28) -> 1 | P28: =O28/15 -> 0.066666667 | Q28: =P28*5 -> 0.33333333
A29: 30751145 | B29: Annabella Mendoza | O29: =SUM('COMPURACION EMERGENTE'!$C29:$N29) -> 0 | P29: =O29/15 -> 0 | Q29: =P29*5 -> 0
A30: 30612944 | B30: Andrés Alejandro Moreno Lombardo | O30: =SUM('COMPURACION EMERGENTE'!$C30:$N30) -> 0 | P30: =O30/15 -> 0 | Q30: =P30*5 -> 0
A31: 29677861 | B31: Juan Diego Nunes Peraza | O31: =SUM('COMPURACION EMERGENTE'!$C31:$N31) -> 0 | P31: =O31/15 -> 0 | Q31: =P31*5 -> 0
A32: 29661990 | B32: Gabriel Rafael Oba Aye Orozco Rodriguez | O32: =SUM('COMPURACION EMERGENTE'!$C32:$N32) -> 0 | P32: =O32/15 -> 0 | Q32: =P32*5 -> 0
A33: 27472721 | B33: Adrián Eduardo Pinzón Vásquez | O33: =SUM('COMPURACION EMERGENTE'!$C33:$N33) -> 0 | P33: =O33/15 -> 0 | Q33: =P33*5 -> 0
A34: 29887224 | B34: Jonathan Pizzurro Fortun | O34: =SUM('COMPURACION EMERGENTE'!$C34:$N34) -> 0 | P34: =O34/15 -> 0 | Q34: =P34*5 -> 0
A35: 28317519 | B35: CRChristian Ramos | O35: =SUM('COMPURACION EMERGENTE'!$C35:$N35) -> 0 | P35: =O35/15 -> 0 | Q35: =P35*5 -> 0
A36: 30496487 | B36: GRGonzalo Andrés Ramos De Sa Pinto | C36: 1 | E36: 1 | O36: =SUM('COMPURACION EMERGENTE'!$C36:$N36) -> 2 | P36: =O36/15 -> 0.13333333 | Q36: =P36*5 -> 0.66666667
A37: 30411279 | B37: ARAndrea Veronica Reyes Mejia | C37: 1 | D37: 1 | E37: 1 | O37: =SUM('COMPURACION EMERGENTE'!$C37:$N37) -> 3 | P37: =O37/15 -> 0.2 | Q37: =P37*5 -> 1
A38: 26783022 | B38: IRIsabella Rondón | D38: 1 | O38: =SUM('COMPURACION EMERGENTE'!$C38:$N38) -> 1 | P38: =O38/15 -> 0.066666667 | Q38: =P38*5 -> 0.33333333
A39: 31460153 | B39: MRMaria Antonella Ruiz Cianci | O39: =SUM('COMPURACION EMERGENTE'!$C39:$N39) -> 0 | P39: =O39/15 -> 0 | Q39: =P39*5 -> 0
A40: 26994959 | B40: VTVirginia Torrealba | C40: 1 | D40: 2 | E40: 2 | G40: 1 | I40: 2 | J40: 1 | K40: 1 | L40: 1 | M40: 1 | O40: =SUM('COMPURACION EMERGENTE'!$C40:$N40) -> 12 | P40: =O40/15 -> 0.8 | Q40: =P40*5 -> 4
...

Sheet Estandar
A1: Materia: | B1: Computacion Emergente
A2: Trimestre: | B2: 2526-2
A3: Sección: | B3: 1
A5: numero_lista | B5: nombre | C5: apellido | D5: cedula | E5: carnet | F5: Semana 1 | H5: Semana 2 | J5: Semana 3 | L5: Semana 4 | N5: Semana 5 | P5: Semana 6 | R5: Semana 7 | T5: Semana 8 | V5: Semana 9 | X5: Semana 10 | Z5: Semana 11 | AB5: Semana 12
F6: martes | G6: jueves | H6: martes | I6: jueves | J6: martes | K6: jueves | L6: martes | M6: jueves | N6: martes | O6: jueves | P6: martes | Q6: jueves | R6: martes | S6: jueves | T6: martes | U6: jueves | V6: martes | W6: jueves | X6: martes | Y6: jueves | Z6: martes | AA6: jueves | AB6: martes | AC6: jueves
A7: 1 | B7: Santiago David | C7: Aristimuño Yaguaramay | D7: 31068474 | E7: 20231110073 | I7: 1
A8: 2 | B8: Albany Veronica | C8: Avila Blanco | D8: 29510447 | E8: 20181120049
A9: 3 | B9: Jhorman | C9: Bloom | D9: 25947729 | E9: 20171111081
A10: 4 | B10: Andrés Alonso | C10: Camacho López | D10: 27849723 | E10: 20221110382 | K10: 1 | L10: 1 | M10: 1 | Q10: 1 | T10: 1 | W10: 1
A11: 5 | B11: Beatriz Elena | C11: Cardozo López | D11: 30057442 | E11: 20221110439
A12: 6 | B12: Carlo | C12: Carpentieri Perez | D12: 28021957 | E12: 20191110031
A13: 7 | B13: Ramón | C13: Carrasquel | D13: 29508689 | E13: 20231110055 | H13: 1 | J13: 1 | K13: 1 | L13: 1 | M13: 1 | Q13: 1 | T13: 1 | W13: 1 | Y13: 1 | AA13: 1
A14: 8 | B14: Luis | C14: Carreño | D14: 30496325 | E14: 20231110399 | I14: 1 | K14: 1
A15: 9 | B15: Nicola | C15: Colarusso | D15: 30358773 | E15: 20231110531 | I15: 2 | J15: 1 | K15: 1 | L15: 1 | M15: 1 | Q15: 1 | T15: 1 | W15: 1
A16: 10 | B16: Diego | C16: De Jesús | D16: 29741760 | E16: 20211120003
A17: 11 | B17: Juan | C17: Diaz | D17: 29983279 | E17: 20231110841
A18: 12 | B18: Asier | C18: Errasti | D18: 30497244 | E18: 20231110111
A19: 13 | B19: Gabriel Jesus | C19: Flores Baez | D19: 30030632 | E19: 20221110010
A20: 14 | B20: Jose Ignacio | C20: Francisco Alvarez | D20: 30579903 | E20: 20231110114 | H20: 1 | J20: 1 | O20: 1 | V20: 1
A21: 15 | B21: Joel Eduardo | C21: Gascón Pulido | D21: 31065516 | E21: 20231110454 | P21: 1
A22: 16 | B22: Tomas Enrique | C22: Gonzalez Adrian | D22: 28127331
A23: 17 | B23: Karelin | C23: Guzman | D23: 30157257 | E23: 20221110657 | F23: 1 | H23: 1 | L23: 1 | M23: 1 | V23: 1
A24: 18 | B24: Alejo | C24: Hernandez | D24: 29506315 | E24: 20211110506
A25: 19 | B25: Kevin | C25: Hernandez | D25: 25736710 | E25: 20161110446 | I25: 1
A26: 20 | B26: Victoria | C26: Knuth | D26: 29662587 | E26: 20211110471
A27: 21 | B27: Verónica | C27: Luna | D27: 28462135 | E27: 20191120013
A28: 22 | B28: Rodolfo | C28: Marin | D28: 26895167 | E28: 20181110067 | K28: 1
A29: 23 | B29: Victor | C29: Martinez | D29: 30727488 | E29: 20231110234 | F29: 1
A30: 24 | B30: David Alejandro | C30: Mavares Delgado | D30: 30821945 | E30: 20231110297
A31: 25 | B31: Ricardo | C31: Mazziotta | D31: 30330786 | E31: 20231110059
A32: 26 | B32: Mauricio | C32: Méndez | D32: 29850491 | E32: 20221110100 | H32: 1
A33: 27 | B33: Annabella | C33: Mendoza | D33: 30751145 | E33: 20231110519
A34: 28 | B34: Andrés Alejandro | C34: Moreno Lombardo | D34: 30612944 | E34: 20231110217
A35: 29 | B35: Juan Diego | C35: Nunes Peraza | D35: 29677861 | E35: 20211120097
A36: 30 | B36: Gabriel Rafael Oba Aye | C36: Orozco Rodriguez | D36: 29661990 | E36: 20231110045
A37: 31 | B37: Adrián Eduardo | C37: Pinzón Vásquez | D37: 27472721 | E37: 20191110253
A38: 32 | B38: Jonathan | C38: Pizzurro Fortun | D38: 29887224 | E38: 20221110599
A39: 33 | B39: Christian | C39: Ramos | D39: 28317519 | E39: 20191110269
A40: 34 | B40: Gonzalo Andrés | C40: Ramos De Sa Pinto | D40: 30496487 | E40: 20231110123 | F40: 1 | K40: 1
A41: 35 | B41: Andrea Veronica | C41: Reyes Mejia | D41: 30411279 | E41: 20221110183 | F41: 1 | I41: 1 | J41: 1
...

Sheet Cronograma
A1: semana | B1: dia_sesion | C1: tema | D1: tipo_sesion
A2: 1 | B2: 1 | C2: 0 | D2: administrativa
A3: 1 | B3: 2 | C3: 1
A4: 2 | B4: 1 | C4: 2
A5: 2 | B5: 2 | C5: 3
A6: 3 | B6: 1 | C6: 8
A7: 3 | B7: 2 | C7: 3
A8: 4 | B8: 1 | C8: 3
A9: 4 | B9: 2 | C9: 3
A10: 5 | B10: 1 | C10: 0 | D10: evaluacion
A11: 5 | B11: 2 | C11: 0 | D11: evaluacion
A12: 6 | B12: 1 | C12: 6
A13: 6 | B13: 2 | C13: 0 | D13: evaluacion
A14: 7 | B14: 1 | C14: 0 | D14: sin_clase
A15: 7 | B15: 2 | C15: 6
A16: 8 | B16: 1 | C16: 6
A17: 8 | B17: 2 | C17: 0 | D17: evaluacion
A18: 9 | B18: 1 | C18: 0 | D18: evaluacion
A19: 9 | B19: 2 | C19: 9
A20: 10 | B20: 1 | C20: 9
A21: 10 | B21: 2 | C21: 9
A22: 11 | B22: 1 | C22: 0 | D22: evaluacion
A23: 11 | B23: 2 | C23: 9
A24: 12 | B24: 1 | C24: 0 | D24: evaluacion
A25: 12 | B25: 2 | C25: 0 | D25: administrativa
A27: Nota: | B27: tema = código del catálogo de la asignatura. Si la sesión no cubre contenido nuevo: tema = 0 y tipo_sesion indica la causa (evaluacion, repaso, sin_clase, administrativa). Si tema > 0 la sesión es de contenido y tipo_sesion queda vacío.
