Workbook

Sheet COMPURACION EMERGENTE
B1: Participaciones Computacion Emergente - Enero-Marzo 2026
A2: Cédula | B2: Apellidos | C2: Sem 1 | D2: Sem 2 | E2: Sem 3 | F2: Sem 4 | G2: Sem 5 | H2: Sem 6 | I2: Sem 7 | J2: Sem 8 | K2: Sem 9 | L2: Sem 10 | M2: Sem 11 | N2: Sem 12 | O2: TOTAL | P2: percent | Q2: 0.05
A3: 31068474 | B3: SASantiago David Aristimuño Yaguaramay | D3: 1 | O3: =SUM('COMPURACION EMERGENTE'!$C3:$N3) -> 1 | P3: =O3/15 -> 0.066666667 | Q3: =P3*5 -> 0.33333333
A4: 29510447 | B4: Albany Veronica Avila Blanco | O4: =SUM('COMPURACION EMERGENTE'!$C4:$N4) -> 0 | P4: =O4/15 -> 0 | Q4: =P4*5 -> 0
A5: 25947729 | B5: JBJhorman Bloom | O5: =SUM('COMPURACION EMERGENTE'!$C5:$N5) -> 0 | P5: =O5/15 -> 0 | Q5: =P5*5 -> 0
A6: 27849723 | B6: Andrés Alonso Camacho López | E6: 1 | F6: 2 | H6: 1 | J6: 1 | K6: 1 | O6: =SUM('COMPURACION EMERGENTE'!$C6:$N6) -> 6 | P6: =O6/15 -> 0.4 | Q6: =P6*5 -> 2
A7: 30057442 | B7: Beatriz Elena Cardozo López | O7: =SUM('COMPURACION EMERGENTE'!$C7:$N7) -> 0 | P7: =O7/15 -> 0 | Q7: =P7*5 -> 0
A8: 28021957 | B8: CCCarlo Carpentieri Perez | O8: =SUM('COMPURACION EMERGENTE'!$C8:$N8) -> 0 | P8: =O8/15 -> 0 | Q8: =P8*5 -> 0
A9: 29508689 | B9: Ramón Carrasquel | D9: 1 | E9: 2 | F9: 2 | H9: 1 | J9: 1 | K9: 1 | L9: 1 | M9: 1 | O9: =SUM('COMPURACION EMERGENTE'!$C9:$N9) -> 10 | P9: =O9/15 -> 0.66666667 | Q9: =P9*5 -> 3.3333333
A10: 30496325 | B10: LCLuis Carreño | D10: 1 | E10: 1 | O10: =SUM('COMPURACION EMERGENTE'!$C10:$N10) -> 2 | P10: =O10/15 -> 0.13333333 | Q10: =P10*5 -> 0.66666667
A11: 30358773 | B11: Nicola Colarusso | D11: 2 | E11: 2 | F11: 2 | H11: 1 | J11: 1 | K11: 1 | O11: =SUM('COMPURACION EMERGENTE'!$C11:$N11) -> 9 | P11: =O11/15 -> 0.6 | Q11: =P11*5 -> 3
A12: 29741760 | B12: Diego De Jesús | O12: =SUM('COMPURACION EMERGENTE'!$C12:$N12) -> 0 | P12: =O12/15 -> 0 | Q12: =P12*5 -> 0
A13: 29983279 | B13: JDJuan Diaz | O13: =SUM('COMPURACION EMERGENTE'!$C13:$N13) -> 0 | P13: =O13/15 -> 0 | Q13: =P13*5 -> 0
A14: 30497244 | B14: AEAsier Errasti | O14: =SUM('COMPURACION EMERGENTE'!$C14:$N14) -> 0 | P14: =O14/15 -> 0 | Q14: =P14*5 -> 0
A15: 30030632 | B15: Gabriel Jesus Flores Baez | O15: =SUM('COMPURACION EMERGENTE'!$C15:$N15) -> 0 | P15: =O15/15 -> 0 | Q15: =P15*5 -> 0
A16: 30579903 | B16: Jose Ignacio Francisco alvarez | D16: 1 | E16: 1 | G16: 1 | K16: 1 | O16: =SUM('COMPURACION EMERGENTE'!$C16:$N16) -> 4 | P16: =O16/15 -> 0.26666667 | Q16: =P16*5 -> 1.3333333
A17: 31065516 | B17: JGJoel Eduardo Gascón Pulido | H17: 1 | O17: =SUM('COMPURACION EMERGENTE'!$C17:$N17) -> 1 | P17: =O17/15 -> 0.066666667 | Q17: =P17*5 -> 0.33333333
A18: 28127331 | B18: Tomas Enrique Gonzalez Adrian | O18: =SUM('COMPURACION EMERGENTE'!$C18:$N18) -> 0 | P18: =O18/15 -> 0 | Q18: =P18*5 -> 0
A19: 30157257 | B19: Karelin Guzman | C19: 1 | E19: 1 | F19: 2 | K19: 1 | O19: =SUM('COMPURACION EMERGENTE'!$C19:$N19) -> 5 | P19: =O19/15 -> 0.33333333 | Q19: =P19*5 -> 1.6666667
A20: 25736710 | B20: Kevin Hernandez | D20: 1 | O20: =SUM('COMPURACION EMERGENTE'!$C20:$N20) -> 1 | P20: =O20/15 -> 0.066666667 | Q20: =P20*5 -> 0.33333333
A21: 29506315 | B21: Alejo Hernandez | O21: =SUM('COMPURACION EMERGENTE'!$C21:$N21) -> 0 | P21: =O21/15 -> 0 | Q21: =P21*5 -> 0
A22: 29662587 | B22: VKVictoria Knuth | O22: =SUM('COMPURACION EMERGENTE'!$C22:$N22) -> 0 | P22: =O22/15 -> 0 | Q22: =P22*5 -> 0
A23: 28462135 | B23: Verónica Luna | O23: =SUM('COMPURACION EMERGENTE'!$C23:$N23) -> 0 | P23: =O23/15 -> 0 | Q23: =P23*5 -> 0
A24: 26895167 | B24: Rodolfo Marin | E24: 1 | O24: =SUM('COMPURACION EMERGENTE'!$C24:$N24) -> 1 | P24: =O24/15 -> 0.066666667 | Q24: =P24*5 -> 0.33333333
A25: 30727488 | B25: VMVictor Martinez | C25: 1 | O25: =SUM('COMPURACION EMERGENTE'!$C25:$N25) -> 1 | P25: =O25/15 -> 0.066666667 | Q25: =P25*5 -> 0.33333333
A26: 30821945 | B26: DMDavid Alejandro Mavares Delgado | O26: =SUM('COMPURACION EMERGENTE'!$C26:$N26) -> 0 | P26: =O26/15 -> 0 | Q26: =P26*5 -> 0
A27: 30330786 | B27: RMRicardo Mazziotta | O27: =SUM('COMPURACION EMERGENTE'!$C27:$N27) -> 0 | P27: =O27/15 -> 0 | Q27: =P27*5 -> 0
A28: 29850491 | B28: Mauricio Méndez | D28: 1 | O28: =SUM('COMPURACION EMERGENTE'!$C28:$N28) -> 1 | P28: =O28/15 -> 0.066666667 | Q28: =P28*5 -> 0.33333333
A29: 30751145 | B29: Annabella Mendoza | O29: =SUM('COMPURACION EMERGENTE'!$C29:$N29) -> 0 | P29: =O29/15 -> 0 | Q29: =P29*5 -> 0
A30: 30612944 | B30: Andrés Alejandro Moreno Lombardo | O30: =SUM('COMPURACION EMERGENTE'!$C30:$N30) -> 0 | P30: =O30/15 -> 0 | Q30: =P30*5 -> 0
B31: Elvira Esther Navas Piñate | O31: =SUM('COMPURACION EMERGENTE'!$C31:$N31) -> 0 | P31: =O31/15 -> 0 | Q31: =P31*5 -> 0
A32: 29677861 | B32: Juan Diego Nunes Peraza | O32: =SUM('COMPURACION EMERGENTE'!$C32:$N32) -> 0 | P32: =O32/15 -> 0 | Q32: =P32*5 -> 0
A33: 29661990 | B33: Gabriel Rafael Oba Aye Orozco Rodriguez | O33: =SUM('COMPURACION EMERGENTE'!$C33:$N33) -> 0 | P33: =O33/15 -> 0 | Q33: =P33*5 -> 0
A34: 27472721 | B34: Adrián Eduardo Pinzón Vásquez | O34: =SUM('COMPURACION EMERGENTE'!$C34:$N34) -> 0 | P34: =O34/15 -> 0 | Q34: =P34*5 -> 0
A35: 29887224 | B35: Jonathan Pizzurro Fortun | O35: =SUM('COMPURACION EMERGENTE'!$C35:$N35) -> 0 | P35: =O35/15 -> 0 | Q35: =P35*5 -> 0
A36: 28317519 | B36: CRChristian Ramos | O36: =SUM('COMPURACION EMERGENTE'!$C36:$N36) -> 0 | P36: =O36/15 -> 0 | Q36: =P36*5 -> 0
A37: 30496487 | B37: GRGonzalo Andrés Ramos De Sa Pinto | C37: 1 | E37: 1 | O37: =SUM('COMPURACION EMERGENTE'!$C37:$N37) -> 2 | P37: =O37/15 -> 0.13333333 | Q37: =P37*5 -> 0.66666667
A38: 30411279 | B38: ARAndrea Veronica Reyes Mejia | C38: 1 | D38: 1 | E38: 1 | O38: =SUM('COMPURACION EMERGENTE'!$C38:$N38) -> 3 | P38: =O38/15 -> 0.2 | Q38: =P38*5 -> 1
A39: 26783022 | B39: IRIsabella Rondón | D39: 1 | O39: =SUM('COMPURACION EMERGENTE'!$C39:$N39) -> 1 | P39: =O39/15 -> 0.066666667 | Q39: =P39*5 -> 0.33333333
A40: 31460153 | B40: MRMaria Antonella Ruiz Cianci | O40: =SUM('COMPURACION EMERGENTE'!$C40:$N40) -> 0 | P40: =O40/15 -> 0 | Q40: =P40*5 -> 0
...
