Workbook

Sheet Acum
A1: CEDULA | B1: APELLIDO | C1: NOMBRE | D1: Correo Unimet | E1: Estatus | F1: Eval Cont | G1: Quiz 1 | H1: Parcial 1 | I1: Quiz 2 | J1: Proyecto | K1: Parcial 2 | L1: XTRA | M1: Total | N1: Escala 20 | O1: Partic | P1: Tareas | Q1: Def
A2: 30612256 | B2: Alcantarini | C2: Marco | D2: marco.alcantarini@correo.unimet.edu.ve. | F2: =VLOOKUP(LEFT(D2,LEN(D2)-1),'Eval. Cont.'!$A$2:$Q$31,17,FALSE) -> 16.405 | G2: ='Quiz 1'!G3/2 -> 10 | H2: =_xludf.ifna(VLOOKUP(VALUE(A2),'Parcial 1'!$A$2:$H$30,8,FALSE),"") -> #NAME? | I2: ='Quiz 2'!L3/2 -> 8.5 | J2: =_xludf.ifna(VLOOKUP(VALUE(A2),Proyecto!$A$3:$AA$24,27, FALSE),"") -> #NAME? | K2: =_xludf.ifna(VLOOKUP(VALUE(A2),'Parcial 2'!$A$2:$G$21,7,FALSE),"") -> #NAME? | L2: =_xludf.ifna(VLOOKUP(LEFT(D2,LEN(D2)-1),Xtra!$C$6:$N$53,12,FALSE),"") -> #NAME? | M2: =SUM(F2:L2) -> #NAME? | N2: =M2/5 -> #NAME? | O2: =Partic!T2/(COUNTA(Partic!D$1:T$1)-1) -> 0.125 | P2: =VLOOKUP(LEFT(D2,LEN(D2)-1),Tareas!$A$2:$Q$31,17,FALSE) -> 0.28571429 | Q2: =IF(E2="Retirado","R",N2+MAX(O2:P2)) -> #NAME?
A3: 31985209 | B3: Aponte | C3: Pedro | D3: pedro.aponte@correo.unimet.edu.ve. | F3: =VLOOKUP(LEFT(D3,LEN(D3)-1),'Eval. Cont.'!$A$2:$Q$31,17,FALSE) -> 17.430714 | G3: ='Quiz 1'!G4/2 -> 11.25 | H3: =_xludf.ifna(VLOOKUP(VALUE(A3),'Parcial 1'!$A$2:$H$30,8,FALSE),"") -> #NAME? | I3: ='Quiz 2'!L4/2 -> 2.5 | J3: =_xludf.ifna(VLOOKUP(VALUE(A3),Proyecto!$A$3:$AA$24,27, FALSE),"") -> #NAME? | K3: =_xludf.ifna(VLOOKUP(VALUE(A3),'Parcial 2'!$A$2:$G$21,7,FALSE),"") -> #NAME? | L3: =_xludf.ifna(VLOOKUP(LEFT(D3,LEN(D3)-1),Xtra!$C$6:$N$53,12,FALSE),"") -> #NAME? | M3: =SUM(F3:L3) -> #NAME? | N3: =M3/5 -> #NAME? | O3: =Partic!T3/(COUNTA(Partic!D$1:T$1)-1) -> 0 | P3: =VLOOKUP(LEFT(D3,LEN(D3)-1),Tareas!$A$2:$Q$31,17,FALSE) -> 0.85714286 | Q3: =IF(E3="Retirado","R",N3+MAX(O3:P3)) -> #NAME?
A4: 27670956 | B4: Araque | C4: Maria | D4: maria.araque@correo.unimet.edu.ve. | F4: =VLOOKUP(LEFT(D4,LEN(D4)-1),'Eval. Cont.'!$A$2:$Q$31,17,FALSE) -> 18.578571 | G4: ='Quiz 1'!G5/2 -> 0.5 | H4: =_xludf.ifna(VLOOKUP(VALUE(A4),'Parcial 1'!$A$2:$H$30,8,FALSE),"") -> #NAME? | I4: ='Quiz 2'!L5/2 -> 2.25 | J4: =_xludf.ifna(VLOOKUP(VALUE(A4),Proyecto!$A$3:$AA$24,27, FALSE),"") -> #NAME? | K4: =_xludf.ifna(VLOOKUP(VALUE(A4),'Parcial 2'!$A$2:$G$21,7,FALSE),"") -> #NAME? | L4: =_xludf.ifna(VLOOKUP(LEFT(D4,LEN(D4)-1),Xtra!$C$6:$N$53,12,FALSE),"") -> #NAME? | M4: =SUM(F4:L4) -> #NAME? | N4: =M4/5 -> #NAME? | O4: =Partic!T4/(COUNTA(Partic!D$1:T$1)-1) -> 1.0625 | P4: =VLOOKUP(LEFT(D4,LEN(D4)-1),Tareas!$A$2:$Q$31,17,FALSE) -> 0.92857143 | Q4: =IF(E4="Retirado","R",N4+MAX(O4:P4)) -> #NAME?
A5: 32241977 | B5: Bezara | C5: Cesar | D5: cbezara@correo.unimet.edu.ve. | F5: =VLOOKUP(LEFT(D5,LEN(D5)-1),'Eval. Cont.'!$A$2:$Q$31,17,FALSE) -> 17 | G5: ='Quiz 1'!G6/2 -> 11.5 | H5: =_xludf.ifna(VLOOKUP(VALUE(A5),'Parcial 1'!$A$2:$H$30,8,FALSE),"") -> #NAME? | I5: ='Quiz 2'!L6/2 -> 2.75 | J5: =_xludf.ifna(VLOOKUP(VALUE(A5),Proyecto!$A$3:$AA$24,27, FALSE),"") -> #NAME? | K5: =_xludf.ifna(VLOOKUP(VALUE(A5),'Parcial 2'!$A$2:$G$21,7,FALSE),"") -> #NAME? | L5: =_xludf.ifna(VLOOKUP(LEFT(D5,LEN(D5)-1),Xtra!$C$6:$N$53,12,FALSE),"") -> #NAME? | M5: =SUM(F5:L5) -> #NAME? | N5: =M5/5 -> #NAME? | O5: =Partic!T5/(COUNTA(Partic!D$1:T$1)-1) -> 0.125 | P5: =VLOOKUP(LEFT(D5,LEN(D5)-1),Tareas!$A$2:$Q$31,17,FALSE) -> 0.92857143 | Q5: =IF(E5="Retirado","R",N5+MAX(O5:P5)) -> #NAME?
A6: 30888238 | B6: Briceño | C6: Ignacio | D6: ignacio.briceno@correo.unimet.edu.ve. | E6: Retirado | F6: =VLOOKUP(LEFT(D6,LEN(D6)-1),'Eval. Cont.'!$A$2:$Q$31,17,FALSE) -> 11.928571 | G6: ='Quiz 1'!G7/2 -> 4.25 | H6: =_xludf.ifna(VLOOKUP(VALUE(A6),'Parcial 1'!$A$2:$H$30,8,FALSE),"") -> #NAME? | J6: =_xludf.ifna(VLOOKUP(VALUE(A6),Proyecto!$A$3:$AA$24,27, FALSE),"") -> #NAME? | K6: =_xludf.ifna(VLOOKUP(VALUE(A6),'Parcial 2'!$A$2:$G$21,7,FALSE),"") -> #NAME? | L6: =_xludf.ifna(VLOOKUP(LEFT(D6,LEN(D6)-1),Xtra!$C$6:$N$53,12,FALSE),"") -> #NAME? | M6: =SUM(F6:L6) -> #NAME? | N6: =M6/5 -> #NAME? | O6: =Partic!T6/(COUNTA(Partic!D$1:T$1)-1) -> 0.625 | P6: =VLOOKUP(LEFT(D6,LEN(D6)-1),Tareas!$A$2:$Q$31,17,FALSE) -> 0.35714286 | Q6: =IF(E6="Retirado","R",N6+MAX(O6:P6)) -> R
A7: 30539028 | B7: El Chaer | C7: José | D7: jelchaer@correo.unimet.edu.ve. | E7: Retirado | F7: =VLOOKUP(LEFT(D7,LEN(D7)-1),'Eval. Cont.'!$A$2:$Q$31,17,FALSE) -> 5.8807143 | G7: ='Quiz 1'!G8/2 -> 0 | H7: =_xludf.ifna(VLOOKUP(VALUE(A7),'Parcial 1'!$A$2:$H$30,8,FALSE),"") -> #NAME? | J7: =_xludf.ifna(VLOOKUP(VALUE(A7),Proyecto!$A$3:$AA$24,27, FALSE),"") -> #NAME? | K7: =_xludf.ifna(VLOOKUP(VALUE(A7),'Parcial 2'!$A$2:$G$21,7,FALSE),"") -> #NAME? | L7: =_xludf.ifna(VLOOKUP(LEFT(D7,LEN(D7)-1),Xtra!$C$6:$N$53,12,FALSE),"") -> #NAME? | M7: =SUM(F7:L7) -> #NAME? | N7: =M7/5 -> #NAME? | O7: =Partic!T7/(COUNTA(Partic!D$1:T$1)-1) -> 0 | P7: =VLOOKUP(LEFT(D7,LEN(D7)-1),Tareas!$A$2:$Q$31,17,FALSE) -> 0.35714286 | Q7: =IF(E7="Retirado","R",N7+MAX(O7:P7)) -> R
A8: 31423864 | B8: García | C8: Rocco | D8: rocco.garcia@correo.unimet.edu.ve. | F8: =VLOOKUP(LEFT(D8,LEN(D8)-1),'Eval. Cont.'!$A$2:$Q$31,17,FALSE) -> 13.078571 | G8: ='Quiz 1'!G9/2 -> 1.75 | H8: =_xludf.ifna(VLOOKUP(VALUE(A8),'Parcial 1'!$A$2:$H$30,8,FALSE),"") -> #NAME? | I8: ='Quiz 2'!L9/2 -> 1 | J8: =_xludf.ifna(VLOOKUP(VALUE(A8),Proyecto!$A$3:$AA$24,27, FALSE),"") -> #NAME? | K8: =_xludf.ifna(VLOOKUP(VALUE(A8),'Parcial 2'!$A$2:$G$21,7,FALSE),"") -> #NAME? | L8: =_xludf.ifna(VLOOKUP(LEFT(D8,LEN(D8)-1),Xtra!$C$6:$N$53,12,FALSE),"") -> #NAME? | M8: =SUM(F8:L8) -> #NAME? | N8: =M8/5 -> #NAME? | O8: =Partic!T8/(COUNTA(Partic!D$1:T$1)-1) -> 0 | P8: =VLOOKUP(LEFT(D8,LEN(D8)-1),Tareas!$A$2:$Q$31,17,FALSE) -> 0.21428571 | Q8: =IF(E8="Retirado","R",N8+MAX(O8:P8)) -> #NAME?
A9: 31979046 | B9: Gonzalez | C9: Salomon | D9: salo-gonzalez@correo.unimet.edu.ve. | F9: =VLOOKUP(LEFT(D9,LEN(D9)-1),'Eval. Cont.'!$A$2:$Q$31,17,FALSE) -> 18.285714 | G9: ='Quiz 1'!G10/2 -> 9.5 | H9: =_xludf.ifna(VLOOKUP(VALUE(A9),'Parcial 1'!$A$2:$H$30,8,FALSE),"") -> #NAME? | I9: ='Quiz 2'!L10/2 -> 6.5 | J9: =_xludf.ifna(VLOOKUP(VALUE(A9),Proyecto!$A$3:$AA$24,27, FALSE),"") -> #NAME? | K9: =_xludf.ifna(VLOOKUP(VALUE(A9),'Parcial 2'!$A$2:$G$21,7,FALSE),"") -> #NAME? | L9: =_xludf.ifna(VLOOKUP(LEFT(D9,LEN(D9)-1),Xtra!$C$6:$N$53,12,FALSE),"") -> #NAME? | M9: =SUM(F9:L9) -> #NAME? | N9: =M9/5 -> #NAME? | O9: =Partic!T9/(COUNTA(Partic!D$1:T$1)-1) -> 0.5625 | P9: =VLOOKUP(LEFT(D9,LEN(D9)-1),Tareas!$A$2:$Q$31,17,FALSE) -> 0.85714286 | Q9: =IF(E9="Retirado","R",N9+MAX(O9:P9)) -> #NAME?
A10: 32042714 | B10: González | C10: Manuel | D10: go.manuel@correo.unimet.edu.ve. | F10: =VLOOKUP(LEFT(D10,LEN(D10)-1),'Eval. Cont.'!$A$2:$Q$31,17,FALSE) -> 16.607143 | G10: ='Quiz 1'!G11/2 -> 2.25 | H10: =_xludf.ifna(VLOOKUP(VALUE(A10),'Parcial 1'!$A$2:$H$30,8,FALSE),"") -> #NAME? | I10: ='Quiz 2'!L11/2 -> 4.375 | J10: =_xludf.ifna(VLOOKUP(VALUE(A10),Proyecto!$A$3:$AA$24,27, FALSE),"") -> #NAME? | K10: =_xludf.ifna(VLOOKUP(VALUE(A10),'Parcial 2'!$A$2:$G$21,7,FALSE),"") -> #NAME? | L10: =_xludf.ifna(VLOOKUP(LEFT(D10,LEN(D10)-1),Xtra!$C$6:$N$53,12,FALSE),"") -> #NAME? | M10: =SUM(F10:L10) -> #NAME? | N10: =M10/5 -> #NAME? | O10: =Partic!T10/(COUNTA(Partic!D$1:T$1)-1) -> 1 | P10: =VLOOKUP(LEFT(D10,LEN(D10)-1),Tareas!$A$2:$Q$31,17,FALSE) -> 0.57142857 | Q10: =IF(E10="Retirado","R",N10+MAX(O10:P10)) -> #NAME?
A11: 31696701 | B11: Guillén | C11: Sebastián | D11: s.guillen@correo.unimet.edu.ve. | F11: =VLOOKUP(LEFT(D11,LEN(D11)-1),'Eval. Cont.'!$A$2:$Q$31,17,FALSE) -> 14.167143 | G11: ='Quiz 1'!G12/2 -> 1 | H11: =_xludf.ifna(VLOOKUP(VALUE(A11),'Parcial 1'!$A$2:$H$30,8,FALSE),"") -> #NAME? | J11: =_xludf.ifna(VLOOKUP(VALUE(A11),Proyecto!$A$3:$AA$24,27, FALSE),"") -> #NAME? | K11: =_xludf.ifna(VLOOKUP(VALUE(A11),'Parcial 2'!$A$2:$G$21,7,FALSE),"") -> #NAME? | L11: =_xludf.ifna(VLOOKUP(LEFT(D11,LEN(D11)-1),Xtra!$C$6:$N$53,12,FALSE),"") -> #NAME? | M11: =SUM(F11:L11) -> #NAME? | N11: =M11/5 -> #NAME? | O11: =Partic!T11/(COUNTA(Partic!D$1:T$1)-1) -> 1.375 | P11: =VLOOKUP(LEFT(D11,LEN(D11)-1),Tareas!$A$2:$Q$31,17,FALSE) -> 0.35714286 | Q11: =IF(E11="Retirado","R",N11+MAX(O11:P11)) -> #NAME?
A12: 31935772 | B12: Guzzo | C12: Antonio | D12: antonio.guzzo@correo.unimet.edu.ve. | F12: =VLOOKUP(LEFT(D12,LEN(D12)-1),'Eval. Cont.'!$A$2:$Q$31,17,FALSE) -> 12.202143 | G12: ='Quiz 1'!G13/2 -> 7.5 | H12: =_xludf.ifna(VLOOKUP(VALUE(A12),'Parcial 1'!$A$2:$H$30,8,FALSE),"") -> #NAME? | I12: ='Quiz 2'!L13/2 -> 2.875 | J12: =_xludf.ifna(VLOOKUP(VALUE(A12),Proyecto!$A$3:$AA$24,27, FALSE),"") -> #NAME? | K12: =_xludf.ifna(VLOOKUP(VALUE(A12),'Parcial 2'!$A$2:$G$21,7,FALSE),"") -> #NAME? | L12: =_xludf.ifna(VLOOKUP(LEFT(D12,LEN(D12)-1),Xtra!$C$6:$N$53,12,FALSE),"") -> #NAME? | M12: =SUM(F12:L12) -> #NAME? | N12: =M12/5 -> #NAME? | O12: =Partic!T12/(COUNTA(Partic!D$1:T$1)-1) -> 0.375 | P12: =VLOOKUP(LEFT(D12,LEN(D12)-1),Tareas!$A$2:$Q$31,17,FALSE) -> 0.071428571 | Q12: =IF(E12="Retirado","R",N12+MAX(O12:P12)) -> #NAME?
A13: 31886469 | B13: Hernández | C13: Victoria | D13: h.victoria@correo.unimet.edu.ve. | F13: =VLOOKUP(LEFT(D13,LEN(D13)-1),'Eval. Cont.'!$A$2:$Q$31,17,FALSE) -> 12.762143 | G13: ='Quiz 1'!G14/2 -> 0 | H13: =_xludf.ifna(VLOOKUP(VALUE(A13),'Parcial 1'!$A$2:$H$30,8,FALSE),"") -> #NAME? | I13: ='Quiz 2'!L14/2 -> 1 | J13: =_xludf.ifna(VLOOKUP(VALUE(A13),Proyecto!$A$3:$AA$24,27, FALSE),"") -> #NAME? | K13: =_xludf.ifna(VLOOKUP(VALUE(A13),'Parcial 2'!$A$2:$G$21,7,FALSE),"") -> #NAME? | L13: =_xludf.ifna(VLOOKUP(LEFT(D13,LEN(D13)-1),Xtra!$C$6:$N$53,12,FALSE),"") -> #NAME? | M13: =SUM(F13:L13) -> #NAME? | N13: =M13/5 -> #NAME? | O13: =Partic!T13/(COUNTA(Partic!D$1:T$1)-1) -> 0 | P13: =VLOOKUP(LEFT(D13,LEN(D13)-1),Tareas!$A$2:$Q$31,17,FALSE) -> 0.21428571 | Q13: =IF(E13="Retirado","R",N13+MAX(O13:P13)) -> #NAME?
A14: 32121959 | B14: Jaspe | C14: Gabriel | D14: g.jaspe@correo.unimet.edu.ve. | F14: =VLOOKUP(LEFT(D14,LEN(D14)-1),'Eval. Cont.'!$A$2:$Q$31,17,FALSE) -> 16.178571 | G14: ='Quiz 1'!G15/2 -> 7.75 | H14: =_xludf.ifna(VLOOKUP(VALUE(A14),'Parcial 1'!$A$2:$H$30,8,FALSE),"") -> #NAME? | I14: ='Quiz 2'!L15/2 -> 2.625 | J14: =_xludf.ifna(VLOOKUP(VALUE(A14),Proyecto!$A$3:$AA$24,27, FALSE),"") -> #NAME? | K14: =_xludf.ifna(VLOOKUP(VALUE(A14),'Parcial 2'!$A$2:$G$21,7,FALSE),"") -> #NAME? | L14: =_xludf.ifna(VLOOKUP(LEFT(D14,LEN(D14)-1),Xtra!$C$6:$N$53,12,FALSE),"") -> #NAME? | M14: =SUM(F14:L14) -> #NAME? | N14: =M14/5 -> #NAME? | O14: =Partic!T14/(COUNTA(Partic!D$1:T$1)-1) -> 0 | P14: =VLOOKUP(LEFT(D14,LEN(D14)-1),Tareas!$A$2:$Q$31,17,FALSE) -> 0.85714286 | Q14: =IF(E14="Retirado","R",N14+MAX(O14:P14)) -> #NAME?
A15: 32235827 | B15: Lahrssen | C15: Thomas | D15: thomas.lahrssen@correo.unimet.edu.ve. | F15: =VLOOKUP(LEFT(D15,LEN(D15)-1),'Eval. Cont.'!$A$2:$Q$31,17,FALSE) -> 18.328571 | G15: ='Quiz 1'!G16/2 -> 5.75 | H15: =_xludf.ifna(VLOOKUP(VALUE(A15),'Parcial 1'!$A$2:$H$30,8,FALSE),"") -> #NAME? | I15: ='Quiz 2'!L16/2 -> 4 | J15: =_xludf.ifna(VLOOKUP(VALUE(A15),Proyecto!$A$3:$AA$24,27, FALSE),"") -> #NAME? | K15: =_xludf.ifna(VLOOKUP(VALUE(A15),'Parcial 2'!$A$2:$G$21,7,FALSE),"") -> #NAME? | L15: =_xludf.ifna(VLOOKUP(LEFT(D15,LEN(D15)-1),Xtra!$C$6:$N$53,12,FALSE),"") -> #NAME? | M15: =SUM(F15:L15) -> #NAME? | N15: =M15/5 -> #NAME? | O15: =Partic!T15/(COUNTA(Partic!D$1:T$1)-1) -> 1.4375 | P15: =VLOOKUP(LEFT(D15,LEN(D15)-1),Tareas!$A$2:$Q$31,17,FALSE) -> 0.35714286 | Q15: =IF(E15="Retirado","R",N15+MAX(O15:P15)) -> #NAME?
A16: 31873119 | B16: Mosquera | C16: Isabella | D16: isabella.mosquera@correo.unimet.edu.ve. | F16: =VLOOKUP(LEFT(D16,LEN(D16)-1),'Eval. Cont.'!$A$2:$Q$31,17,FALSE) -> 18.464286 | G16: ='Quiz 1'!G17/2 -> 5.25 | H16: =_xludf.ifna(VLOOKUP(VALUE(A16),'Parcial 1'!$A$2:$H$30,8,FALSE),"") -> #NAME? | I16: ='Quiz 2'!L17/2 -> 3.125 | J16: =_xludf.ifna(VLOOKUP(VALUE(A16),Proyecto!$A$3:$AA$24,27, FALSE),"") -> #NAME? | K16: =_xludf.ifna(VLOOKUP(VALUE(A16),'Parcial 2'!$A$2:$G$21,7,FALSE),"") -> #NAME? | L16: =_xludf.ifna(VLOOKUP(LEFT(D16,LEN(D16)-1),Xtra!$C$6:$N$53,12,FALSE),"") -> #NAME? | M16: =SUM(F16:L16) -> #NAME? | N16: =M16/5 -> #NAME? | O16: =Partic!T16/(COUNTA(Partic!D$1:T$1)-1) -> 1.5 | P16: =VLOOKUP(LEFT(D16,LEN(D16)-1),Tareas!$A$2:$Q$31,17,FALSE) -> 0.92857143 | Q16: =IF(E16="Retirado","R",N16+MAX(O16:P16)) -> #NAME?
A17: 27007813 | B17: Ortega | C17: Carlos | D17: carlos.ortega@correo.unimet.edu.ve. | E17: Retirado | F17: =VLOOKUP(LEFT(D17,LEN(D17)-1),'Eval. Cont.'!$A$2:$Q$31,17,FALSE) -> 0 | H17: =_xludf.ifna(VLOOKUP(VALUE(A17),'Parcial 1'!$A$2:$H$30,8,FALSE),"") -> #NAME? | I17: ='Quiz 2'!L18/2 -> 2.75 | J17: =_xludf.ifna(VLOOKUP(VALUE(A17),Proyecto!$A$3:$AA$24,27, FALSE),"") -> #NAME? | K17: =_xludf.ifna(VLOOKUP(VALUE(A17),'Parcial 2'!$A$2:$G$21,7,FALSE),"") -> #NAME? | L17: =_xludf.ifna(VLOOKUP(LEFT(D17,LEN(D17)-1),Xtra!$C$6:$N$53,12,FALSE),"") -> #NAME? | M17: =SUM(F17:L17) -> #NAME? | N17: =M17/5 -> #NAME? | O17: =Partic!T17/(COUNTA(Partic!D$1:T$1)-1) -> 0.0625 | P17: =VLOOKUP(LEFT(D17,LEN(D17)-1),Tareas!$A$2:$Q$31,17,FALSE) -> 0 | Q17: =IF(E17="Retirado","R",N17+MAX(O17:P17)) -> R
A18: 31460623 | B18: Ostos | C18: Samuel | D18: samuel.ostos@correo.unimet.edu.ve. | F18: =VLOOKUP(LEFT(D18,LEN(D18)-1),'Eval. Cont.'!$A$2:$Q$31,17,FALSE) -> 14.178571 | G18: ='Quiz 1'!G19/2 -> 3.5 | H18: =_xludf.ifna(VLOOKUP(VALUE(A18),'Parcial 1'!$A$2:$H$30,8,FALSE),"") -> #NAME? | J18: =_xludf.ifna(VLOOKUP(VALUE(A18),Proyecto!$A$3:$AA$24,27, FALSE),"") -> #NAME? | K18: =_xludf.ifna(VLOOKUP(VALUE(A18),'Parcial 2'!$A$2:$G$21,7,FALSE),"") -> #NAME? | L18: =_xludf.ifna(VLOOKUP(LEFT(D18,LEN(D18)-1),Xtra!$C$6:$N$53,12,FALSE),"") -> #NAME? | M18: =SUM(F18:L18) -> #NAME? | N18: =M18/5 -> #NAME? | O18: =Partic!T18/(COUNTA(Partic!D$1:T$1)-1) -> 0.0625 | P18: =VLOOKUP(LEFT(D18,LEN(D18)-1),Tareas!$A$2:$Q$31,17,FALSE) -> 0 | Q18: =IF(E18="Retirado","R",N18+MAX(O18:P18)) -> #NAME?
A19: 33186550 | B19: Pacheco | C19: Daniela | D19: danipacheco@correo.unimet.edu.ve. | F19: =VLOOKUP(LEFT(D19,LEN(D19)-1),'Eval. Cont.'!$A$2:$Q$31,17,FALSE) -> 17.559286 | G19: ='Quiz 1'!G20/2 -> 4 | H19: =_xludf.ifna(VLOOKUP(VALUE(A19),'Parcial 1'!$A$2:$H$30,8,FALSE),"") -> #NAME? | I19: ='Quiz 2'!L19/2 -> 3.75 | J19: =_xludf.ifna(VLOOKUP(VALUE(A19),Proyecto!$A$3:$AA$24,27, FALSE),"") -> #NAME? | K19: =_xludf.ifna(VLOOKUP(VALUE(A19),'Parcial 2'!$A$2:$G$21,7,FALSE),"") -> #NAME? | L19: =_xludf.ifna(VLOOKUP(LEFT(D19,LEN(D19)-1),Xtra!$C$6:$N$53,12,FALSE),"") -> #NAME? | M19: =SUM(F19:L19) -> #NAME? | N19: =M19/5 -> #NAME? | O19: =Partic!T19/(COUNTA(Partic!D$1:T$1)-1) -> 1.0625 | P19: =VLOOKUP(LEFT(D19,LEN(D19)-1),Tareas!$A$2:$Q$31,17,FALSE) -> 1 | Q19: =IF(E19="Retirado","R",N19+MAX(O19:P19)) -> #NAME?
A20: 33219652 | B20: Pedroza | C20: Gustavo | D20: gustavo.pedroza@correo.unimet.edu.ve. | E20: Retirado | F20: =VLOOKUP(LEFT(D20,LEN(D20)-1),'Eval. Cont.'!$A$2:$Q$31,17,FALSE) -> 7.5 | G20: ='Quiz 1'!G21/2 -> 10.75 | H20: =_xludf.ifna(VLOOKUP(VALUE(A20),'Parcial 1'!$A$2:$H$30,8,FALSE),"") -> #NAME? | J20: =_xludf.ifna(VLOOKUP(VALUE(A20),Proyecto!$A$3:$AA$24,27, FALSE),"") -> #NAME? | K20: =_xludf.ifna(VLOOKUP(VALUE(A20),'Parcial 2'!$A$2:$G$21,7,FALSE),"") -> #NAME? | L20: =_xludf.ifna(VLOOKUP(LEFT(D20,LEN(D20)-1),Xtra!$C$6:$N$53,12,FALSE),"") -> #NAME? | M20: =SUM(F20:L20) -> #NAME? | N20: =M20/5 -> #NAME? | O20: =Partic!T20/(COUNTA(Partic!D$1:T$1)-1) -> 0 | P20: =VLOOKUP(LEFT(D20,LEN(D20)-1),Tareas!$A$2:$Q$31,17,FALSE) -> 0.21428571 | Q20: =IF(E20="Retirado","R",N20+MAX(O20:P20)) -> R
A21: 31935917 | B21: Poleo | C21: Raul | D21: raul.poleo@correo.unimet.edu.ve. | E21: Retirado | F21: =VLOOKUP(LEFT(D21,LEN(D21)-1),'Eval. Cont.'!$A$2:$Q$31,17,FALSE) -> 4.2614286 | G21: ='Quiz 1'!G22/2 -> 0 | H21: =_xludf.ifna(VLOOKUP(VALUE(A21),'Parcial 1'!$A$2:$H$30,8,FALSE),"") -> #NAME? | J21: =_xludf.ifna(VLOOKUP(VALUE(A21),Proyecto!$A$3:$AA$24,27, FALSE),"") -> #NAME? | K21: =_xludf.ifna(VLOOKUP(VALUE(A21),'Parcial 2'!$A$2:$G$21,7,FALSE),"") -> #NAME? | L21: =_xludf.ifna(VLOOKUP(LEFT(D21,LEN(D21)-1),Xtra!$C$6:$N$53,12,FALSE),"") -> #NAME? | M21: =SUM(F21:L21) -> #NAME? | N21: =M21/5 -> #NAME? | O21: =Partic!T21/(COUNTA(Partic!D$1:T$1)-1) -> 0.25 | P21: =VLOOKUP(LEFT(D21,LEN(D21)-1),Tareas!$A$2:$Q$31,17,FALSE) -> 0.28571429 | Q21: =IF(E21="Retirado","R",N21+MAX(O21:P21)) -> R
A22: 31745168 | B22: Prieto | C22: Andrés | D22: andres.prieto@correo.unimet.edu.ve. | F22: =VLOOKUP(LEFT(D22,LEN(D22)-1),'Eval. Cont.'!$A$2:$Q$31,17,FALSE) -> 14.928571 | G22: ='Quiz 1'!G23/2 -> 7.5 | H22: =_xludf.ifna(VLOOKUP(VALUE(A22),'Parcial 1'!$A$2:$H$30,8,FALSE),"") -> #NAME? | I22: ='Quiz 2'!L23/2 -> 9.25 | J22: =_xludf.ifna(VLOOKUP(VALUE(A22),Proyecto!$A$3:$AA$24,27, FALSE),"") -> #NAME? | K22: =_xludf.ifna(VLOOKUP(VALUE(A22),'Parcial 2'!$A$2:$G$21,7,FALSE),"") -> #NAME? | L22: =_xludf.ifna(VLOOKUP(LEFT(D22,LEN(D22)-1),Xtra!$C$6:$N$53,12,FALSE),"") -> #NAME? | M22: =SUM(F22:L22) -> #NAME? | N22: =M22/5 -> #NAME? | O22: =Partic!T22/(COUNTA(Partic!D$1:T$1)-1) -> 0.125 | P22: =VLOOKUP(LEFT(D22,LEN(D22)-1),Tareas!$A$2:$Q$31,17,FALSE) -> 0.28571429 | Q22: =IF(E22="Retirado","R",N22+MAX(O22:P22)) -> #NAME?
A23: 32511604 | B23: Pérez | C23: Henmary | D23: henmary.perez@correo.unimet.edu.ve. | F23: =VLOOKUP(LEFT(D23,LEN(D23)-1),'Eval. Cont.'!$A$2:$Q$31,17,FALSE) -> 18.464286 | G23: ='Quiz 1'!G24/2 -> 10.75 | H23: =_xludf.ifna(VLOOKUP(VALUE(A23),'Parcial 1'!$A$2:$H$30,8,FALSE),"") -> #NAME? | I23: ='Quiz 2'!L21/2 -> 9 | J23: =_xludf.ifna(VLOOKUP(VALUE(A23),Proyecto!$A$3:$AA$24,27, FALSE),"") -> #NAME? | K23: =_xludf.ifna(VLOOKUP(VALUE(A23),'Parcial 2'!$A$2:$G$21,7,FALSE),"") -> #NAME? | L23: =_xludf.ifna(VLOOKUP(LEFT(D23,LEN(D23)-1),Xtra!$C$6:$N$53,12,FALSE),"") -> #NAME? | M23: =SUM(F23:L23) -> #NAME? | N23: =M23/5 -> #NAME? | O23: =Partic!T23/(COUNTA(Partic!D$1:T$1)-1) -> 1.5 | P23: =VLOOKUP(LEFT(D23,LEN(D23)-1),Tareas!$A$2:$Q$31,17,FALSE) -> 1 | Q23: =IF(E23="Retirado","R",N23+MAX(O23:P23)) -> #NAME?
A24: 31701229 | B24: Quintero | C24: Santiago | D24: quintero.santiago@correo.unimet.edu.ve. | F24: =VLOOKUP(LEFT(D24,LEN(D24)-1),'Eval. Cont.'!$A$2:$Q$31,17,FALSE) -> 17 | G24: ='Quiz 1'!G25/2 -> 9 | H24: =_xludf.ifna(VLOOKUP(VALUE(A24),'Parcial 1'!$A$2:$H$30,8,FALSE),"") -> #NAME? | I24: ='Quiz 2'!L24/2 -> 8.25 | J24: =_xludf.ifna(VLOOKUP(VALUE(A24),Proyecto!$A$3:$AA$24,27, FALSE),"") -> #NAME? | K24: =_xludf.ifna(VLOOKUP(VALUE(A24),'Parcial 2'!$A$2:$G$21,7,FALSE),"") -> #NAME? | L24: =_xludf.ifna(VLOOKUP(LEFT(D24,LEN(D24)-1),Xtra!$C$6:$N$53,12,FALSE),"") -> #NAME? | M24: =SUM(F24:L24) -> #NAME? | N24: =M24/5 -> #NAME? | O24: =Partic!T24/(COUNTA(Partic!D$1:T$1)-1) -> 1.1875 | P24: =VLOOKUP(LEFT(D24,LEN(D24)-1),Tareas!$A$2:$Q$31,17,FALSE) -> 0.35714286 | Q24: =IF(E24="Retirado","R",N24+MAX(O24:P24)) -> #NAME?
A25: 30538673 | B25: Rienzo | C25: Fabiana | D25: frienzo@correo.unimet.edu.ve. | F25: =VLOOKUP(LEFT(D25,LEN(D25)-1),'Eval. Cont.'!$A$2:$Q$31,17,FALSE) -> 18.070714 | G25: ='Quiz 1'!G26/2 -> 0.75 | H25: =_xludf.ifna(VLOOKUP(VALUE(A25),'Parcial 1'!$A$2:$H$30,8,FALSE),"") -> #NAME? | I25: ='Quiz 2'!L25/2 -> 2.75 | J25: =_xludf.ifna(VLOOKUP(VALUE(A25),Proyecto!$A$3:$AA$24,27, FALSE),"") -> #NAME? | K25: =_xludf.ifna(VLOOKUP(VALUE(A25),'Parcial 2'!$A$2:$G$21,7,FALSE),"") -> #NAME? | L25: =_xludf.ifna(VLOOKUP(LEFT(D25,LEN(D25)-1),Xtra!$C$6:$N$53,12,FALSE),"") -> #NAME? | M25: =SUM(F25:L25) -> #NAME? | N25: =M25/5 -> #NAME? | O25: =Partic!T25/(COUNTA(Partic!D$1:T$1)-1) -> 0.4375 | P25: =VLOOKUP(LEFT(D25,LEN(D25)-1),Tareas!$A$2:$Q$31,17,FALSE) -> 0.28571429 | Q25: 12
A26: 32001850 | B26: Rodrigues | C26: Sergio | D26: rodrigues.sergio@correo.unimet.edu.ve. | E26: Retirado | F26: =VLOOKUP(LEFT(D26,LEN(D26)-1),'Eval. Cont.'!$A$2:$Q$31,17,FALSE) -> 14.728571 | G26: ='Quiz 1'!G27/2 -> 2.75 | H26: =_xludf.ifna(VLOOKUP(VALUE(A26),'Parcial 1'!$A$2:$H$30,8,FALSE),"") -> #NAME? | J26: =_xludf.ifna(VLOOKUP(VALUE(A26),Proyecto!$A$3:$AA$24,27, FALSE),"") -> #NAME? | K26: =_xludf.ifna(VLOOKUP(VALUE(A26),'Parcial 2'!$A$2:$G$21,7,FALSE),"") -> #NAME? | L26: =_xludf.ifna(VLOOKUP(LEFT(D26,LEN(D26)-1),Xtra!$C$6:$N$53,12,FALSE),"") -> #NAME? | M26: =SUM(F26:L26) -> #NAME? | N26: =M26/5 -> #NAME? | O26: =Partic!T26/(COUNTA(Partic!D$1:T$1)-1) -> 0.3125 | P26: =VLOOKUP(LEFT(D26,LEN(D26)-1),Tareas!$A$2:$Q$31,17,FALSE) -> 0.21428571 | Q26: =IF(E26="Retirado","R",N26+MAX(O26:P26)) -> R
A27: 31873242 | B27: Tamma | C27: Anna | D27: a.tamma@correo.unimet.edu.ve. | F27: =VLOOKUP(LEFT(D27,LEN(D27)-1),'Eval. Cont.'!$A$2:$Q$31,17,FALSE) -> 12.678571 | G27: ='Quiz 1'!G28/2 -> 0 | H27: =_xludf.ifna(VLOOKUP(VALUE(A27),'Parcial 1'!$A$2:$H$30,8,FALSE),"") -> #NAME? | I27: ='Quiz 2'!L27/2 -> 1 | J27: =_xludf.ifna(VLOOKUP(VALUE(A27),Proyecto!$A$3:$AA$24,27, FALSE),"") -> #NAME? | K27: =_xludf.ifna(VLOOKUP(VALUE(A27),'Parcial 2'!$A$2:$G$21,7,FALSE),"") -> #NAME? | L27: =_xludf.ifna(VLOOKUP(LEFT(D27,LEN(D27)-1),Xtra!$C$6:$N$53,12,FALSE),"") -> #NAME? | M27: =SUM(F27:L27) -> #NAME? | N27: =M27/5 -> #NAME? | O27: =Partic!T27/(COUNTA(Partic!D$1:T$1)-1) -> 0 | P27: =VLOOKUP(LEFT(D27,LEN(D27)-1),Tareas!$A$2:$Q$31,17,FALSE) -> 0.14285714 | Q27: =IF(E27="Retirado","R",N27+MAX(O27:P27)) -> #NAME?
A28: 30849483 | B28: Valdez | C28: Paola | D28: pvaldez@correo.unimet.edu.ve. | F28: =VLOOKUP(LEFT(D28,LEN(D28)-1),'Eval. Cont.'!$A$2:$Q$31,17,FALSE) -> 18.042857 | G28: ='Quiz 1'!G29/2 -> 3.5 | H28: =_xludf.ifna(VLOOKUP(VALUE(A28),'Parcial 1'!$A$2:$H$30,8,FALSE),"") -> #NAME? | I28: ='Quiz 2'!L28/2 -> 2.625 | J28: =_xludf.ifna(VLOOKUP(VALUE(A28),Proyecto!$A$3:$AA$24,27, FALSE),"") -> #NAME? | K28: =_xludf.ifna(VLOOKUP(VALUE(A28),'Parcial 2'!$A$2:$G$21,7,FALSE),"") -> #NAME? | L28: =_xludf.ifna(VLOOKUP(LEFT(D28,LEN(D28)-1),Xtra!$C$6:$N$53,12,FALSE),"") -> #NAME? | M28: =SUM(F28:L28) -> #NAME? | N28: =M28/5 -> #NAME? | O28: =Partic!T28/(COUNTA(Partic!D$1:T$1)-1) -> 0.625 | P28: =VLOOKUP(LEFT(D28,LEN(D28)-1),Tareas!$A$2:$Q$31,17,FALSE) -> 0.28571429 | Q28: =IF(E28="Retirado","R",N28+MAX(O28:P28)) -> #NAME?
A29: 31382931 | B29: Velásquez | C29: Luis | D29: velasquez.luis@correo.unimet.edu.ve. | F29: =VLOOKUP(LEFT(D29,LEN(D29)-1),'Eval. Cont.'!$A$2:$Q$31,17,FALSE) -> 18.928571 | G29: ='Quiz 1'!G30/2 -> 0.5 | H29: =_xludf.ifna(VLOOKUP(VALUE(A29),'Parcial 1'!$A$2:$H$30,8,FALSE),"") -> #NAME? | I29: ='Quiz 2'!L29/2 -> 8.375 | J29: =_xludf.ifna(VLOOKUP(VALUE(A29),Proyecto!$A$3:$AA$24,27, FALSE),"") -> #NAME? | K29: =_xludf.ifna(VLOOKUP(VALUE(A29),'Parcial 2'!$A$2:$G$21,7,FALSE),"") -> #NAME? | L29: =_xludf.ifna(VLOOKUP(LEFT(D29,LEN(D29)-1),Xtra!$C$6:$N$53,12,FALSE),"") -> #NAME? | M29: =SUM(F29:L29) -> #NAME? | N29: =M29/5 -> #NAME? | O29: =Partic!T29/(COUNTA(Partic!D$1:T$1)-1) -> 1.125 | P29: =VLOOKUP(LEFT(D29,LEN(D29)-1),Tareas!$A$2:$Q$31,17,FALSE) -> 0.28571429 | Q29: =IF(E29="Retirado","R",N29+MAX(O29:P29)) -> #NAME?
A30: 32336250 | B30: Villarroel | C30: Abdallah | D30: abdallah.villarroel@correo.unimet.edu.ve. | F30: =VLOOKUP(LEFT(D30,LEN(D30)-1),'Eval. Cont.'!$A$2:$Q$31,17,FALSE) -> 5.9642857 | H30: =_xludf.ifna(VLOOKUP(VALUE(A30),'Parcial 1'!$A$2:$H$30,8,FALSE),"") -> #NAME? | J30: =_xludf.ifna(VLOOKUP(VALUE(A30),Proyecto!$A$3:$AA$24,27, FALSE),"") -> #NAME? | K30: =_xludf.ifna(VLOOKUP(VALUE(A30),'Parcial 2'!$A$2:$G$21,7,FALSE),"") -> #NAME? | L30: =_xludf.ifna(VLOOKUP(LEFT(D30,LEN(D30)-1),Xtra!$C$6:$N$53,12,FALSE),"") -> #NAME? | M30: =SUM(F30:L30) -> #NAME? | N30: =M30/5 -> #NAME? | O30: =Partic!T30/(COUNTA(Partic!D$1:T$1)-1) -> 0 | P30: =VLOOKUP(LEFT(D30,LEN(D30)-1),Tareas!$A$2:$Q$31,17,FALSE) -> 0 | Q30: =IF(E30="Retirado","R",N30+MAX(O30:P30)) -> #NAME?
A31: 32001498 | B31: Zambrano | C31: Santiago | D31: s.zambrano@correo.unimet.edu.ve. | F31: =VLOOKUP(LEFT(D31,LEN(D31)-1),'Eval. Cont.'!$A$2:$Q$31,17,FALSE) -> 16.297857 | G31: ='Quiz 1'!G32/2 -> 10 | H31: =_xludf.ifna(VLOOKUP(VALUE(A31),'Parcial 1'!$A$2:$H$30,8,FALSE),"") -> #NAME? | I31: ='Quiz 2'!L30/2 -> 2.875 | J31: =_xludf.ifna(VLOOKUP(VALUE(A31),Proyecto!$A$3:$AA$24,27, FALSE),"") -> #NAME? | K31: =_xludf.ifna(VLOOKUP(VALUE(A31),'Parcial 2'!$A$2:$G$21,7,FALSE),"") -> #NAME? | L31: =_xludf.ifna(VLOOKUP(LEFT(D31,LEN(D31)-1),Xtra!$C$6:$N$53,12,FALSE),"") -> #NAME? | M31: =SUM(F31:L31) -> #NAME? | N31: =M31/5 -> #NAME? | O31: =Partic!T31/(COUNTA(Partic!D$1:T$1)-1) -> 0.8125 | P31: =VLOOKUP(LEFT(D31,LEN(D31)-1),Tareas!$A$2:$Q$31,17,FALSE) -> 0.28571429 | Q31: =IF(E31="Retirado","R",N31+MAX(O31:P31)) -> #NAME?

Sheet Quiz 1
A1: NOMBRE | B1: P1 (4.00) | C1: P2 (9.00) | D1: P3(3.00) | E1: P4(4.00) | F1: BONO (3.00) | G1: TOTAL (23.00)
B2: Funcionamiento | C2: Fun+Mtx+Fact | D2: Funcionamiento | E2: Funcionamiento | F2: Funcionamiento
A3: Marco Alcantarini | B3: 4 | C3: 9 | D3: 3 | E3: 4 | F3: 0 | G3: 20
A4: Pedro Aponte | B4: 4 | C4: 8.5 | D4: 3 | E4: 4 | F4: 3 | G4: 22.5
A5: Maria Araque | B5: 1 | C5: 0 | D5: 0 | E5: 0 | F5: 0 | G5: 1
A6: Cesar Bezara | B6: 4 | C6: 9 | D6: 3 | E6: 4 | F6: 3 | G6: 23
A7: Ignacio Briceño | B7: 3.5 | C7: 5 | D7: 0 | E7: 0 | F7: 0 | G7: 8.5
A8: Jose El Chaer | B8: 0 | C8: 0 | D8: 0 | E8: 0 | F8: 0 | G8: 0
A9: Rocco Garcia | B9: 2.5 | C9: 0 | D9: 0 | E9: 0 | F9: 1 | G9: 3.5
A10: Salomon Gonzalez | B10: 4 | C10: 8 | D10: 3 | E10: 4 | F10: 0 | G10: 19
A11: Manuel Gonzalez | B11: 1.5 | C11: 0 | D11: 0 | E11: 0 | F11: 3 | G11: 4.5
A12: Sebastian Guillen | B12: 0 | C12: 1 | D12: 0 | E12: 0 | F12: 1 | G12: 2
A13: Antonio Guzzo | B13: 3.5 | C13: 7.5 | D13: 3 | E13: 0 | F13: 1 | G13: 15
A14: Victoria Hernandez | B14: 0 | C14: 0 | D14: 0 | E14: 0 | F14: 0 | G14: 0
... A17: Isabella Mosquera | B17: 0 | C17: 4 | D17: 3 | E17: 1 | F17: 2.5 | G17: 10.5
A18: Carlos Ortega
A19: Samuel Ostos | B19: 4 | C19: 3 | D19: 0 | E19: 0 | F19: 0 | G19: 7
A20: Daniela Pacheco | B20: 2.5 | C20: 3 | D20: 1 | E20: 1 | F20: 0.5 | G20: 8
A21: Henmary Perez | B21: 2.5 | C21: 9 | D21: 3 | E21: 4 | F21: 3 | G21: 21.5
A22: Raul Poleo | B22: 0 | C22: 0 | D22: 0 | E22: 0 | F22: 0 | G22: 0
A23: Andres Prieto | B23: 0 | C23: 9 | D23: 3 | E23: 0 | F23: 3 | G23: 15
A24: Henmary Perez | B24: 2.5 | C24: 9 | D24: 3 | E24: 4 | F24: 3 | G24: 21.5
A25: Santiago Quintero | B25: 4 | C25: 9 | D25: 0 | E25: 4 | F25: 1 | G25: 18
A26: Fabiana Rienzo | B26: 0 | C26: 0 | D26: 0.5 | E26: 0 | F26: 1 | G26: 1.5
A27: Sergio Rodrigues | B27: 0 | C27: 5.5 | D27: 0 | E27: 0 | F27: 0 | G27: 5.5
A28: Anna Tamma | B28: 0 | C28: 0 | D28: 0 | E28: 0 | F28: 0 | G28: 0
A29: Paola Valdez | B29: 0 | C29: 1.5 | D29: 3 | E29: 0 | F29: 2.5 | G29: 7
A30: Luis Velasquez | B30: 0 | C30: 0 | D30: 0 | E30: 0 | F30: 1 | G30: 1
A31: Abdallah Villarroel
A32: Santiago Zambrano | B32: 4 | C32: 9 | D32: 3 | E32: 4 | F32: 0 | G32: 20

Sheet Parcial 1
A1: CEDULA | B1: APELLIDO | C1: NOMBRE | D1: V/F | E1: Selec | F1: Complet | G1: Desarrollo | H1: Total
A2: 32336250 | B2: Villarroel | C2: Abdallah | D2: 4 | E2: 0 | H2: =SUM(D2:G2) -> 4
A3: 31935917 | B3: Poleo | C3: Raul David | D3: 3 | E3: 0 | F3: 0 | G3: 0 | H3: =SUM(D3:G3) -> 3
A4: 30612256 | B4: Alcantarini | C4: Marco | D4: 4 | E4: 3 | F4: 6 | G4: 7 | H4: =SUM(D4:G4) -> 20
A5: 31696701 | B5: Guillén | C5: Sebastián | D5: 4 | E5: 3 | F5: 5.5 | G5: 6.5 | H5: =SUM(D5:G5) -> 19
A6: 31701229 | B6: Quintero | C6: Santiago | D6: 4 | E6: 3 | F6: 4 | G6: 3 | H6: =SUM(D6:G6) -> 14
A7: 30888238 | B7: Briceño | C7: Ignacio | D7: 0 | E7: 0 | F7: 0 | G7: 0 | H7: =SUM(D7:G7) -> 0
A8: 32235827 | B8: Lahrssen | C8: Thomas | D8: 4 | E8: 3 | F8: 3 | G8: 5 | H8: =SUM(D8:G8) -> 15
A9: 31745168 | B9: Prieto | C9: Andrés | D9: 4 | E9: 3 | F9: 2 | G9: 6 | H9: =SUM(D9:G9) -> 15
A10: 31460623 | B10: Ostos | C10: Samuel | D10: 4 | E10: 3 | F10: 3.5 | H10: =SUM(D10:G10) -> 10.5
A11: 31886469 | B11: Hernández | C11: Victoria | D11: 3 | E11: 0 | F11: 0 | G11: 0 | H11: =SUM(D11:G11) -> 3
A12: 31873242 | B12: Tamma | C12: Anna Paola | D12: 3 | E12: 0 | F12: 3 | G12: 1 | H12: =SUM(D12:G12) -> 7
A13: 31979046 | B13: Gonzalez | C13: Salomon | D13: 3 | E13: 3 | F13: 6 | G13: 7 | H13: =SUM(D13:G13) -> 19
A14: 27670956 | B14: Araque | C14: Maria Emilia | D14: 3 | E14: 0 | F14: 2 | G14: 1 | H14: =SUM(D14:G14) -> 6
A15: 32042714 | B15: González | C15: Manuel | D15: 4 | E15: 0 | F15: 6 | G15: 7 | H15: =SUM(D15:G15) -> 17
A16: 32001498 | B16: Zambrano | C16: Santiago | D16: 4 | E16: 3 | F16: 6 | G16: 7 | H16: =SUM(D16:G16) -> 20
A17: 30849483 | B17: Valdez | C17: Paola | D17: 4 | E17: 3 | F17: 1 | G17: 1 | H17: =SUM(D17:G17) -> 9
A18: 30538673 | B18: Rienzo | C18: Fabiana | D18: 4 | E18: 3 | F18: 4 | H18: =SUM(D18:G18) -> 11
A19: 31423864 | B19: García | C19: Rocco | D19: 3 | E19: 0 | F19: 2.5 | G19: 1 | H19: =SUM(D19:G19) -> 6.5
A20: 31382931 | B20: Velásquez | C20: Luis | D20: 3 | E20: 3 | F20: 2 | H20: =SUM(D20:G20) -> 8
A21: 32511604 | B21: Pérez | C21: Henmary | D21: 3 | E21: 3 | G21: 6 | H21: =SUM(D21:G21) -> 12
A22: 31985209 | B22: Aponte | C22: Pedro | D22: 3 | E22: 3 | F22: 1 | H22: =SUM(D22:G22) -> 7
A23: 31935772 | B23: Guzzo | C23: Antonio | D23: 4 | E23: 0 | F23: 4 | G23: 4 | H23: =SUM(D23:G23) -> 12
A24: 32001850 | B24: Rodrigues | C24: Sergio | D24: 4 | E24: 3 | F24: 1 | G24: 3 | H24: =SUM(D24:G24) -> 11
A25: 31873119 | B25: Mosquera | C25: Isabella | D25: 4 | E25: 3 | F25: 3.5 | G25: 3.5 | H25: =SUM(D25:G25) -> 14
A26: 32121959 | B26: Jaspe | C26: Gabriel | D26: 1 | E26: 0 | F26: 3 | H26: =SUM(D26:G26) -> 4
A27: 33219652 | B27: Pedroza | C27: Gustavo | D27: 3 | E27: 3 | G27: 0 | H27: =SUM(D27:G27) -> 6
A28: 30539028 | B28: El Chaer | C28: José | D28: 4 | E28: 0 | F28: 1 | H28: =SUM(D28:G28) -> 5
A29: 33186550 | B29: Pacheco | C29: Daniela | D29: 4 | E29: 0 | F29: 6 | G29: 1 | H29: =SUM(D29:G29) -> 11
A30: 32241977 | B30: César | C30: Bezara | D30: 3 | E30: 3 | F30: 4 | G30: 0 | H30: =SUM(D30:G30) -> 10

Sheet Quiz 2
A1: NOMBRE | B1: Ejercicio (20.00) | J1: BONO (3.00) | L1: TOTAL (23.00)
B2: Clases (6) | C2: Carga de info (4) | D2: Carrito (3) | E2: Ver (2) | F2: Usuario (1) | G2: Menú (1) | H2: Robustez (1) | I2: Est (2) | J2: Est 1 (1.5) | K2: Registro (1.5)
A3: Marco Alcantarini | B3: 4 | C3: 4 | D3: 3 | E3: 2 | F3: 1 | G3: 0.75 | H3: 0.25 | I3: 2 | J3: 0 | K3: 0 | L3: =SUM(B3:K3) -> 17
A4: Pedro Aponte | B4: 5 | C4: 0 | D4: 0 | E4: 0 | F4: 0 | G4: 0 | H4: 0 | I4: 0 | J4: 0 | K4: 0 | L4: =SUM(B4:K4) -> 5
A5: Maria Araque | B5: 4.5 | C5: 0 | D5: 0 | E5: 0 | F5: 0 | G5: 0 | H5: 0 | I5: 0 | J5: 0 | K5: 0 | L5: =SUM(B5:K5) -> 4.5
A6: Cesar Bezara | B6: 5.5 | C6: 0 | D6: 0 | E6: 0 | F6: 0 | G6: 0 | H6: 0 | I6: 0 | J6: 0 | K6: 0 | L6: =SUM(B6:K6) -> 5.5
A7: Ignacio Briceño
A8: Jose El Chaer
A9: Rocco Garcia | B9: 2 | C9: 0 | D9: 0 | E9: 0 | F9: 0 | G9: 0 | H9: 0 | I9: 0 | J9: 0 | K9: 0 | L9: =SUM(B9:K9) -> 2
A10: Salomon Gonzalez | B10: 4.75 | C10: 3 | D10: 1.25 | E10: 2 | F10: 0 | G10: 1 | H10: 1 | I10: 0 | J10: 0 | K10: 0 | L10: =SUM(B10:K10) -> 13
A11: Manuel Gonzalez | B11: 5.25 | C11: 1.5 | D11: 1 | E11: 0.5 | F11: 0.25 | G11: 0.25 | H11: 0 | I11: 0 | J11: 0 | K11: 0 | L11: =SUM(B11:K11) -> 8.75
A12: Sebastian Guillen
A13: Antonio Guzzo | B13: 4.75 | C13: 0 | D13: 0 | E13: 0 | F13: 1 | G13: 0 | H13: 0 | I13: 0 | J13: 0 | K13: 0 | L13: =SUM(B13:K13) -> 5.75
A14: Victoria Hernandez | B14: 2 | C14: 0 | D14: 0 | E14: 0 | F14: 0 | G14: 0 | H14: 0 | I14: 0 | J14: 0 | K14: 0 | L14: =SUM(B14:K14) -> 2
A15: Gabriel Jaspe | B15: 1.75 | C15: 0 | D15: 2.25 | E15: 1 | F15: 0.25 | G15: 0 | H15: 0 | I15: 0 | J15: 0 | K15: 0 | L15: =SUM(B15:K15) -> 5.25
A16: Thomas Lahrssen | B16: 5 | C16: 0 | D16: 1 | E16: 2 | F16: 0 | G16: 0 | H16: 0 | I16: 0 | J16: 0 | K16: 0 | L16: =SUM(B16:K16) -> 8
A17: Isabella Mosquera | B17: 6 | C17: 0 | D17: 0 | E17: 0 | F17: 0 | G17: 0.25 | H17: 0 | I17: 0 | J17: 0 | K17: 0 | L17: =SUM(B17:K17) -> 6.25
A18: Samuel Ostos | B18: 5.5 | C18: 0 | D18: 0 | E18: 0 | F18: 0 | G18: 0 | H18: 0 | I18: 0 | J18: 0 | K18: 0 | L18: =SUM(B18:K18) -> 5.5
A19: Daniela Pacheco | B19: 5.25 | C19: 0 | E19: 1.5 | F19: 0 | G19: 0.75 | H19: 0 | I19: 0 | J19: 0 | K19: 0 | L19: =SUM(B19:K19) -> 7.5
A20: Gustavo Pedroza
A21: Henmary Perez | B21: 5 | C21: 1 | D21: 2.75 | E21: 2 | F21: 0.75 | G21: 1 | H21: 0.5 | I21: 2 | J21: 1.5 | K21: 1.5 | L21: =SUM(B21:K21) -> 18
A22: Raul Poleo
A23: Andres Prieto | B23: 4 | C23: 4 | D23: 3 | E23: 2 | F23: 1 | G23: 1 | H23: 0 | I23: 2 | J23: 0 | K23: 1.5 | L23: =SUM(B23:K23) -> 18.5
A24: Santiago Quintero | B24: 4 | C24: 3 | D24: 3 | E24: 1.5 | F24: 1 | G24: 1 | H24: 1 | I24: 2 | J24: 0 | K24: 0 | L24: =SUM(B24:K24) -> 16.5
A25: Fabiana Rienzo | B25: 5.5 | C25: 0 | D25: 0 | E25: 0 | F25: 0 | G25: 0 | H25: 0 | I25: 0 | J25: 0 | K25: 0 | L25: =SUM(B25:K25) -> 5.5
A26: Sergio Rodrigues
A27: Anna Tamm | B27: 2 | C27: 0 | D27: 0 | E27: 0 | F27: 0 | G27: 0 | H27: 0 | I27: 0 | J27: 0 | K27: 0 | L27: =SUM(B27:K27) -> 2
A28: Paola Valdez | B28: 5.25 | C28: 0 | D28: 0 | E28: 0 | F28: 0 | G28: 0 | H28: 0 | I28: 0 | J28: 0 | K28: 0 | L28: =SUM(B28:K28) -> 5.25
A29: Luis Velasquez | B29: 5.75 | C29: 1 | D29: 3 | E29: 2 | F29: 1 | G29: 0.5 | H29: 1 | I29: 2 | J29: 0 | K29: 0.5 | L29: =SUM(B29:K29) -> 16.75
A30: Santiago Zambrano | B30: 5.75 | C30: 0 | D30: 0 | E30: 0 | F30: 0 | G30: 0 | H30: 0 | I30: 0 | J30: 0 | K30: 0 | L30: =SUM(B30:K30) -> 5.75

Sheet Parcial 2
A1: Cédula | B1: Nombre | C1: V/F | D1: Selec | E1: E.Error | F1: Desarrollo | G1: Total
A2: 31745168 | B2: Andrés Prieto | C2: 4 | D2: 2 | E2: 0 | F2: 4 | G2: 10
A3: 31985209 | B3: Pedro Aponte | C3: 4 | D3: 2 | E3: 0 | F3: 1 | G3: 7
A4: 30538673 | B4: Fabiana Rienzo | C4: 4 | D4: 2 | E4: 0 | F4: 1 | G4: 7
A5: 32235827 | B5: Thomas Lahrssen | C5: 2 | D5: 2 | E5: 3 | F5: 4 | G5: 11
A6: 31701229 | B6: Santiago Quintero | C6: 2 | D6: 2 | E6: 3 | F6: 5 | G6: 12
A7: 30849483 | B7: Paola Valdez | C7: 4 | D7: 2 | E7: 0 | F7: 1 | G7: 7
A8: 32121959 | B8: Gabriel Jaspe | C8: 3 | D8: 2 | E8: 0 | F8: 1 | G8: 6
A9: 31873119 | B9: Isabella Mosquera | C9: 4 | D9: 2 | E9: 3 | F9: 2 | G9: 11
A10: 32042714 | B10: Manuel González | C10: 3 | D10: 2 | E10: 3 | F10: 7 | G10: 15
A11: 32241977 | B11: César Bezara | C11: 4 | D11: 2 | E11: 0 | F11: 1 | G11: 7
A12: 27670956 | B12: Maria Emilia Araque | C12: 3 | D12: 2 | E12: 3 | F12: 1 | G12: 9
A13: 30612256 | B13: Marco Alcantarini | C13: 4 | D13: 1 | E13: 3 | F13: 0 | G13: 8
... A20: 31696701 | B20: Sebastian Guillén | C20: 4 | D20: 2 | E20: 3 | F20: 6 | G20: 15
A21: 31460623 | B21: Samuel Ostos | C21: 4 | D21: 3 | E21: 3 | F21: 0 | G21: =SUM(C21:F21) -> 10

Sheet Proyecto
F1: Defensa | K1: Módulo 1: reactivos | N1: Módulo 2: experimentos | Q1: Módulo 3: resultados | T1: Módulo 4: Estadísticas | W1: Uso API | Y1: Archivos
A2: Cédula | B2: Apellido | C2: Nombre | D2: Ord. Entrega | E2: Ord. Defensa | F2: Expo-sicion | G2: Pregunta Prof | H2: Preg. de público | I2: Preg. a Compañero | J2: Diagra-ma | K2: Reagent Code | L2: Reagent Exec | M2: Reagent Bonus | N2: Exprmt. Code | O2: Exprmt. Exec | P2: Exprmt. Bonus | Q2: Result Code | R2: Result Exec | S2: Result Bonus | T2: Stat Code | U2: Stat Exec | V2: Stat Bonus | W2: API Code | X2: API exec | Y2: File Mgmt | Z2: File struc | AA2: Total
A3: 32235827 | B3: Lahrssen | C3: Thomas | D3: 14 | F3: 2 | G3: 1 | H3: 0.5 | I3: 3.5 | J3: 1.9 | K3: 0.9 | L3: 2 | N3: 1 | O3: 1.75 | P3: 1 | Q3: 1 | R3: 1 | S3: 1 | T3: 1 | U3: 2 | V3: 2 | W3: 1 | X3: 1 | Y3: 1 | Z3: 1 | AA3: =SUM(F3:Z3) -> 27.55
A4: 31696701 | B4: Guillén | C4: Sebastián | D4: 20 | E4: 6 | F4: 45690 | G4: 1 | H4: 1 | I4: 5.25 | K4: 0.9 | L4: 2 | N4: 1 | O4: 1.5 | Q4: 1 | R4: 1 | T4: 0.9 | U4: 1.8 | W4: 0.5 | X4: 0.5 | Y4: 0.5 | Z4: 1 | AA4: 21.85
A5: 30849483 | B5: Valdez | C5: Paola | D5: 9 | E5: 2 | F5: 2 | G5: 1 | H5: 0.75 | I5: 0.5 | J5: 1.75 | K5: 1 | L5: 2 | N5: 0.9 | O5: 1.9 | Q5: 1 | R5: 1 | T5: 1 | U5: 2 | V5: 2 | W5: 0.75 | X5: 0.75 | Y5: 1 | Z5: 1 | AA5: 22.3
A6: 32121959 | B6: Jaspe | C6: Gabriel | D6: 1 | F6: 0.5 | G6: 0 | H6: 0.25 | I6: 0.5 | J6: 0 | K6: 0.7 | L6: 0.1 | N6: 0.8 | O6: 0 | Q6: 0 | R6: 0.1 | T6: 0.1 | U6: 0.1 | W6: 0 | X6: 0 | Y6: 1 | Z6: 1 | AA6: 5.15
A7: 32042714 | B7: González | C7: Manuel | D7: 7 | E7: 1 | F7: 2 | G7: 1 | H7: 0.5 | I7: 1 | J7: 2 | K7: 1 | L7: 1.8 | N7: 0.6 | O7: 1.2 | Q7: 1 | R7: 1 | S7: 1 | T7: 1 | U7: 2 | W7: 1 | X7: 1 | Y7: 0.33 | Z7: 1 | AA7: 20.43
A8: 31979046 | B8: Gonzalez | C8: Salomon | D8: 2 | E8: 3 | F8: 2 | G8: 1 | H8: 0.75 | I8: 1 | J8: 2 | K8: 1 | L8: 1.9 | N8: 1 | O8: 2 | Q8: 0.75 | R8: 1 | S8: 1 | T8: 1 | U8: 2 | V8: 4 | W8: 1 | X8: 1 | Y8: 1 | Z8: 1 | AA8: 26.4
A9: 30538673 | B9: Rienzo | C9: Fabiana | D9: 3 | E9: 4 | F9: 2 | G9: 0.5 | H9: 1.5 | I9: 0.5 | J9: 2 | K9: 0.75 | L9: 0.9 | N9: 0.75 | O9: 1 | Q9: 0.5 | R9: 0 | T9: 0.5 | U9: 1 | W9: 0.5 | X9: 0.5 | Y9: 1 | Z9: 1 | AA9: 14.9
A10: 31935772 | B10: Guzzo | C10: Antonio | D10: 4 | E10: 5 | F10: 45690 | G10: 0/1 | H10: 1.5/0.5 | K10: 0.5/1 | L10: 45690 | N10: 0.50/1 | O10: 45659 | P10: =1 -> 1 | Q10: 0/1 | R10: 0/1 | T10: 0/1 | U10: 0/2 | W10: 45658 | X10: 45658 | Y10: 0/1 | Z10: 0/1 | AA10: 10.5
A11: 31873242 | B11: Tamma | C11: Anna | D11: 5 | E11: 7 | F11: 2 | G11: 0 | H11: 1.5 | I11: 2.5 | K11: 1 | L11: 0 | N11: 0 | O11: 0 | Q11: 0 | R11: 0 | T11: 0 | U11: 0 | W11: 0.5 | X11: 0 | Y11: 0.5 | Z11: 0.5 | AA11: 8.5
A12: 31873119 | B12: Mosquera | C12: Isabella | D12: 21 | E12: 8 | F12: 2 | G12: 1 | H12: 4 | I12: 1 | J12: 2 | K12: 0.75 | L12: 2 | N12: 0.75 | O12: 2 | Q12: 1 | R12: 0.5 | S12: 1.5 | T12: 1 | U12: 1 | W12: 0.5 | X12: 1 | Y12: 1 | Z12: 1 | AA12: 24
A13: 33186550 | B13: Pacheco | C13: Daniela | D13: 11 | F13: 2 | G13: 1 | H13: 0.5 | I13: 5 | J13: 1 | K13: 1 | L13: 2 | N13: 1 | O13: 1.8 | Q13: 1 | R13: 0 | S13: 2 | T13: 1 | U13: 1.8 | V13: 0.2 | W13: 1 | X13: 1 | Y13: 1 | Z13: 1 | AA13: 25.3
A14: 27670956 | B14: Araque | C14: Maria | D14: 8 | F14: 2 | G14: 0.75 | H14: 0.5 | I14: 4 | J14: 1.75 | K14: 1 | L14: 2 | M14: 1 | N14: 1 | O14: 1 | P14: 1 | Q14: 1 | R14: 2 | S14: 2 | T14: 1 | U14: 2 | V14: 1 | W14: 1 | X14: 1 | Y14: 1 | Z14: 1 | AA14: 29
A15: 32511604 | B15: Pérez | C15: Henmary | D15: 13 | F15: 1 | G15: 1 | H15: 0.5 | I15: 7 | K15: 1 | L15: 1 | N15: 1 | O15: 1 | P15: 2 | Q15: 0 | R15: 0 | T15: 0 | U15: 0 | W15: 0 | X15: 0 | Y15: 0.5 | Z15: 0.75 | AA15: 16.75
A16: 31985209 | B16: Aponte | C16: Pedro | D16: 18 | F16: 0.5 | G16: 0 | H16: 0.25 | I16: 1 | K16: 0 | L16: 0 | N16: 0 | O16: 0 | Q16: 0 | R16: 0 | S16: 1 | T16: 0 | U16: 0 | W16: 0 | X16: 0 | Y16: 1 | Z16: 0 | AA16: 3.75
A17: 32241977 | B17: Bezara | C17: Cesar | D17: 19 | F17: 0.5 | G17: 0 | H17: 0.25 | I17: 0.5 | K17: 0.14 | L17: 0.4 | N17: 0 | O17: 0 | Q17: 0.25 | R17: 0.1 | S17: 1 | T17: 0 | U17: 0 | W17: 0 | X17: 0 | AA17: 3.14
A18: 31701229 | B18: Quintero | C18: Santiago | E18: 10 | F18: 2 | G18: 0 | H18: 1.5 | I18: 0.5 | K18: 0.5 | L18: 0 | N18: 0.5 | O18: 1 | Q18: 0 | R18: 0 | T18: 0.5 | U18: 2 | V18: 1 | W18: 0.5 | X18: 0.75 | Y18: 1 | Z18: 0 | AA18: 11.75
A19: 31382931 | B19: Velásquez | C19: Luis | D19: 15 | E19: 11 | F19: 1.9/2 | G19: 45658 | H19: 3.0/0.5 | I19: 2.0/0.5 | J19: 45690 | K19: 45658 | L19: 45690 | N19: 0.5/1 | O19: 45690 | P19: =1 -> 1 | Q19: 1.0/1 | R19: 0.0/1 | T19: 45658 | U19: 2 | V19: =2 -> 2 | W19: 45658 | Y19: 45658 | Z19: 45658 | AA19: 24.9
A20: 30612256 | B20: Alcantarini | C20: Marco | D20: 6 | K20: 0.5/1 | L20: 0.5/2 | N20: 0.5/1 | O20: 0.25/2 | P20: =1 -> 1 | Q20: 0/1 | R20: 0/1 | T20: 0/1 | U20: 0/2 | W20: 45658 | X20: 45658 | Y20: 45658 | Z20: 0/1 | AA20: 5.2
A21: 31460623 | B21: Ostos | C21: Samuel | D21: 10 | F21: 1.5 | G21: 0.5 | H21: 0.5 | I21: 1.5 | J21: 1 | K21: 0.75 | L21: 1.75 | N21: 0.5 | O21: 0 | Q21: 0.5 | R21: 0 | T21: 0.5 | U21: 0 | W21: 0.5 | X21: 0.5 | Y21: 1 | Z21: 0 | AA21: 11
A22: 31745168 | B22: Prieto | C22: Andrés | D22: 12 | I22: 0.5/0.5 | K22: 0.00/1 | L22: 0/2 | N22: 0/1 | O22: 0/2 | Q22: 0/1 | R22: 0/1 | T22: 0/1 | U22: 0/2 | W22: 0/1 | X22: 0/1 | Y22: 45658 | Z22: 0/1 | AA22: 1.5
A23: 31886469 | B23: Hernández | C23: Victoria | D23: 17 | K23: 0.0/1 | L23: 0/2 | N23: 0/1 | O23: 0/2 | Q23: 0/1 | R23: 0/1 | T23: 0/1 | U23: 0/2 | W23: 45658 | X23: 0/1 | Y23: 0/1 | Z23: 0/1 | AA23: 1
A24: 32001498 | B24: Zambrano | C24: Santiago | D24: 16 | E24: 9 | F24: 1.9 | G24: 1 | H24: 2.5 | I24: 3.5 | K24: 1 | L24: 0 | N24: 1 | O24: 0 | Q24: 0.5 | R24: 0 | T24: 0.5 | U24: 1 | W24: 0 | X24: 0 | Y24: 1 | Z24: 0 | AA24: 13.9

Sheet Eval. Cont.
A1: Correo unimet | B1: Nombre | C1: Quiz 1 de EvaluaciÃ³n Continua - IntroducciÃ³n (52110139) | D1: Quiz 2 de EvaluaciÃ³n Continua - Operaciones (52110120) | E1: Quiz 3 de EvaluaciÃ³n Continua - Condicionales (52110140) | F1: Quiz 4 de EvaluaciÃ³n continua - Bucles (52110129) | G1: Quiz 5 de EvaluaciÃ³n continua - Listas (52110132) | H1: Quiz 6 de EvaluaciÃ³n Continua - diccionarios (52110122) | I1: Quiz 7 de EvaluaciÃ³n Continua - Funciones (52110136) | J1: Quiz 8 de EvaluaciÃ³n Continua - ProgramaciÃ³n Orientada a Objetos (52110123) | K1: Quiz 9 de EvaluaciÃ³n Continua - Herencia (52110124) | L1: Quiz 10 de EvaluaciÃ³n Continua - Diagrama de Clases (52110128) | M1: Quiz 11 de EvaluaciÃ³n Continua - APIs y Archivos (52110138) | N1: Quiz 13 de EvaluaciÃ³n ContÃ­nua - Recursividad (52110127) | O1: Quiz 14 de EvaluaciÃ³n ContÃ­nua - Ordenamiento (52110126) | P1: Quiz 15 de EvaluaciÃ³n ContÃ­nua - Complejidad (52110133) | Q1: Acum
A2: marco.alcantarini@correo.unimet.edu.ve | B2: Alcantarini. Marco | C2: 18 | D2: 15 | E2: 11 | F2: 12 | G2: 20 | H2: 16 | I2: 10 | J2: 19 | K2: 16.67 | L2: 18 | M2: 20 | N2: 18 | O2: 18 | P2: 18 | Q2: =SUM(C2:P2)/COUNTA(C$1:P$1) -> 16.405
A3: pedro.aponte@correo.unimet.edu.ve | B3: Aponte. Pedro | C3: 16 | D3: 18.33 | E3: 16 | F3: 10 | G3: 19 | H3: 20 | I3: 18 | J3: 20 | K3: 18 | L3: 14.7 | M3: 20 | N3: 18 | O3: 18 | P3: 18 | Q3: =SUM(C3:P3)/COUNTA(C$1:P$1) -> 17.430714
A4: maria.araque@correo.unimet.edu.ve | B4: Araque. Maria | C4: 18 | D4: 20 | E4: 18 | F4: 19.5 | G4: 18 | H4: 20 | I4: 14 | J4: 19 | K4: 20 | L4: 19.6 | M4: 20 | N4: 20 | O4: 16 | P4: 18 | Q4: =SUM(C4:P4)/COUNTA(C$1:P$1) -> 18.578571
A5: cbezara@correo.unimet.edu.ve | B5: Bezara. Cesar | C5: 18 | D5: 18 | E5: 14 | F5: 20 | G5: 18 | H5: 20 | I5: 16 | J5: 10 | K5: 20 | L5: 18 | M5: 16 | N5: 18 | O5: 12 | P5: 20 | Q5: =SUM(C5:P5)/COUNTA(C$1:P$1) -> 17
A6: ignacio.briceno@correo.unimet.edu.ve | B6: BriceÃ±o. Ignacio | C6: 18 | D6: 16 | E6: 11.67 | F6: 16 | G6: 12 | H6: 10 | I6: 10 | J6: 13.33 | K6: 10 | L6: 18 | M6: 14 | N6: 18 | Q6: =SUM(C6:P6)/COUNTA(C$1:P$1) -> 11.928571
A7: jelchaer@correo.unimet.edu.ve | B7: Chaer. JosÃ© El | C7: 18 | D7: 15.33 | E7: 14 | F7: 7.5 | G7: 10 | H7: 17.5 | Q7: =SUM(C7:P7)/COUNTA(C$1:P$1) -> 5.8807143
A8: rocco.garcia@correo.unimet.edu.ve | B8: GarcÃ­a. Rocco | C8: 10 | D8: 10 | E8: 10 | F8: 10 | G8: 10 | H8: 10 | I8: 10 | J8: 16 | K8: 12 | L8: 15.1 | M8: 16 | N8: 18 | O8: 18 | P8: 18 | Q8: =SUM(C8:P8)/COUNTA(C$1:P$1) -> 13.078571
A9: go.manuel@correo.unimet.edu.ve | B9: GonzÃ¡lez. Manuel | C9: 20 | D9: 18 | E9: 11 | F9: 19.5 | G9: 16 | H9: 18 | I9: 18 | J9: 18 | K9: 20 | L9: 20 | M9: 20 | N9: 14 | P9: 20 | Q9: =SUM(C9:P9)/COUNTA(C$1:P$1) -> 16.607143
A10: salo-gonzalez@correo.unimet.edu.ve | B10: Gonzalez. Salomon | C10: 20 | D10: 17 | E10: 16 | F10: 20 | G10: 20 | H10: 20 | I10: 18 | J10: 18 | K10: 19 | L10: 20 | M10: 20 | N10: 20 | O10: 10 | P10: 18 | Q10: =SUM(C10:P10)/COUNTA(C$1:P$1) -> 18.285714
A11: s.guillen@correo.unimet.edu.ve | B11: GuillÃ©n. SebastiÃ¡n | C11: 20 | D11: 16.67 | E11: 16 | F11: 18 | G11: 18 | H11: 11 | I11: 10 | J11: 16.67 | K11: 12 | L11: 16 | M11: 10 | N11: 10 | O11: 10 | P11: 14 | Q11: =SUM(C11:P11)/COUNTA(C$1:P$1) -> 14.167143
A12: antonio.guzzo@correo.unimet.edu.ve | B12: Guzzo. Antonio | C12: 16 | D12: 16 | E12: 18 | F12: 20 | G12: 18 | H12: 11.5 | I12: 16 | J12: 15.33 | K12: 10 | M12: 10 | N12: 10 | O12: 10 | Q12: =SUM(C12:P12)/COUNTA(C$1:P$1) -> 12.202143
A13: h.victoria@correo.unimet.edu.ve | B13: HerÃ¡ndez. Victoria | C13: 16 | D13: 15.67 | E13: 12 | F13: 13.5 | H13: 15 | K13: 17 | L13: 17.5 | M13: 18 | N13: 18 | O13: 18 | P13: 18 | Q13: =SUM(C13:P13)/COUNTA(C$1:P$1) -> 12.762143
A14: carlos.ortega@correo.unimet.edu.ve | B14: Iannacci. Carlos Daniel Ortega | Q14: =SUM(C14:P14)/COUNTA(C$1:P$1) -> 0
A15: g.jaspe@correo.unimet.edu.ve | B15: Jaspe. Gabriel | C15: 10 | D15: 12 | E15: 11 | F15: 14 | G15: 20 | H15: 17.5 | I15: 20 | J15: 18 | K15: 19 | L15: 20 | M15: 18 | N15: 14 | O15: 16 | P15: 17 | Q15: =SUM(C15:P15)/COUNTA(C$1:P$1) -> 16.178571
A16: thomas.lahrssen@correo.unimet.edu.ve | B16: Lahrssen. Thomas | C16: 20 | D16: 16 | E16: 18 | F16: 16 | G16: 20 | H16: 20 | I16: 18 | J16: 19 | K16: 19 | L16: 18.6 | M16: 20 | N16: 18 | O16: 16 | P16: 18 | Q16: =SUM(C16:P16)/COUNTA(C$1:P$1) -> 18.328571
A17: isabella.mosquera@correo.unimet.edu.ve | B17: Mosquera. Isabella | C17: 20 | D17: 20 | E17: 16 | F17: 20 | G17: 18 | H17: 19.5 | I17: 20 | J17: 17 | K17: 20 | L17: 20 | M17: 16 | N17: 18 | O17: 18 | P17: 16 | Q17: =SUM(C17:P17)/COUNTA(C$1:P$1) -> 18.464286
A18: samuel.ostos@correo.unimet.edu.ve | B18: Ostos. Samuel | C18: 14 | D18: 18 | E18: 13 | F18: 18 | G18: 20 | H18: 17.5 | I18: 10 | J18: 10 | K18: 10 | L18: 10 | M18: 12 | N18: 16 | O18: 16 | P18: 14 | Q18: =SUM(C18:P18)/COUNTA(C$1:P$1) -> 14.178571
A19: danipacheco@correo.unimet.edu.ve | B19: Pacheco. Daniela | C19: 16 | D19: 17 | E19: 16 | F19: 18 | G19: 20 | H19: 19.5 | I19: 16 | J19: 13.33 | K19: 18 | L19: 18 | M19: 18 | N19: 20 | O19: 18 | P19: 18 | Q19: =SUM(C19:P19)/COUNTA(C$1:P$1) -> 17.559286
A20: gustavo.pedroza@correo.unimet.edu.ve | B20: Pedroza. Gustavo | C20: 18 | D20: 19 | E20: 12 | F20: 18 | G20: 10 | H20: 18 | I20: 10 | Q20: =SUM(C20:P20)/COUNTA(C$1:P$1) -> 7.5
A21: henmary.perez@correo.unimet.edu.ve | B21: PÃ©rez. Henmary | C21: 20 | D21: 18 | E21: 20 | F21: 17.5 | G21: 18 | H21: 18 | I21: 20 | J21: 17 | K21: 14 | L21: 20 | M21: 20 | N21: 18 | O21: 20 | P21: 18 | Q21: =SUM(C21:P21)/COUNTA(C$1:P$1) -> 18.464286
A22: raul.poleo@correo.unimet.edu.ve | B22: Poleo. Raul | C22: 17.33 | D22: 14 | E22: 13.33 | H22: 15 | Q22: =SUM(C22:P22)/COUNTA(C$1:P$1) -> 4.2614286
A23: andres.prieto@correo.unimet.edu.ve | B23: Prieto. AndrÃ©s | C23: 14 | D23: 15 | E23: 7 | F23: 7.67 | G23: 16 | H23: 18 | I23: 10 | J23: 17.33 | K23: 18 | L23: 20 | M23: 16 | N23: 16 | O23: 18 | P23: 16 | Q23: =SUM(C23:P23)/COUNTA(C$1:P$1) -> 14.928571
A24: quintero.santiago@correo.unimet.edu.ve | B24: Quintero. Santiago | C24: 18 | D24: 17 | E24: 18 | F24: 20 | G24: 16 | H24: 18 | I24: 20 | J24: 18 | K24: 17 | L24: 10 | M24: 18 | N24: 18 | O24: 10 | P24: 20 | Q24: =SUM(C24:P24)/COUNTA(C$1:P$1) -> 17
A25: frienzo@correo.unimet.edu.ve | B25: Rienzo. Fabiana | C25: 20 | D25: 18.33 | E25: 19.33 | F25: 18 | G25: 16 | H25: 17 | I25: 20 | J25: 18 | K25: 17.33 | L25: 20 | M25: 17 | N25: 16 | O25: 20 | P25: 16 | Q25: =SUM(C25:P25)/COUNTA(C$1:P$1) -> 18.070714
A26: rodrigues.sergio@correo.unimet.edu.ve | B26: Rodrigues. Sergio | C26: 16 | D26: 17 | E26: 14 | F26: 16 | G26: 20 | H26: 18 | I26: 18 | J26: 15 | K26: 17 | L26: 19.2 | M26: 18 | N26: 18 | Q26: =SUM(C26:P26)/COUNTA(C$1:P$1) -> 14.728571
A27: a.tamma@correo.unimet.edu.ve | B27: Tamm. Anna | C27: 16 | D27: 16 | E27: 6 | F27: 18 | H27: 17.5 | K27: 18 | L27: 20 | M27: 14 | N27: 18 | O27: 18 | P27: 16 | Q27: =SUM(C27:P27)/COUNTA(C$1:P$1) -> 12.678571
A28: pvaldez@correo.unimet.edu.ve | B28: Valdez. Paola | C28: 14 | D28: 19 | E28: 18 | F28: 19 | G28: 20 | H28: 20 | I28: 18 | J28: 18 | K28: 17 | L28: 19.6 | M28: 20 | N28: 20 | O28: 16 | P28: 14 | Q28: =SUM(C28:P28)/COUNTA(C$1:P$1) -> 18.042857
A29: velasquez.luis@correo.unimet.edu.ve | B29: VelÃ¡squez. Luis | C29: 18 | D29: 17 | E29: 20 | F29: 18 | G29: 20 | H29: 16 | I29: 20 | J29: 20 | K29: 20 | L29: 20 | M29: 18 | N29: 20 | O29: 20 | P29: 18 | Q29: =SUM(C29:P29)/COUNTA(C$1:P$1) -> 18.928571
A30: abdallah.villarroel@correo.unimet.edu.ve | B30: Villarroel. Abdallah | C30: 16 | D30: 18 | E30: 18 | F30: 11.5 | G30: 10 | I30: 10 | Q30: =SUM(C30:P30)/COUNTA(C$1:P$1) -> 5.9642857
A31: s.zambrano@correo.unimet.edu.ve | B31: Zambrano. Santiago | C31: 20 | D31: 17 | E31: 16.67 | F31: 20 | G31: 10 | H31: 19.5 | I31: 14 | J31: 14 | K31: 20 | L31: 13 | M31: 14 | N31: 16 | O31: 18 | P31: 16 | Q31: =SUM(C31:P31)/COUNTA(C$1:P$1) -> 16.297857

Sheet Partic
A1: CI | B1: Nombre de Pila | C1: Nombre y apellido | D1: Jan-06 | E1: 08-Jan | F1: 13-Jan | G1: 45672 | H1: 45677 | I1: 45679 | J1: 45684 | K1: 45686 | L1: 45693 | M1: 45700 | N1: 45705 | O1: 45707 | P1: 45712 | Q1: 45714 | R1: 45726 | S1: 45728 | T1: TOTAL
A2: 30612256 | B2: Marco Antonio | C2: Marco Alcantarini | D2: 1 | G2: 1 | T2: =SUM(B2:Q2) -> 2
A3: 31985209 | B3: Pedro Manuel | C3: Pedro Aponte | S3: 2 | T3: =SUM(B3:Q3) -> 0
A4: 27670956 | B4: Maria Emilia | C4: Maria Araque | F4: 2 | H4: 1 | I4: 1 | K4: 2 | L4: 1 | M4: 2 | N4: 1 | O4: 1 | P4: 3 | Q4: 1 | R4: 1 | S4: 1 | T4: =SUM(B4:S4) -> 17
A5: 32241977 | B5: Cesar Miguel | C5: Cesar Bezara | E5: 2 | T5: =SUM(B5:Q5) -> 2
A6: 30888238 | B6: Ignacio Javier | C6: Ignacio Briceño | E6: 1 | F6: 2 | K6: 4 | L6: 1 | M6: 1 | N6: 1 | T6: =SUM(B6:Q6) -> 10
A7: 30539028 | B7: José Ángel | C7: José El Chaer | T7: =SUM(B7:Q7) -> 0
A8: 31423864 | B8: Rocco | C8: Rocco García | T8: =SUM(B8:R8) -> 0
A9: 31979046 | B9: Salomon Jose | C9: Salomon Gonzalez | E9: 2 | K9: 2 | O9: 1 | P9: 1 | R9: 1 | S9: 2 | T9: =SUM(B9:S9) -> 9
A10: 32042714 | B10: Manuel Ignacio | C10: Manuel González | H10: 2 | J10: 2 | K10: 1 | L10: 1 | M10: 1 | N10: 1 | O10: 1 | P10: 3 | Q10: 3 | R10: 1 | T10: =SUM(B10:R10) -> 16
A11: 31696701 | B11: Sebastián José | C11: Sebastián Guillén | D11: 1 | E11: 1 | G11: 1 | H11: 3 | I11: 1 | K11: 1 | L11: 1 | M11: 3 | N11: 1 | O11: 1 | P11: 3 | Q11: 3 | R11: 1 | S11: 1 | T11: =SUM(B11:S11) -> 22
A12: 31935772 | B12: Antonio Alfredo | C12: Antonio Guzzo | F12: 2 | K12: 2 | L12: 1 | O12: 1 | T12: =SUM(B12:Q12) -> 6
A13: 31886469 | B13: Victoria Coromoto de Jesus | C13: Victoria Hernández | T13: =SUM(B13:Q13) -> 0
A14: 32121959 | B14: Gabriel Ali | C14: Gabriel Jaspe | T14: =SUM(B14:Q14) -> 0
A15: 32235827 | B15: Thomas Alejandro | C15: Thomas Lahrssen | D15: 3 | E15: 3 | F15: 3 | G15: 2 | I15: 3 | K15: 1 | L15: 1 | M15: 1 | O15: 1 | P15: 1 | Q15: 3 | R15: 1 | T15: =SUM(B15:R15) -> 23
A16: 31873119 | B16: Isabella | C16: Isabella Mosquera | D16: 1 | F16: 1 | G16: 1 | H16: 1 | I16: 1 | J16: 2 | K16: 2 | L16: 1 | M16: 2 | N16: 3 | O16: 1 | P16: 3 | Q16: 3 | R16: 1 | S16: 1 | T16: =SUM(B16:S16) -> 24
A17: 27007813 | B17: Carlos Daniel | C17: Carlos Ortega | O17: 1 | T17: =SUM(B17:Q17) -> 1
A18: 31460623 | B18: Samuel Felipe | C18: Samuel Ostos | O18: 1 | T18: =SUM(B18:Q18) -> 1
A19: 33186550 | B19: Daniela Valentina | C19: Daniela Pacheco | F19: 1 | H19: 2 | I19: 3 | M19: 4 | N19: 1 | O19: 3 | Q19: 1 | R19: 1 | S19: 1 | T19: =SUM(B19:S19) -> 17
A20: 33219652 | B20: Gustavo Alberto | C20: Gustavo Pedroza | T20: =SUM(B20:Q20) -> 0
A21: 31935917 | B21: Raul David | C21: Raul Poleo | E21: 1 | F21: 2 | H21: 1 | T21: =SUM(B21:Q21) -> 4
A22: 31745168 | B22: Andrés Alejandro | C22: Andrés Prieto | L22: 1 | M22: 1 | T22: =SUM(B22:Q22) -> 2
A23: 32511604 | B23: Henmary José | C23: Henmary Pérez | D23: 2 | E23: 2 | F23: 1 | G23: 1 | H23: 1 | I23: 1 | J23: 3 | L23: 1 | M23: 2 | N23: 3 | O23: 3 | P23: 1 | Q23: 1 | R23: 1 | S23: 1 | T23: =SUM(B23:S23) -> 24
A24: 31701229 | B24: Santiago alonso | C24: Santiago Quintero | F24: 1 | G24: 2 | H24: 1 | I24: 1 | J24: 3 | K24: 3 | L24: 3 | M24: 1 | O24: 1 | P24: 2 | R24: 1 | T24: =SUM(B24:R24) -> 19
A25: 30538673 | B25: Fabiana Rosa | C25: Fabiana Rienzo | D25: 2 | F25: 1 | I25: 1 | L25: 1 | M25: 1 | R25: 1 | T25: =SUM(B25:R25) -> 7
A26: 32001850 | B26: Sergio Rodrigo | C26: Sergio Rodrigues | D26: 2 | E26: 1 | K26: 2 | T26: =SUM(B26:Q26) -> 5
A27: 31873242 | B27: Anna Paola | C27: Anna Tamma | T27: =SUM(B27:Q27) -> 0
A28: 30849483 | B28: Paola Daniela | C28: Paola Valdez | G28: 2 | I28: 1 | L28: 1 | M28: 1 | P28: 2 | Q28: 2 | R28: 1 | T28: =SUM(B28:R28) -> 10
A29: 31382931 | B29: Luis Miguel | C29: Luis Velásquez | D29: 1 | E29: 2 | F29: 2 | G29: 2 | H29: 1 | I29: 2 | K29: 2 | M29: 1 | N29: 3 | O29: 1 | R29: 1 | T29: =SUM(B29:R29) -> 18
A30: 32336250 | B30: Abdallah Joseph | C30: Abdallah Villarroel | T30: =SUM(B30:Q30) -> 0
A31: 32001498 | B31: Santiago Enrique | C31: Santiago Zambrano | G31: 2 | H31: 3 | I31: 2 | K31: 2 | M31: 1 | N31: 1 | Q31: 2 | S31: 2 | T31: =SUM(B31:Q31) -> 13
B32: TOTAL | D32: =SUM(D2:D31) -> 13 | E32: =SUM(E2:E31) -> 15 | F32: =SUM(F2:F31) -> 18 | G32: =SUM(G2:G31) -> 14 | H32: =SUM(H2:H31) -> 16 | I32: =SUM(I2:I31) -> 17 | J32: =SUM(J2:J31) -> 10 | K32: =SUM(K2:K31) -> 24 | ... Q32: =SUM(Q2:Q31) -> 19 | T32: =SUM(B32:Q32) -> 233

Sheet Tareas
A1: Correo unimet | B1: Nombre | C1: Tarea 1: GitHub (52110170) | D1: Tarea 2: Arepas DinÃ¡micas (52110169) | E1: Tarea 3: Perfil de usuario (52110171) | F1: Tarea 4: AÃ±o Bisiesto (52110172) | G1: Tarea 5: Â¡Batalla! (juego de cartas) (52110173) | H1: Tarea 6: Batalla pokÃ©mon (52110174) | I1: Tarea 7: Batalla PokÃ©mon con Funciones (52110175) | J1: Tarea 8: Registro de vehÃ­culos (52110176) | K1: Tarea 9: Marcar tarjeta (52110177) | L1: Tarea 10: Diagrama de Clases (52110162) | M1: Tarea 11: PokÃ©dex (52110163) | N1: Tarea 13: RecursiÃ³n (52110165) | O1: Tarea 14: Algoritmos de Ordenamiento (52110166) | P1: Tarea 15: Complejidad (52110168) | Q1: Total
A2: marco.alcantarini@correo.unimet.edu.ve | B2: Alcantarini. Marco | C2: TRUE | D2: TRUE | E2: TRUE | F2: TRUE | G2: FALSE | H2: FALSE | I2: FALSE | J2: FALSE | K2: FALSE | L2: FALSE | M2: FALSE | N2: FALSE | O2: FALSE | P2: FALSE | Q2: =COUNTIF(C2:P2,TRUE)/COUNTA(C$1:P$1) -> 0.28571429
A3: pedro.aponte@correo.unimet.edu.ve | B3: Aponte. Pedro | C3: TRUE | D3: TRUE | E3: TRUE | F3: TRUE | G3: TRUE | H3: TRUE | I3: TRUE | J3: TRUE | K3: TRUE | L3: TRUE | M3: TRUE | N3: TRUE | O3: FALSE | P3: FALSE | Q3: =COUNTIF(C3:P3,TRUE)/COUNTA(C$1:P$1) -> 0.85714286
A4: maria.araque@correo.unimet.edu.ve | B4: Araque. Maria | C4: TRUE | D4: TRUE | E4: TRUE | F4: TRUE | G4: FALSE | H4: TRUE | I4: TRUE | J4: TRUE | K4: TRUE | L4: TRUE | M4: TRUE | N4: TRUE | O4: TRUE | P4: TRUE | Q4: =COUNTIF(C4:P4,TRUE)/COUNTA(C$1:P$1) -> 0.92857143
A5: cbezara@correo.unimet.edu.ve | B5: Bezara. Cesar | C5: TRUE | D5: TRUE | E5: TRUE | F5: TRUE | G5: TRUE | H5: TRUE | I5: TRUE | J5: TRUE | K5: TRUE | L5: TRUE | M5: TRUE | N5: TRUE | O5: TRUE | P5: FALSE | Q5: =COUNTIF(C5:P5,TRUE)/COUNTA(C$1:P$1) -> 0.92857143
A6: ignacio.briceno@correo.unimet.edu.ve | B6: BriceÃ±o. Ignacio | C6: TRUE | D6: TRUE | E6: TRUE | F6: TRUE | G6: TRUE | H6: FALSE | I6: FALSE | J6: FALSE | K6: FALSE | L6: FALSE | M6: FALSE | N6: FALSE | O6: FALSE | P6: FALSE | Q6: =COUNTIF(C6:P6,TRUE)/COUNTA(C$1:P$1) -> 0.35714286
A7: jelchaer@correo.unimet.edu.ve | B7: Chaer. JosÃ© El | C7: FALSE | D7: TRUE | E7: TRUE | F7: TRUE | G7: TRUE | H7: TRUE | I7: FALSE | J7: FALSE | K7: FALSE | L7: FALSE | M7: FALSE | N7: FALSE | O7: FALSE | P7: FALSE | Q7: =COUNTIF(C7:P7,TRUE)/COUNTA(C$1:P$1) -> 0.35714286
A8: rocco.garcia@correo.unimet.edu.ve | B8: GarcÃ­a. Rocco | C8: FALSE | D8: TRUE | E8: TRUE | F8: TRUE | G8: FALSE | H8: FALSE | I8: FALSE | J8: FALSE | K8: FALSE | L8: FALSE | M8: FALSE | N8: FALSE | O8: FALSE | P8: FALSE | Q8: =COUNTIF(C8:P8,TRUE)/COUNTA(C$1:P$1) -> 0.21428571
A9: go.manuel@correo.unimet.edu.ve | B9: GonzÃ¡lez. Manuel | C9: TRUE | D9: TRUE | E9: TRUE | F9: TRUE | G9: TRUE | H9: TRUE | I9: FALSE | J9: FALSE | K9: TRUE | L9: FALSE | M9: TRUE | N9: FALSE | O9: FALSE | P9: FALSE | Q9: =COUNTIF(C9:P9,TRUE)/COUNTA(C$1:P$1) -> 0.57142857
A10: salo-gonzalez@correo.unimet.edu.ve | B10: Gonzalez. Salomon | C10: TRUE | D10: TRUE | E10: TRUE | F10: TRUE | G10: TRUE | H10: TRUE | I10: TRUE | J10: TRUE | K10: FALSE | L10: TRUE | M10: TRUE | N10: TRUE | O10: TRUE | P10: FALSE | Q10: =COUNTIF(C10:P10,TRUE)/COUNTA(C$1:P$1) -> 0.85714286
A11: s.guillen@correo.unimet.edu.ve | B11: GuillÃ©n. SebastiÃ¡n | C11: TRUE | D11: TRUE | E11: TRUE | F11: TRUE | G11: FALSE | H11: TRUE | I11: FALSE | J11: FALSE | K11: FALSE | L11: FALSE | M11: FALSE | N11: FALSE | O11: FALSE | P11: FALSE | Q11: =COUNTIF(C11:P11,TRUE)/COUNTA(C$1:P$1) -> 0.35714286
A12: antonio.guzzo@correo.unimet.edu.ve | B12: Guzzo. Antonio | C12: FALSE | D12: TRUE | E12: FALSE | F12: FALSE | G12: FALSE | H12: FALSE | I12: FALSE | J12: FALSE | K12: FALSE | L12: FALSE | M12: FALSE | N12: FALSE | O12: FALSE | P12: FALSE | Q12: =COUNTIF(C12:P12,TRUE)/COUNTA(C$1:P$1) -> 0.071428571
A13: h.victoria@correo.unimet.edu.ve | B13: HerÃ¡ndez. Victoria | C13: TRUE | D13: TRUE | E13: FALSE | F13: FALSE | G13: FALSE | H13: TRUE | I13: FALSE | J13: FALSE | K13: FALSE | L13: FALSE | M13: FALSE | N13: FALSE | O13: FALSE | P13: FALSE | Q13: =COUNTIF(C13:P13,TRUE)/COUNTA(C$1:P$1) -> 0.21428571
... A31: s.zambrano@correo.unimet.edu.ve | B31: Zambrano. Santiago | C31: FALSE | D31: TRUE | E31: TRUE | F31: TRUE | G31: TRUE | H31: FALSE | I31: FALSE | J31: FALSE | K31: FALSE | L31: FALSE | M31: FALSE | N31: FALSE | O31: FALSE | P31: FALSE | Q31: =COUNTIF(C31:P31,TRUE)/COUNTA(C$1:P$1) -> 0.28571429

Sheet Xtra
A1: Código Naranja 2425-2
A2: 01 | E2: Ejercicio #1 | F2: Ejercicio #2 | G2: Ejercicio #3 | H2: Ejercicio #4 | I2: Ejercicio #5 | J2: Ejercicio #6 | K2: Ejercicio #8 | L2: RPC 02
A3: =HYPERLINK("https://classroom.google.com/c/NzQ2NzcxMDkxODky", UPPER("Abrir Classroom")) -> ABRIR CLASSROOM | E3: 1 | F3: 1 | G3: 1 | H3: 1 | I3: 1 | J3: 1 | K3: 1 | L3: 3
A5: Media de la clase | D5: 0.44516129 | E5: 0.19354839 | F5: 0.16129032 | G5: 0.25806452 | H5: 0.19354839 | I5: 0.38709677 | J5: 0.48387097 | K5: 0.25806452 | L5: 2.516129 | M5: TOTAL NARANJA | N5: Total pts de 100
A6: Marcano | B6: Alejandro | C6: marcano.alejandro@correo.unimet.edu.ve | D6: 0.6 | E6: 0 | F6: 0 | G6: 0 | H6: 0 | I6: 0 | J6: 0 | K6: 0 | L6: 2 | M6: =SUM(E6:K6)/8 -> 0 | N6: =M6*6+IF(L6>0,4,0) -> 4
A7: Leon | B7: Alexia | C7: a.leon2020@correo.unimet.edu.ve | M7: =SUM(E7:K7)/8 -> 0 | N7: =M7*6+IF(L7>0,4,0) -> 0
A8: Tucci | B8: Andres | C8: atucci@correo.unimet.edu.ve | D8: 0.7 | E8: 0 | F8: 0 | G8: 0 | H8: 0 | I8: 0 | J8: 0 | K8: 0 | L8: 3 | M8: =SUM(E8:K8)/8 -> 0 | N8: =M8*6+IF(L8>0,4,0) -> 4
A9: Atencio | B9: Cesar | C9: c.atencio@correo.unimet.edu.ve | D9: 1.45 | E9: 1 | F9: 0 | G9: 0 | H9: 0 | I9: 1 | J9: 1 | K9: 1 | L9: 3 | M9: =SUM(E9:K9)/8 -> 0.5 | N9: =M9*6+IF(L9>0,4,0) -> 7
A10: Pacheco | B10: Daniela | C10: danipacheco@correo.unimet.edu.ve | D10: 1.075 | E10: 0 | F10: 0 | G10: 0 | H10: 0 | I10: 0 | J10: =J22 -> 1 | K10: =K22 -> 1 | L10: 3 | M10: =SUM(E10:K10)/8 -> 0.25 | N10: =M10*6+IF(L10>0,4,0) -> 5.5
A11: Arreaza | B11: Diego | C11: diego.arreaza@correo.unimet.edu.ve | D11: 0.975 | E11: 0 | F11: 0 | G11: 0 | H11: 0 | I11: 1 | J11: 1 | K11: 0 | L11: 2 | M11: =SUM(E11:K11)/8 -> 0.25 | N11: =M11*6+IF(L11>0,4,0) -> 5.5
A12: Baron | B12: Diego | C12: baronb@correo.unimet.edu.ve | D12: 1.075 | E12: 0 | F12: 0 | G12: 0 | H12: 0 | I12: 1 | J12: 0 | K12: 1 | L12: 3 | M12: =SUM(E12:K12)/8 -> 0.25 | N12: =M12*6+IF(L12>0,4,0) -> 5.5
A13: Callender | B13: Diego | C13: diego.callender@correo.unimet.edu.ve | D13: 0.7 | E13: 0 | F13: 0 | G13: 0 | H13: 0 | I13: 0 | J13: 0 | K13: 0 | L13: 3 | M13: =SUM(E13:K13)/8 -> 0 | N13: =M13*6+IF(L13>0,4,0) -> 4
A14: De Jesús | B14: Diego | C14: di.dejesus@correo.unimet.edu.ve | D14: 1.1625 | E14: 0 | F14: 0 | G14: 1 | H14: 0 | I14: 1 | J14: 1 | K14: 0 | L14: 2 | M14: =SUM(E14:K14)/8 -> 0.375 | N14: =M14*6+IF(L14>0,4,0) -> 6.25
A15: Casais | B15: Elohym | C15: casais.elohym@correo.unimet.edu.ve | D15: 0.7875 | E15: 0 | F15: 0 | G15: 0 | H15: 0 | I15: 0 | J15: 1 | K15: 0 | L15: 2 | M15: =SUM(E15:K15)/8 -> 0.125 | N15: =M15*6+IF(L15>0,4,0) -> 4.75
A16: Aray | B16: Flavia | C16: flavia.aray@correo.unimet.edu.ve | D16: 0.7 | E16: 0 | F16: 0 | G16: 0 | H16: 0 | I16: 0 | J16: 0 | K16: 0 | L16: 3 | M16: =SUM(E16:K16)/8 -> 0 | N16: =M16*6+IF(L16>0,4,0) -> 4
A17: Jimenez | B17: Gabriel | C17: gabriel.jimenez@correo.unimet.edu.ve | D17: 0.9875 | E17: 0 | F17: 0 | G17: 1 | H17: 0 | I17: 0 | J17: 0 | K17: 0 | L17: 4 | M17: =SUM(E17:K17)/8 -> 0.125 | N17: =M17*6+IF(L17>0,4,0) -> 4.75
A18: Viñas | B18: Gabriel | C18: gvinas@correo.unimet.edu.ve | D18: 0.7 | E18: 0 | F18: 0 | G18: 0 | H18: 0 | I18: 0 | J18: 0 | K18: 0 | L18: 3 | M18: =SUM(E18:K18)/8 -> 0 | N18: =M18*6+IF(L18>0,4,0) -> 4
