Workbook

Sheet ALGORITMOS
A1: Participaciones ALGORITMOS - Enero-Marzo 2026
A2: Cédula | B2: Nombres y Apellidos | C2: Sem 1 | D2: Sem 2 | E2: Sem 3 | F2: Sem 4 | G2: Sem 5 | H2: Sem 6 | I2: Sem 7 | J2: Sem 8 | K2: Sem 9 | L2: Sem 10 | M2: Sem 11 | N2: Sem 12 | O2: TOTAL | P2: %
A3: 32535007 | B3: Lorenzo Perez | F3: 4 | H3: 1 | O3: =SUM(ALGORITMOS!$C3:$N3) -> 5 | P3: =O3/10 -> 0.5
A4: 32753793 | B4: Armando Díaz | O4: =SUM(ALGORITMOS!$C4:$N4) -> 0 | P4: =O4/10 -> 0
A5: 32473285 | B5: Emmanuel Miquilave | K5: 1 | O5: =SUM(ALGORITMOS!$C5:$N5) -> 1 | P5: =O5/10 -> 0.1
A6: 32235603 | B6: Fabricio García | O6: =SUM(ALGORITMOS!$C6:$N6) -> 0 | P6: =O6/10 -> 0
A7: 32749893 | B7: Julian Andrés Pérez De Armas | C7: 1 | G7: 1 | O7: =SUM(ALGORITMOS!$C7:$N7) -> 2 | P7: =O7/10 -> 0.2
A8: 32227280 | B8: Jacobo Hernández | C8: 1 | K8: 1 | M8: 1 | O8: =SUM(ALGORITMOS!$C8:$N8) -> 3 | P8: =O8/10 -> 0.3
A9: 31821320 | B9: Daniel Denis | C9: 1 | E9: 2 | F9: 3 | G9: 1 | H9: 3 | O9: =SUM(ALGORITMOS!$C9:$N9) -> 10 | P9: =O9/10 -> 1
A10: 36064964 | B10: Ariana Stolk | C10: 1 | O10: =SUM(ALGORITMOS!$C10:$N10) -> 1 | P10: =O10/10 -> 0.1
A11: 32357635 | B11: Manuel Sanabria | O11: =SUM(ALGORITMOS!$C11:$N11) -> 0 | P11: =O11/10 -> 0
A12: 30538964 | B12: Eduardo López | F12: 1 | M12: 1 | O12: =SUM(ALGORITMOS!$C12:$N12) -> 2 | P12: =O12/10 -> 0.2
A13: 32348335 | B13: Ana S. Martínez S | C13: 1 | O13: =SUM(ALGORITMOS!$C13:$N13) -> 1 | P13: =O13/10 -> 0.1
A14: 32122169 | B14: Samuel Herrera | O14: =SUM(ALGORITMOS!$C14:$N14) -> 0 | P14: =O14/10 -> 0
A15: 32013622 | B15: Alessandro Gimenez | C15: 1 | O15: =SUM(ALGORITMOS!$C15:$N15) -> 1 | P15: =O15/10 -> 0.1
A16: 30497178 | B16: David López | C16: 1 | O16: =SUM(ALGORITMOS!$C16:$N16) -> 1 | P16: =O16/10 -> 0.1
A17: 32337077 | B17: Francesco Antolino | O17: =SUM(ALGORITMOS!$C17:$N17) -> 0 | P17: =O17/10 -> 0
A18: 32348512 | B18: Pedro Trigo | C18: 1 | K18: 1 | O18: =SUM(ALGORITMOS!$C18:$N18) -> 2 | P18: =O18/10 -> 0.2
A19: 32226530 | B19: Hans Senior | C19: 1 | E19: 3 | O19: =SUM(ALGORITMOS!$C19:$N19) -> 4 | P19: =O19/10 -> 0.4
A20: 31873764 | B20: Juan Mata | E20: 1 | F20: 4 | O20: =SUM(ALGORITMOS!$C20:$N20) -> 5 | P20: =O20/10 -> 0.5
A21: 32396833 | B21: Sebastian Yrady | M21: 1 | O21: =SUM(ALGORITMOS!$C21:$N21) -> 1 | P21: =O21/10 -> 0.1
A22: 32292306 | B22: Santiago Ramos | F22: 1 | M22: 1 | O22: =SUM(ALGORITMOS!$C22:$N22) -> 2 | P22: =O22/10 -> 0.2
A23: 31873213 | B23: Santiago Macia | O23: =SUM(ALGORITMOS!$C23:$N23) -> 0 | P23: =O23/10 -> 0
A24: 32520003 | B24: Manuel Rodriguez | C24: 2 | O24: =SUM(ALGORITMOS!$C24:$N24) -> 2 | P24: =O24/10 -> 0.2
A25: 34002480 | B25: José León | O25: =SUM(ALGORITMOS!$C25:$N25) -> 0 | P25: =O25/10 -> 0
A26: 32122247 | B26: Jesús Díaz | E26: 1 | O26: =SUM(ALGORITMOS!$C26:$N26) -> 1 | P26: =O26/10 -> 0.1
A27: 32857188 | B27: Manuel Díaz | C27: 1 | E27: 3 | K27: 1 | O27: =SUM(ALGORITMOS!$C27:$N27) -> 5 | P27: =O27/10 -> 0.5
A28: 32624143 | B28: Carlos Bastidas | C28: 1 | E28: 2 | K28: 1 | O28: =SUM(ALGORITMOS!$C28:$N28) -> 4 | P28: =O28/10 -> 0.4
A29: 32504495 | B29: Lowin Mariño | C29: 1 | E29: 3 | K29: 1 | O29: =SUM(ALGORITMOS!$C29:$N29) -> 5 | P29: =O29/10 -> 0.5
A30: 32538098 | B30: Roger Capozzolo | O30: =SUM(ALGORITMOS!$C30:$N30) -> 0 | P30: =O30/10 -> 0
A31: 32110956 | B31: Ignacio Gotz | O31: =SUM(ALGORITMOS!$C31:$N31) -> 0 | P31: =O31/10 -> 0
A32: 30774515 | B32: Fabian Lucci | O32: =SUM(ALGORITMOS!$C32:$N32) -> 0 | P32: =O32/10 -> 0

Sheet ESTRUCTURAS-DE DATOS
A1: Participaciones ESTRUCTURAS DE DATOS - Enero-Marzo 2026
A2: Cédula de Identidad | B2: Nombres y Apellidos | C2: Sem 1 | D2: Sem 2 | E2: Sem 3 | F2: Sem 4 | G2: Sem 5 | H2: Sem 6 | I2: Sem 7 | J2: Sem 8 | K2: Sem 9 | L2: Sem 10 | M2: Sem 11 | N2: Sem 12 | O2: TOTAL | P2: %
A3: 28410856 | B3: Sebastian Alfonzo | D3: 2 | E3: 1 | O3: =SUM('ESTRUCTURAS-DE DATOS'!$C3:$N3) -> 3 | P3: =O3/17 -> 0.17647059
A4: 30911705 | B4: Daniel Angulo | C4: 2 | E4: 1 | G4: 2 | H4: 2 | N4: 2 | O4: =SUM('ESTRUCTURAS-DE DATOS'!$C4:$N4) -> 9 | P4: =O4/17 -> 0.52941176
A5: 30394726 | B5: Valentina Cabrera | C5: 8 | D5: 4 | E5: 5 | F5: 1 | G5: 8 | I5: 1 | J5: 4 | L5: 4 | N5: 1 | O5: =SUM('ESTRUCTURAS-DE DATOS'!$C5:$N5) -> 36 | P5: =O5/17 -> 2.1176471
A6: 32333927 | B6: Juan Pablo Rojas | C6: 1 | D6: 2 | E6: 1 | G6: 2 | H6: 2 | K6: 1 | L6: 3 | N6: 2 | O6: =SUM('ESTRUCTURAS-DE DATOS'!$C6:$N6) -> 14 | P6: =O6/17 -> 0.82352941
A7: 31464995 | B7: Giancarlo Paolino | O7: =SUM('ESTRUCTURAS-DE DATOS'!$C7:$N7) -> 0 | P7: =O7/17 -> 0
A8: 31042821 | B8: Sebastian Velasquez | H8: 2 | K8: 1 | L8: 5 | O8: =SUM('ESTRUCTURAS-DE DATOS'!$C8:$N8) -> 8 | P8: =O8/17 -> 0.47058824
A9: 29724329 | B9: Gabriel Cedeño | H9: 4 | O9: =SUM('ESTRUCTURAS-DE DATOS'!$C9:$N9) -> 4 | P9: =O9/17 -> 0.23529412
A10: 31785756 | B10: Carlos Padrón | O10: =SUM('ESTRUCTURAS-DE DATOS'!$C10:$N10) -> 0 | P10: =O10/17 -> 0
A11: 31985434 | B11: Antonio Barriola | O11: =SUM('ESTRUCTURAS-DE DATOS'!$C11:$N11) -> 0 | P11: =O11/17 -> 0
A12: 31758845 | B12: Adrian Martinez | K12: 1 | L12: 4 | N12: 2 | O12: =SUM('ESTRUCTURAS-DE DATOS'!$C12:$N12) -> 7 | P12: =O12/17 -> 0.41176471
A13: 31377369 | B13: Gianfranco Camporeale | G13: 1 | L13: 2 | O13: =SUM('ESTRUCTURAS-DE DATOS'!$C13:$N13) -> 3 | P13: =O13/17 -> 0.17647059
A14: 32377039 | B14: Ugarte Alirio | D14: 2 | E14: 1 | O14: =SUM('ESTRUCTURAS-DE DATOS'!$C14:$N14) -> 3 | P14: =O14/17 -> 0.17647059
A15: 32124905 | B15: Jose Quintero | O15: =SUM('ESTRUCTURAS-DE DATOS'!$C15:$N15) -> 0 | P15: =O15/17 -> 0
A16: 24843496 | B16: David Mayora | O16: =SUM('ESTRUCTURAS-DE DATOS'!$C16:$N16) -> 0 | P16: =O16/17 -> 0
A17: 30538925 | B17: Juan Blanco | D17: 1 | E17: 1 | L17: 4 | O17: =SUM('ESTRUCTURAS-DE DATOS'!$C17:$N17) -> 6 | P17: =O17/17 -> 0.35294118
A18: 31707262 | B18: Samuel Vergel | O18: =SUM('ESTRUCTURAS-DE DATOS'!$C18:$N18) -> 0 | P18: =O18/17 -> 0
A19: 31307971 | B19: Andrés Fung | O19: =SUM('ESTRUCTURAS-DE DATOS'!$C19:$N19) -> 0 | P19: =O19/17 -> 0
A20: 31707260 | B20: Oscar Ezeiza | K20: 1 | O20: =SUM('ESTRUCTURAS-DE DATOS'!$C20:$N20) -> 1 | P20: =O20/17 -> 0.058823529

Sheet COMPURACION EMERGENTE
B1: Participaciones Computacion Emergente - Enero-Marzo 2026
A2: Cédula | B2: Apellidos | C2: Sem 1 | D2: Sem 2 | E2: Sem 3 | F2: Sem 4 | G2: Sem 5 | H2: Sem 6 | I2: Sem 7 | J2: Sem 8 | K2: Sem 9 | L2: Sem 10 | M2: Sem 11 | N2: Sem 12 | O2: TOTAL | P2: percent | Q2: 0.05
A3: 31068474 | B3: SASantiago David Aristimuño Yaguaramay | D3: 1 | O3: =SUM('COMPURACION EMERGENTE'!$C3:$N3) -> 1 | P3: =O3/15 -> 0.066666667 | Q3: =P3*5 -> 0.33333333
A4: 29510447 | B4: Albany Veronica Avila Blanco | O4: =SUM('COMPURACION EMERGENTE'!$C4:$N4) -> 0 | P4: =O4/15 -> 0 | Q4: =P4*5 -> 0
A5: 25947729 | B5: JBJhorman Bloom | O5: =SUM('COMPURACION EMERGENTE'!$C5:$N5) -> 0 | P5: =O5/15 -> 0 | Q5: =P5*5 -> 0
A6: 27849723 | B6: Andrés Alonso Camacho López | E6: 1 | F6: 2 | H6: 1 | J6: 1 | K6: 1 | O6: =SUM('COMPURACION EMERGENTE'!$C6:$N6) -> 6 | P6: =O6/15 -> 0.4 | Q6: =P6*5 -> 2
A7: 30057442 | B7: Beatriz Elena Cardozo López | O7: =SUM('COMPURACION EMERGENTE'!$C7:$N7) -> 0 | P7: =O7/15 -> 0 | Q7: =P7*5 -> 0
A8: 28021957 | B8: CCCarlo Carpentieri Perez | O8: =SUM('COMPURACION EMERGENTE'!$C8:$N8) -> 0 | P8: =O8/15 -> 0 | Q8: =P8*5 -> 0
A9: 29508689 | B9: Ramón Carrasquel | D9: 1 | E9: 2 | F9: 2 | H9: 1 | J9: 1 | K9: 1 | L9: 1 | M9: 1 | O9: =SUM('COMPURACION EMERGENTE'!$C9:$N9) -> 10 | P9: =O9/15 -> 0.66666667 | Q9: =P9*5 -> 3.3333333
A10: 30496325 | B10: LCLuis Carreño | D10: 1 | E10: 1 | O10: =SUM('COMPURACION EMERGENTE'!$C10:$N10) -> 2 | P10: =O10/15 -> 0.13333333 | Q10: =P10*5 -> 0.66666667
A11: 30358773 | B11: Nicola Colarusso | D11: 2 | E11: 2 | F11: 2 | H11: 1 | J11: 1 | K11: 1 | O11: =SUM('COMPURACION EMERGENTE'!$C11:$N11) -> 9 | P11: =O11/15 -> 0.6 | Q11: =P11*5 -> 3
A12: 29741760 | B12: Diego De Jesús | O12: =SUM('COMPURACION EMERGENTE'!$C12:$N12) -> 0 | P12: =O12/15 -> 0 | Q12: =P12*5 -> 0
A13: 29983279 | B13: JDJuan Diaz | O13: =SUM('COMPURACION EMERGENTE'!$C13:$N13) -> 0 | P13: =O13/15 -> 0 | Q13: =P13*5 -> 0
A14: 30497244 | B14: AEAsier Errasti | O14: =SUM('COMPURACION EMERGENTE'!$C14:$N14) -> 0 | P14: =O14/15 -> 0 | Q14: =P14*5 -> 0
A15: 30030632 | B15: Gabriel Jesus Flores Baez | O15: =SUM('COMPURACION EMERGENTE'!$C15:$N15) -> 0 | P15: =O15/15 -> 0 | Q15: =P15*5 -> 0
A16: 30579903 | B16: Jose Ignacio Francisco alvarez | D16: 1 | E16: 1 | G16: 1 | K16: 1 | O16: =SUM('COMPURACION EMERGENTE'!$C16:$N16) -> 4 | P16: =O16/15 -> 0.26666667 | Q16: =P16*5 -> 1.3333333
A17: 31065516 | B17: JGJoel Eduardo Gascón Pulido | H17: 1 | O17: =SUM('COMPURACION EMERGENTE'!$C17:$N17) -> 1 | P17: =O17/15 -> 0.066666667 | Q17: =P17*5 -> 0.33333333
A18: 28127331 | B18: Tomas Enrique Gonzalez Adrian | O18: =SUM('COMPURACION EMERGENTE'!$C18:$N18) -> 0 | P18: =O18/15 -> 0 | Q18: =P18*5 -> 0
A19: 30157257 | B19: Karelin Guzman | C19: 1 | E19: 1 | F19: 2 | K19: 1 | O19: =SUM('COMPURACION EMERGENTE'!$C19:$N19) -> 5 | P19: =O19/15 -> 0.33333333 | Q19: =P19*5 -> 1.6666667
A20: 25736710 | B20: Kevin Hernandez | D20: 1 | O20: =SUM('COMPURACION EMERGENTE'!$C20:$N20) -> 1 | P20: =O20/15 -> 0.066666667 | Q20: =P20*5 -> 0.33333333
A21: 29506315 | B21: Alejo Hernandez | O21: =SUM('COMPURACION EMERGENTE'!$C21:$N21) -> 0 | P21: =O21/15 -> 0 | Q21: =P21*5 -> 0
A22: 29662587 | B22: VKVictoria Knuth | O22: =SUM('COMPURACION EMERGENTE'!$C22:$N22) -> 0 | P22: =O22/15 -> 0 | Q22: =P22*5 -> 0
A23: 28462135 | B23: Verónica Luna | O23: =SUM('COMPURACION EMERGENTE'!$C23:$N23) -> 0 | P23: =O23/15 -> 0 | Q23: =P23*5 -> 0
A24: 26895167 | B24: Rodolfo Marin | E24: 1 | O24: =SUM('COMPURACION EMERGENTE'!$C24:$N24) -> 1 | P24: =O24/15 -> 0.066666667 | Q24: =P24*5 -> 0.33333333
A25: 30727488 | B25: VMVictor Martinez | C25: 1 | O25: =SUM('COMPURACION EMERGENTE'!$C25:$N25) -> 1 | P25: =O25/15 -> 0.066666667 | Q25: =P25*5 -> 0.33333333
A26: 30821945 | B26: DMDavid Alejandro Mavares Delgado | O26: =SUM('COMPURACION EMERGENTE'!$C26:$N26) -> 0 | P26: =O26/15 -> 0 | Q26: =P26*5 -> 0
A27: 30330786 | B27: RMRicardo Mazziotta | O27: =SUM('COMPURACION EMERGENTE'!$C27:$N27) -> 0 | P27: =O27/15 -> 0 | Q27: =P27*5 -> 0
A28: 29850491 | B28: Mauricio Méndez | D28: 1 | O28: =SUM('COMPURACION EMERGENTE'!$C28:$N28) -> 1 | P28: =O28/15 -> 0.066666667 | Q28: =P28*5 -> 0.33333333
A29: 30751145 | B29: Annabella Mendoza | O29: =SUM('COMPURACION EMERGENTE'!$C29:$N29) -> 0 | P29: =O29/15 -> 0 | Q29: =P29*5 -> 0
A30: 30612944 | B30: Andrés Alejandro Moreno Lombardo | O30: =SUM('COMPURACION EMERGENTE'!$C30:$N30) -> 0 | P30: =O30/15 -> 0 | Q30: =P30*5 -> 0
B31: Elvira Esther Navas Piñate | O31: =SUM('COMPURACION EMERGENTE'!$C31:$N31) -> 0 | P31: =O31/15 -> 0 | Q31: =P31*5 -> 0
A32: 29677861 | B32: Juan Diego Nunes Peraza | O32: =SUM('COMPURACION EMERGENTE'!$C32:$N32) -> 0 | P32: =O32/15 -> 0 | Q32: =P32*5 -> 0
A33: 29661990 | B33: Gabriel Rafael Oba Aye Orozco Rodriguez | O33: =SUM('COMPURACION EMERGENTE'!$C33:$N33) -> 0 | P33: =O33/15 -> 0 | Q33: =P33*5 -> 0
A34: 27472721 | B34: Adrián Eduardo Pinzón Vásquez | O34: =SUM('COMPURACION EMERGENTE'!$C34:$N34) -> 0 | P34: =O34/15 -> 0 | Q34: =P34*5 -> 0
A35: 29887224 | B35: Jonathan Pizzurro Fortun | O35: =SUM('COMPURACION EMERGENTE'!$C35:$N35) -> 0 | P35: =O35/15 -> 0 | Q35: =P35*5 -> 0
A36: 28317519 | B36: CRChristian Ramos | O36: =SUM('COMPURACION EMERGENTE'!$C36:$N36) -> 0 | P36: =O36/15 -> 0 | Q36: =P36*5 -> 0
A37: 30496487 | B37: GRGonzalo Andrés Ramos De Sa Pinto | C37: 1 | E37: 1 | O37: =SUM('COMPURACION EMERGENTE'!$C37:$N37) -> 2 | P37: =O37/15 -> 0.13333333 | Q37: =P37*5 -> 0.66666667
A38: 30411279 | B38: ARAndrea Veronica Reyes Mejia | C38: 1 | D38: 1 | E38: 1 | O38: =SUM('COMPURACION EMERGENTE'!$C38:$N38) -> 3 | P38: =O38/15 -> 0.2 | Q38: =P38*5 -> 1
A39: 26783022 | B39: IRIsabella Rondón | D39: 1 | O39: =SUM('COMPURACION EMERGENTE'!$C39:$N39) -> 1 | P39: =O39/15 -> 0.066666667 | Q39: =P39*5 -> 0.33333333
A40: 31460153 | B40: MRMaria Antonella Ruiz Cianci | O40: =SUM('COMPURACION EMERGENTE'!$C40:$N40) -> 0 | P40: =O40/15 -> 0 | Q40: =P40*5 -> 0
...

Sheet RESULTADOS MARATONES PROGRAMACI
A1: Resultados Maratones de Programacion
D2: ENTRENAMIENTOS | F2: MARATONES
A3: Personas | B3: Cédula | C3: Asignatura | D3: Asistencias | E3: Prom Ej x sem | F3: Equipo | G3: RPC01 | H3: RPC02 | I3: Kattis | J3: % Participacion
A4: Daniel Angulo | B4: 30911705 | C4: ESTRUCTURAS | D4: 7 | E4: 1,29 | J4: 60,32%
A5: Gianfranco Camporeale | B5: 31377369 | C5: ESTRUCTURAS | D5: 5 | E5: 1,00 | H5: 1,00 | J5: 44,44%
