Workbook

Sheet Lista
A1: Profesor(a): | B1: Torre | C1: Fernando Javier
A2: C.I.: | B2: 21132576
A3: Asignatura: | B3: BPTSP05 | C3: ALGORITMOS Y PROGRAMACION
A4: Periodo: | B4: 2425 | C4: 008
A5: Sección: | B5: BPTSP05-2
A7: ID | B7: CEDULA | C7: CARNET | D7: APELLIDO | E7: NOMBRE | F7: Segundo Nom | G7: Correo Unimet | H7: EMAIL_PRINC | I7: EMAIL_ADIC | J7: RQ_RT
A8: 1 | B8: 28410856 | C8: 20241120090 | D8: Alfonzo | E8: Sebastian | F8: Eduardo | G8: sebastian.alfonzo@correo.unimet.edu.ve. | H8: ccsebastianalfonzo@gmail.com | I8: sandratiburcio19@gmail.com
A9: 2 | B9: 30849611 | C9: 20251110312 | D9: Amelinckx | E9: Matthias | G9: matthias.amelinckx@correo.unimet.edu.ve. | H9: amelinckxmatthias@gmail.com | I9: aamelinckx@gmail.com
A10: 3 | B10: 29666935 | C10: 20221110318 | D10: Aray | E10: Flavia | F10: Isabel | G10: flavia.aray@correo.unimet.edu.ve. | H10: farayvdb@gmail.com | I10: ursulaaray@hotmail.com
A11: 4 | B11: 30765878 | C11: 20241120058 | D11: Blanco | E11: Angélica | G11: angelica.blanco@correo.unimet.edu.ve. | H11: ariangelibf2@gmail.com | I11: viviblanco1313@gmail.com
A12: 5 | B12: 32729082 | C12: 20251110441 | D12: Brusco | E12: Gabriel | F12: Alejandro | G12: gabriel.brusco@correo.unimet.edu.ve. | H12: gabrielbrusco80@gmail.com | I12: gabrielbrusco80@gmail.com
A13: 6 | B13: 31071592 | C13: 20231110091 | D13: Callender | E13: Diego | F13: Alejandro | G13: diego.callender@correo.unimet.edu.ve. | H13: diego.callender@correo.unimet.edu.ve | I13: leoncallend@hotmail.com
A14: 7 | B14: 32491310 | C14: 20251110101 | D14: Casais | E14: Elohym | F14: Joham | G14: casais.elohym@correo.unimet.edu.ve. | H14: Casais.elohym@correo.unimet.edu.ve
A15: 8 | B15: 31988236 | C15: 20231110809 | D15: Fiandaca | E15: Santiago | F15: De Jesús | G15: sfiandaca@correo.unimet.edu.ve. | H15: santiagofiandaca@gmail.com | I15: juanfiandaca@hotmail.com
A16: 9 | B16: 31112818 | C16: 20241110300 | D16: Haiek | E16: Paola | F16: Marie | G16: paola.haiek@correo.unimet.edu.ve. | H16: paolahaiek@gmail.com | I16: mariadlpereira@hotmail.com
A17: 10 | B17: 30030485 | C17: 20211110277 | D17: Hernandez | E17: Andrea | G17: h.andrea@correo.unimet.edu.ve. | H17: h.andrea@correo.unimet.edu.ve | I17: adalbertouno@gmail.com
A18: 11 | B18: 30793086 | C18: 20241110385 | D18: Idrobo | E18: Jose | F18: Daniel | G18: idrobo.jose@correo.unimet.edu.ve. | H18: idrobojose3@gmail.com
A19: 12 | B19: 32242412 | C19: 20241130210 | D19: Kchour | E19: Mohamad | F19: Ali | G19: mohamad.kchour@correo.unimet.edu.ve. | H19: mohamd.kchour@correo.unimet.edu.ve | I19: alikmhf@gmail.com
A20: 13 | B20: 30598031 | C20: 20241110180 | D20: Livinaly | E20: Paola | F20: Graciela | G20: plivinaly@correo.unimet.edu.ve. | H20: paolalivinaly@gmail.com | I20: cheladelivinaly@gmail.com
A21: 14 | B21: 31852058 | C21: 20241110606 | D21: Medina | E21: Laura | F21: Maria | G21: laura.medina@correo.unimet.edu.ve. | H21: laura.medina@correo.unimet.edu.ve
A22: 15 | B22: 30114012 | C22: 20221110622 | D22: Mercado | E22: Flavia | G22: flavia.mercado@correo.unimet.edu.ve. | H22: flaviamc2000@gmail.com | I22: ccalabre2000@hotmail.com
A23: 16 | B23: 26954417 | C23: 20241130010 | D23: Moya | E23: Angel | F23: Jose | G23: angel.moya@correo.unimet.edu.ve. | H23: angel.moya@correo.unimet.edu.ve | I23: anjomova21@gmail.com
A24: 17 | B24: 31448943 | C24: 20251110270 | D24: Pamphile | E24: Samuel | F24: Abraham | G24: samuel.pamphile@correo.unimet.edu.ve. | H24: samuel.pamphile@correo.unimet.edu.ve | I24: crisapul@gmail.com
A25: 18 | B25: 31423000 | C25: 20241110369 | D25: Pizza | E25: Emmanuel | F25: Giuseppe | G25: pizzap@correo.unimet.edu.ve. | H25: pizzap@correo.unimet.edu.ve | I25: DBANTO@HOTMAIL.COM
A26: 19 | B26: 31046285 | C26: 20241110648 | D26: Rodriguez | E26: Rafael | G26: rodriguez.rafael@correo.unimet.edu.ve. | H26: kikerodriguezm11@gmail.com | I26: crismarmrodriguez@gmail.com
A27: 20 | B27: 31255343 | C27: 20241110234 | D27: Rojas | E27: Luciano | F27: Nicola | G27: luciano.rojas@correo.unimet.edu.ve. | H27: rojasmarquinaluciano4@gmail.com | I27: jhannymarquina@gmail.com
A28: 21 | B28: 32401366 | C28: 20241130155 | D28: Ruiz | E28: José | F28: Alejandro | G28: joseruiz@correo.unimet.edu.ve. | H28: goyitojosearuiz06@gmail.com | I28: rossy_reina@hotmail.com
A29: 22 | B29: 32121917 | C29: 20251110018 | D29: Salimbeni | E29: César | F29: Alexander | G29: cesar.salimbeni@correo.unimet.edu.ve. | H29: cesar.salimbeni@correo.unimet.edu.ve
A30: 23 | B30: 33921124 | C30: 20251110253 | D30: Sanchez | E30: David | F30: Eduardo | G30: d.sanchez@correo.unimet.edu.ve. | H30: desa0517@gmail.com | I30: deboraachang@gmail.com
A31: 24 | B31: 31703910 | C31: 20251110347 | D31: Saracual | E31: Daniel | F31: Antonio | G31: daniel.saracual@correo.unimet.edu.ve. | H31: daniel.saracual@correo.unimet.edu.ve | I31: rsaracual@gmail.com
A32: 25 | B32: 32122110 | C32: 20251110023 | D32: Silva | E32: Elva | F32: María | G32: elva.silva@correo.unimet.edu.ve. | H32: emsr16112007@gmail.com | I32: peterjsilvaf@gmail.com
A33: 26 | B33: 30720123 | C33: 20241110560 | D33: Steinmetz | E33: Erik | G33: s.erik@correo.unimet.edu.ve. | H33: eriksteinmetz2005@gmail.com | I33: alansteinmetz7@gmail.com
A34: 27 | B34: 29895575 | C34: 20211120039 | D34: Trezza | E34: Sofia | F34: Gisela | G34: sofia.trezza@correo.unimet.edu.ve. | H34: sofia.trezza@correo.unimet.edu.ve | I34: emiliotrezzaa@gmail.com
A35: 28 | B35: 31615220 | C35: 20241110006 | D35: Ugarte Pelayo | E35: Nicole | F35: Alejandra | G35: nicole.ugartepelayo@correo.unimet.edu.ve. | H35: nicoleugartelahoud1@gmail.com | I35: Alirio2002@yahoo.com
A36: 29 | B36: 30022208 | C36: 20211110643 | D36: Viñas | E36: Gabriel | F36: Alejandro | G36: gvinas@correo.unimet.edu.ve. | H36: gvinas@correo.unimet.edu.ve | I36: cvinasgl16@gmail.com
A37: 30 | B37: 31963201 | C37: 20241110508 | D37: Zerpa | E37: Azael | F37: Alonso | G37: azael.zerpa@correo.unimet.edu.ve. | H37: azael.zerpa@correo.unimet.edu.ve | I37: joaisasalaz@gmail.com

Sheet Acum
A1: CEDULA | B1: APELLIDO | C1: NOMBRE | D1: Correo Unimet | E1: Estatus | F1: Eval Cont | G1: Quiz 1 | H1: Parcial 1 | I1: Quiz 2 | J1: Proyecto | K1: Parcial 2 | L1: XTRA | M1: Total | N1: Escala 20 | O1: Partic | P1: Tareas | Q1: Def
A2: 28410856 | B2: Alfonzo | C2: Sebastian | D2: sebastian.alfonzo@correo.unimet.edu.ve. | F2: =VLOOKUP(LEFT(D2,LEN(D2)-1),'Eval. Cont.'!$A$2:$Q$31,17,FALSE) -> 6.5592857 | G2: ='Quiz 1'!G3/2 -> 0 | H2: =_xludf.ifna(VLOOKUP(VALUE(A2),'Parcial 1'!$A$2:$H$28,8,FALSE),"") -> #NAME? | I2: =IF('Quiz 2'!K3<>"",'Quiz 2'!K3/2,"") | J2: =_xludf.ifna(VLOOKUP(VALUE(A2),Proyecto!$A$3:$AA$23,27,FALSE),"") -> #NAME? | K2: =_xludf.ifna(VLOOKUP(VALUE(A2),'Parcial 2'!$A$2:$G$21,7,FALSE),"") -> #NAME? | L2: =_xludf.ifna(VLOOKUP(LEFT(D2,LEN(D2)-1),Xtra!$C$6:$N$53,12,FALSE),"") -> #NAME? | M2: =SUM(F2:L2) -> #NAME? | N2: =M2/5 -> #NAME? | O2: =Partic!S2/(COUNTA(Partic!D$1:S$1)-1) -> 0.066666667 | P2: =VLOOKUP(LEFT(D2,LEN(D2)-1),Tareas!$A$2:$Q$31,17,FALSE) -> 0.21428571 | Q2: =IF(E2="Retirado","R",N2+MAX(O2:P2)) -> #NAME?
A3: 30849611 | B3: Amelinckx | C3: Matthias | D3: matthias.amelinckx@correo.unimet.edu.ve. | F3: =VLOOKUP(LEFT(D3,LEN(D3)-1),'Eval. Cont.'!$A$2:$Q$31,17,FALSE) -> 12.237857 | G3: ='Quiz 1'!G4/2 -> 0.625 | H3: =_xludf.ifna(VLOOKUP(VALUE(A3),'Parcial 1'!$A$2:$H$28,8,FALSE),"") -> #NAME? | I3: =IF('Quiz 2'!K4<>"",'Quiz 2'!K4/2,"") | J3: =_xludf.ifna(VLOOKUP(VALUE(A3),Proyecto!$A$3:$AA$23,27,FALSE),"") -> #NAME? | K3: =_xludf.ifna(VLOOKUP(VALUE(A3),'Parcial 2'!$A$2:$G$21,7,FALSE),"") -> #NAME? | L3: =_xludf.ifna(VLOOKUP(LEFT(D3,LEN(D3)-1),Xtra!$C$6:$N$53,12,FALSE),"") -> #NAME? | M3: =SUM(F3:L3) -> #NAME? | N3: =M3/5 -> #NAME? | O3: =Partic!S3/(COUNTA(Partic!D$1:S$1)-1) -> 0.2 | P3: =VLOOKUP(LEFT(D3,LEN(D3)-1),Tareas!$A$2:$Q$31,17,FALSE) -> 0.28571429 | Q3: =IF(E3="Retirado","R",N3+MAX(O3:P3)) -> #NAME?
A4: 29666935 | B4: Aray | C4: Flavia | D4: flavia.aray@correo.unimet.edu.ve. | F4: =VLOOKUP(LEFT(D4,LEN(D4)-1),'Eval. Cont.'!$A$2:$Q$31,17,FALSE) -> 17.428571 | G4: ='Quiz 1'!G5/2 -> 2 | H4: =_xludf.ifna(VLOOKUP(VALUE(A4),'Parcial 1'!$A$2:$H$28,8,FALSE),"") -> #NAME? | I4: =IF('Quiz 2'!K5<>"",'Quiz 2'!K5/2,"") -> 3.125 | J4: =_xludf.ifna(VLOOKUP(VALUE(A4),Proyecto!$A$3:$AA$23,27,FALSE),"") -> #NAME? | K4: =_xludf.ifna(VLOOKUP(VALUE(A4),'Parcial 2'!$A$2:$G$21,7,FALSE),"") -> #NAME? | L4: =_xludf.ifna(VLOOKUP(LEFT(D4,LEN(D4)-1),Xtra!$C$6:$N$53,12,FALSE),"") -> #NAME? | M4: =SUM(F4:L4) -> #NAME? | N4: =M4/5 -> #NAME? | O4: =Partic!S4/(COUNTA(Partic!D$1:S$1)-1) -> 1.3333333 | P4: =VLOOKUP(LEFT(D4,LEN(D4)-1),Tareas!$A$2:$Q$31,17,FALSE) -> 0.21428571 | Q4: =IF(E4="Retirado","R",N4+MAX(O4:P4)) -> #NAME?
A5: 30765878 | B5: Blanco | C5: Angélica | D5: angelica.blanco@correo.unimet.edu.ve. | E5: Retirado | F5: =VLOOKUP(LEFT(D5,LEN(D5)-1),'Eval. Cont.'!$A$2:$Q$31,17,FALSE) -> 13.821429 | G5: ='Quiz 1'!G6/2 -> 0 | H5: =_xludf.ifna(VLOOKUP(VALUE(A5),'Parcial 1'!$A$2:$H$28,8,FALSE),"") -> #NAME? | I5: =IF('Quiz 2'!K6<>"",'Quiz 2'!K6/2,"") | J5: =_xludf.ifna(VLOOKUP(VALUE(A5),Proyecto!$A$3:$AA$23,27,FALSE),"") -> #NAME? | K5: =_xludf.ifna(VLOOKUP(VALUE(A5),'Parcial 2'!$A$2:$G$21,7,FALSE),"") -> #NAME? | L5: =_xludf.ifna(VLOOKUP(LEFT(D5,LEN(D5)-1),Xtra!$C$6:$N$53,12,FALSE),"") -> #NAME? | M5: =SUM(F5:L5) -> #NAME? | N5: =M5/5 -> #NAME? | O5: =Partic!S5/(COUNTA(Partic!D$1:S$1)-1) -> 0.26666667 | P5: =VLOOKUP(LEFT(D5,LEN(D5)-1),Tareas!$A$2:$Q$31,17,FALSE) -> 0.35714286 | Q5: =IF(E5="Retirado","R",N5+MAX(O5:P5)) -> R
A6: 32729082 | B6: Brusco | C6: Gabriel | D6: gabriel.brusco@correo.unimet.edu.ve. | F6: =VLOOKUP(LEFT(D6,LEN(D6)-1),'Eval. Cont.'!$A$2:$Q$31,17,FALSE) -> 12.237857 | G6: ='Quiz 1'!G7/2 -> 0 | H6: =_xludf.ifna(VLOOKUP(VALUE(A6),'Parcial 1'!$A$2:$H$28,8,FALSE),"") -> #NAME? | I6: =IF('Quiz 2'!K7<>"",'Quiz 2'!K7/2,"") -> 7 | J6: 0 | K6: =_xludf.ifna(VLOOKUP(VALUE(A6),'Parcial 2'!$A$2:$G$21,7,FALSE),"") -> #NAME? | L6: =_xludf.ifna(VLOOKUP(LEFT(D6,LEN(D6)-1),Xtra!$C$6:$N$53,12,FALSE),"") -> #NAME? | M6: 0 | N6: =M6/5 -> 0 | O6: =Partic!S6/(COUNTA(Partic!D$1:S$1)-1) -> 0.13333333 | P6: =VLOOKUP(LEFT(D6,LEN(D6)-1),Tareas!$A$2:$Q$31,17,FALSE) -> 0.071428571 | Q6: =IF(E6="Retirado","R",N6+MAX(O6:P6)) -> 0.13333333
A7: 31071592 | B7: Callender | C7: Diego | D7: diego.callender@correo.unimet.edu.ve. | F7: =VLOOKUP(LEFT(D7,LEN(D7)-1),'Eval. Cont.'!$A$2:$Q$31,17,FALSE) -> 14.737857 | G7: ='Quiz 1'!G8/2 -> 5.25 | H7: =_xludf.ifna(VLOOKUP(VALUE(A7),'Parcial 1'!$A$2:$H$28,8,FALSE),"") -> #NAME? | I7: =IF('Quiz 2'!K8<>"",'Quiz 2'!K8/2,"") -> 4 | J7: 0 | K7: =_xludf.ifna(VLOOKUP(VALUE(A7),'Parcial 2'!$A$2:$G$21,7,FALSE),"") -> #NAME? | L7: =_xludf.ifna(VLOOKUP(LEFT(D7,LEN(D7)-1),Xtra!$C$6:$N$53,12,FALSE),"") -> #NAME? | M7: =SUM(F7:L7) -> #NAME? | N7: =M7/5 -> #NAME? | O7: =Partic!S7/(COUNTA(Partic!D$1:S$1)-1) -> 0.53333333 | P7: =VLOOKUP(LEFT(D7,LEN(D7)-1),Tareas!$A$2:$Q$31,17,FALSE) -> 0.28571429 | Q7: =IF(E7="Retirado","R",N7+MAX(O7:P7)) -> #NAME?
A8: 32491310 | B8: Casais | C8: Elohym | D8: casais.elohym@correo.unimet.edu.ve. | F8: =VLOOKUP(LEFT(D8,LEN(D8)-1),'Eval. Cont.'!$A$2:$Q$31,17,FALSE) -> 11.5 | G8: ='Quiz 1'!G9/2 -> 0 | H8: =_xludf.ifna(VLOOKUP(VALUE(A8),'Parcial 1'!$A$2:$H$28,8,FALSE),"") -> #NAME? | I8: =IF('Quiz 2'!K9<>"",'Quiz 2'!K9/2,"") -> 4 | J8: =_xludf.ifna(VLOOKUP(VALUE(A8),Proyecto!$A$3:$AA$23,27,FALSE),"") -> #NAME? | K8: =_xludf.ifna(VLOOKUP(VALUE(A8),'Parcial 2'!$A$2:$G$21,7,FALSE),"") -> #NAME? | L8: =_xludf.ifna(VLOOKUP(LEFT(D8,LEN(D8)-1),Xtra!$C$6:$N$53,12,FALSE),"") -> #NAME? | M8: =SUM(F8:L8) -> #NAME? | N8: =M8/5 -> #NAME? | O8: =Partic!S8/(COUNTA(Partic!D$1:S$1)-1) -> 0 | P8: =VLOOKUP(LEFT(D8,LEN(D8)-1),Tareas!$A$2:$Q$31,17,FALSE) -> 0.64285714 | Q8: =IF(E8="Retirado","R",N8+MAX(O8:P8)) -> #NAME?
A9: 31988236 | B9: Fiandaca | C9: Santiago | D9: sfiandaca@correo.unimet.edu.ve. | F9: =VLOOKUP(LEFT(D9,LEN(D9)-1),'Eval. Cont.'!$A$2:$Q$31,17,FALSE) -> 12.828571 | G9: ='Quiz 1'!G10/2 -> 2 | H9: =_xludf.ifna(VLOOKUP(VALUE(A9),'Parcial 1'!$A$2:$H$28,8,FALSE),"") -> #NAME? | I9: =IF('Quiz 2'!K10<>"",'Quiz 2'!K10/2,"") | J9: =_xludf.ifna(VLOOKUP(VALUE(A9),Proyecto!$A$3:$AA$23,27,FALSE),"") -> #NAME? | K9: =_xludf.ifna(VLOOKUP(VALUE(A9),'Parcial 2'!$A$2:$G$21,7,FALSE),"") -> #NAME? | L9: =_xludf.ifna(VLOOKUP(LEFT(D9,LEN(D9)-1),Xtra!$C$6:$N$53,12,FALSE),"") -> #NAME? | M9: =SUM(F9:L9) -> #NAME? | N9: =M9/5 -> #NAME? | O9: =Partic!S9/(COUNTA(Partic!D$1:S$1)-1) -> 0.066666667 | P9: =VLOOKUP(LEFT(D9,LEN(D9)-1),Tareas!$A$2:$Q$31,17,FALSE) -> 0.21428571 | Q9: =IF(E9="Retirado","R",N9+MAX(O9:P9)) -> #NAME?
A10: 31112818 | B10: Haiek | C10: Paola | D10: paola.haiek@correo.unimet.edu.ve. | E10: Retirado | F10: =VLOOKUP(LEFT(D10,LEN(D10)-1),'Eval. Cont.'!$A$2:$Q$31,17,FALSE) -> 15.185714 | G10: ='Quiz 1'!G11/2 -> 0 | H10: =_xludf.ifna(VLOOKUP(VALUE(A10),'Parcial 1'!$A$2:$H$28,8,FALSE),"") -> #NAME? | I10: =IF('Quiz 2'!K11<>"",'Quiz 2'!K11/2,"") | J10: =_xludf.ifna(VLOOKUP(VALUE(A10),Proyecto!$A$3:$AA$23,27,FALSE),"") -> #NAME? | K10: =_xludf.ifna(VLOOKUP(VALUE(A10),'Parcial 2'!$A$2:$G$21,7,FALSE),"") -> #NAME? | L10: =_xludf.ifna(VLOOKUP(LEFT(D10,LEN(D10)-1),Xtra!$C$6:$N$53,12,FALSE),"") -> #NAME? | M10: =SUM(F10:L10) -> #NAME? | N10: =M10/5 -> #NAME? | O10: =Partic!S10/(COUNTA(Partic!D$1:S$1)-1) -> 0.46666667 | P10: =VLOOKUP(LEFT(D10,LEN(D10)-1),Tareas!$A$2:$Q$31,17,FALSE) -> 0.57142857 | Q10: =IF(E10="Retirado","R",N10+MAX(O10:P10)) -> R
A11: 30030485 | B11: Hernandez | C11: Andrea | D11: h.andrea@correo.unimet.edu.ve. | F11: =VLOOKUP(LEFT(D11,LEN(D11)-1),'Eval. Cont.'!$A$2:$Q$31,17,FALSE) -> 17.321429 | G11: ='Quiz 1'!G12/2 -> 1.75 | H11: =_xludf.ifna(VLOOKUP(VALUE(A11),'Parcial 1'!$A$2:$H$28,8,FALSE),"") -> #NAME? | I11: =IF('Quiz 2'!K12<>"",'Quiz 2'!K12/2,"") -> 2 | J11: =_xludf.ifna(VLOOKUP(VALUE(A11),Proyecto!$A$3:$AA$23,27,FALSE),"") -> #NAME? | K11: =_xludf.ifna(VLOOKUP(VALUE(A11),'Parcial 2'!$A$2:$G$21,7,FALSE),"") -> #NAME? | L11: =_xludf.ifna(VLOOKUP(LEFT(D11,LEN(D11)-1),Xtra!$C$6:$N$53,12,FALSE),"") -> #NAME? | M11: =SUM(F11:L11) -> #NAME? | N11: =M11/5 -> #NAME? | O11: =Partic!S11/(COUNTA(Partic!D$1:S$1)-1) -> 0.13333333 | P11: =VLOOKUP(LEFT(D11,LEN(D11)-1),Tareas!$A$2:$Q$31,17,FALSE) -> 0.21428571 | Q11: =IF(E11="Retirado","R",N11+MAX(O11:P11)) -> #NAME?
A12: 30793086 | B12: Idrobo | C12: Jose | D12: idrobo.jose@correo.unimet.edu.ve. | E12: Retirado | F12: =VLOOKUP(LEFT(D12,LEN(D12)-1),'Eval. Cont.'!$A$2:$Q$31,17,FALSE) -> 2.5 | G12: ='Quiz 1'!G13/2 -> 0 | H12: =_xludf.ifna(VLOOKUP(VALUE(A12),'Parcial 1'!$A$2:$H$28,8,FALSE),"") -> #NAME? | I12: =IF('Quiz 2'!K13<>"",'Quiz 2'!K13/2,"") | J12: =_xludf.ifna(VLOOKUP(VALUE(A12),Proyecto!$A$3:$AA$23,27,FALSE),"") -> #NAME? | K12: =_xludf.ifna(VLOOKUP(VALUE(A12),'Parcial 2'!$A$2:$G$21,7,FALSE),"") -> #NAME? | L12: =_xludf.ifna(VLOOKUP(LEFT(D12,LEN(D12)-1),Xtra!$C$6:$N$53,12,FALSE),"") -> #NAME? | M12: =SUM(F12:L12) -> #NAME? | N12: =M12/5 -> #NAME? | O12: =Partic!S12/(COUNTA(Partic!D$1:S$1)-1) -> 0 | P12: =VLOOKUP(LEFT(D12,LEN(D12)-1),Tareas!$A$2:$Q$31,17,FALSE) -> 0 | Q12: =IF(E12="Retirado","R",N12+MAX(O12:P12)) -> R
A13: 32242412 | B13: Kchour | C13: Mohamad | D13: mohamad.kchour@correo.unimet.edu.ve. | F13: =VLOOKUP(LEFT(D13,LEN(D13)-1),'Eval. Cont.'!$A$2:$Q$31,17,FALSE) -> 15.690714 | G13: ='Quiz 1'!G14/2 -> 0 | H13: =_xludf.ifna(VLOOKUP(VALUE(A13),'Parcial 1'!$A$2:$H$28,8,FALSE),"") -> #NAME? | I13: =IF('Quiz 2'!K14<>"",'Quiz 2'!K14/2,"") -> 1.5 | J13: =_xludf.ifna(VLOOKUP(VALUE(A13),Proyecto!$A$3:$AA$23,27,FALSE),"") -> #NAME? | K13: =_xludf.ifna(VLOOKUP(VALUE(A13),'Parcial 2'!$A$2:$G$21,7,FALSE),"") -> #NAME? | L13: =_xludf.ifna(VLOOKUP(LEFT(D13,LEN(D13)-1),Xtra!$C$6:$N$53,12,FALSE),"") -> #NAME? | M13: =SUM(F13:L13) -> #NAME? | N13: =M13/5 -> #NAME? | O13: =Partic!S13/(COUNTA(Partic!D$1:S$1)-1) -> 0.53333333 | P13: =VLOOKUP(LEFT(D13,LEN(D13)-1),Tareas!$A$2:$Q$31,17,FALSE) -> 0.14285714 | Q13: =IF(E13="Retirado","R",N13+MAX(O13:P13)) -> #NAME?
A14: 30598031 | B14: Livinaly | C14: Paola | D14: plivinaly@correo.unimet.edu.ve. | F14: =VLOOKUP(LEFT(D14,LEN(D14)-1),'Eval. Cont.'!$A$2:$Q$31,17,FALSE) -> 16.102143 | G14: ='Quiz 1'!G15/2 -> 0 | H14: =_xludf.ifna(VLOOKUP(VALUE(A14),'Parcial 1'!$A$2:$H$28,8,FALSE),"") -> #NAME? | I14: =IF('Quiz 2'!K15<>"",'Quiz 2'!K15/2,"") | J14: =_xludf.ifna(VLOOKUP(VALUE(A14),Proyecto!$A$3:$AA$23,27,FALSE),"") -> #NAME? | K14: =_xludf.ifna(VLOOKUP(VALUE(A14),'Parcial 2'!$A$2:$G$21,7,FALSE),"") -> #NAME? | L14: =_xludf.ifna(VLOOKUP(LEFT(D14,LEN(D14)-1),Xtra!$C$6:$N$53,12,FALSE),"") -> #NAME? | M14: =SUM(F14:L14) -> #NAME? | N14: =M14/5 -> #NAME? | O14: =Partic!S14/(COUNTA(Partic!D$1:S$1)-1) -> 0.6 | P14: =VLOOKUP(LEFT(D14,LEN(D14)-1),Tareas!$A$2:$Q$31,17,FALSE) -> 0.71428571 | Q14: =IF(E14="Retirado","R",N14+MAX(O14:P14)) -> #NAME?
A15: 31852058 | B15: Medina | C15: Laura | D15: laura.medina@correo.unimet.edu.ve. | F15: =VLOOKUP(LEFT(D15,LEN(D15)-1),'Eval. Cont.'!$A$2:$Q$31,17,FALSE) -> 18.357143 | G15: ='Quiz 1'!G16/2 -> 1 | H15: =_xludf.ifna(VLOOKUP(VALUE(A15),'Parcial 1'!$A$2:$H$28,8,FALSE),"") -> #NAME? | I15: =IF('Quiz 2'!K16<>"",'Quiz 2'!K16/2,"") -> 4.5 | J15: =_xludf.ifna(VLOOKUP(VALUE(A15),Proyecto!$A$3:$AA$23,27,FALSE),"") -> #NAME? | K15: =_xludf.ifna(VLOOKUP(VALUE(A15),'Parcial 2'!$A$2:$G$21,7,FALSE),"") -> #NAME? | L15: =_xludf.ifna(VLOOKUP(LEFT(D15,LEN(D15)-1),Xtra!$C$6:$N$53,12,FALSE),"") -> #NAME? | M15: =SUM(F15:L15) -> #NAME? | N15: =M15/5 -> #NAME? | O15: =Partic!S15/(COUNTA(Partic!D$1:S$1)-1) -> 0.86666667 | P15: =VLOOKUP(LEFT(D15,LEN(D15)-1),Tareas!$A$2:$Q$31,17,FALSE) -> 0.28571429 | Q15: =IF(E15="Retirado","R",N15+MAX(O15:P15)) -> #NAME?
A16: 30114012 | B16: Mercado | C16: Flavia | D16: flavia.mercado@correo.unimet.edu.ve. | F16: =VLOOKUP(LEFT(D16,LEN(D16)-1),'Eval. Cont.'!$A$2:$Q$31,17,FALSE) -> 16.905 | G16: ='Quiz 1'!G17/2 -> 5.25 | H16: =_xludf.ifna(VLOOKUP(VALUE(A16),'Parcial 1'!$A$2:$H$28,8,FALSE),"") -> #NAME? | I16: =IF('Quiz 2'!K17<>"",'Quiz 2'!K17/2,"") -> 0.75 | J16: =_xludf.ifna(VLOOKUP(VALUE(A16),Proyecto!$A$3:$AA$23,27,FALSE),"") -> #NAME? | K16: =_xludf.ifna(VLOOKUP(VALUE(A16),'Parcial 2'!$A$2:$G$21,7,FALSE),"") -> #NAME? | L16: =_xludf.ifna(VLOOKUP(LEFT(D16,LEN(D16)-1),Xtra!$C$6:$N$53,12,FALSE),"") -> #NAME? | M16: =SUM(F16:L16) -> #NAME? | N16: =M16/5 -> #NAME? | O16: =Partic!S16/(COUNTA(Partic!D$1:S$1)-1) -> 0.66666667 | P16: =VLOOKUP(LEFT(D16,LEN(D16)-1),Tareas!$A$2:$Q$31,17,FALSE) -> 0.21428571 | Q16: =IF(E16="Retirado","R",N16+MAX(O16:P16)) -> #NAME?
A17: 26954417 | B17: Moya | C17: Angel | D17: angel.moya@correo.unimet.edu.ve. | E17: Retirado | F17: =VLOOKUP(LEFT(D17,LEN(D17)-1),'Eval. Cont.'!$A$2:$Q$31,17,FALSE) -> 6.4642857 | G17: ='Quiz 1'!G18/2 -> 0 | H17: =_xludf.ifna(VLOOKUP(VALUE(A17),'Parcial 1'!$A$2:$H$28,8,FALSE),"") -> #NAME? | I17: =IF('Quiz 2'!K18<>"",'Quiz 2'!K18/2,"") | J17: =_xludf.ifna(VLOOKUP(VALUE(A17),Proyecto!$A$3:$AA$23,27,FALSE),"") -> #NAME? | K17: =_xludf.ifna(VLOOKUP(VALUE(A17),'Parcial 2'!$A$2:$G$21,7,FALSE),"") -> #NAME? | L17: =_xludf.ifna(VLOOKUP(LEFT(D17,LEN(D17)-1),Xtra!$C$6:$N$53,12,FALSE),"") -> #NAME? | M17: =SUM(F17:L17) -> #NAME? | N17: =M17/5 -> #NAME? | O17: =Partic!S17/(COUNTA(Partic!D$1:S$1)-1) -> 0 | P17: =VLOOKUP(LEFT(D17,LEN(D17)-1),Tareas!$A$2:$Q$31,17,FALSE) -> 0.071428571 | Q17: =IF(E17="Retirado","R",N17+MAX(O17:P17)) -> R
A18: 31448943 | B18: Pamphile | C18: Samuel | D18: samuel.pamphile@correo.unimet.edu.ve. | E18: Retirado | F18: =VLOOKUP(LEFT(D18,LEN(D18)-1),'Eval. Cont.'!$A$2:$Q$31,17,FALSE) -> 0 | G18: ='Quiz 1'!G19/2 -> 0 | H18: =_xludf.ifna(VLOOKUP(VALUE(A18),'Parcial 1'!$A$2:$H$28,8,FALSE),"") -> #NAME? | I18: =IF('Quiz 2'!K19<>"",'Quiz 2'!K19/2,"") | J18: =_xludf.ifna(VLOOKUP(VALUE(A18),Proyecto!$A$3:$AA$23,27,FALSE),"") -> #NAME? | K18: =_xludf.ifna(VLOOKUP(VALUE(A18),'Parcial 2'!$A$2:$G$21,7,FALSE),"") -> #NAME? | L18: =_xludf.ifna(VLOOKUP(LEFT(D18,LEN(D18)-1),Xtra!$C$6:$N$53,12,FALSE),"") -> #NAME? | M18: =SUM(F18:L18) -> #NAME? | N18: =M18/5 -> #NAME? | O18: =Partic!S18/(COUNTA(Partic!D$1:S$1)-1) -> 0.33333333 | P18: =VLOOKUP(LEFT(D18,LEN(D18)-1),Tareas!$A$2:$Q$31,17,FALSE) -> 0.071428571 | Q18: =IF(E18="Retirado","R",N18+MAX(O18:P18)) -> R
A19: 31423000 | B19: Pizza | C19: Emmanuel | D19: pizzap@correo.unimet.edu.ve. | F19: =VLOOKUP(LEFT(D19,LEN(D19)-1),'Eval. Cont.'!$A$2:$Q$31,17,FALSE) -> 14.464286 | G19: ='Quiz 1'!G20/2 -> 0.5 | H19: =_xludf.ifna(VLOOKUP(VALUE(A19),'Parcial 1'!$A$2:$H$28,8,FALSE),"") -> #NAME? | I19: =IF('Quiz 2'!K20<>"",'Quiz 2'!K20/2,"") -> 1.25 | J19: =_xludf.ifna(VLOOKUP(VALUE(A19),Proyecto!$A$3:$AA$23,27,FALSE),"") -> #NAME? | K19: =_xludf.ifna(VLOOKUP(VALUE(A19),'Parcial 2'!$A$2:$G$21,7,FALSE),"") -> #NAME? | L19: =_xludf.ifna(VLOOKUP(LEFT(D19,LEN(D19)-1),Xtra!$C$6:$N$53,12,FALSE),"") -> #NAME? | M19: =SUM(F19:L19) -> #NAME? | N19: =M19/5 -> #NAME? | O19: =Partic!S19/(COUNTA(Partic!D$1:S$1)-1) -> 0.2 | P19: =VLOOKUP(LEFT(D19,LEN(D19)-1),Tareas!$A$2:$Q$31,17,FALSE) -> 0.071428571 | Q19: =IF(E19="Retirado","R",N19+MAX(O19:P19)) -> #NAME?
A20: 31046285 | B20: Rodriguez | C20: Rafael | D20: rodriguez.rafael@correo.unimet.edu.ve. | E20: Retirado | F20: =VLOOKUP(LEFT(D20,LEN(D20)-1),'Eval. Cont.'!$A$2:$Q$31,17,FALSE) -> 2.6907143 | G20: ='Quiz 1'!G21/2 -> 0 | H20: =_xludf.ifna(VLOOKUP(VALUE(A20),'Parcial 1'!$A$2:$H$28,8,FALSE),"") -> #NAME? | I20: =IF('Quiz 2'!K21<>"",'Quiz 2'!K21/2,"") | J20: =_xludf.ifna(VLOOKUP(VALUE(A20),Proyecto!$A$3:$AA$23,27,FALSE),"") -> #NAME? | K20: =_xludf.ifna(VLOOKUP(VALUE(A20),'Parcial 2'!$A$2:$G$21,7,FALSE),"") -> #NAME? | L20: =_xludf.ifna(VLOOKUP(LEFT(D20,LEN(D20)-1),Xtra!$C$6:$N$53,12,FALSE),"") -> #NAME? | M20: =SUM(F20:L20) -> #NAME? | N20: =M20/5 -> #NAME? | O20: =Partic!S20/(COUNTA(Partic!D$1:S$1)-1) -> 0.066666667 | P20: =VLOOKUP(LEFT(D20,LEN(D20)-1),Tareas!$A$2:$Q$31,17,FALSE) -> 0 | Q20: =IF(E20="Retirado","R",N20+MAX(O20:P20)) -> R
A21: 31255343 | B21: Rojas | C21: Luciano | D21: luciano.rojas@correo.unimet.edu.ve. | F21: =VLOOKUP(LEFT(D21,LEN(D21)-1),'Eval. Cont.'!$A$2:$Q$31,17,FALSE) -> 18.054286 | G21: ='Quiz 1'!G22/2 -> 3.25 | H21: =_xludf.ifna(VLOOKUP(VALUE(A21),'Parcial 1'!$A$2:$H$28,8,FALSE),"") -> #NAME? | I21: =IF('Quiz 2'!K22<>"",'Quiz 2'!K22/2,"") -> 3.25 | J21: =_xludf.ifna(VLOOKUP(VALUE(A21),Proyecto!$A$3:$AA$23,27,FALSE),"") -> #NAME? | K21: =_xludf.ifna(VLOOKUP(VALUE(A21),'Parcial 2'!$A$2:$G$21,7,FALSE),"") -> #NAME? | L21: =_xludf.ifna(VLOOKUP(LEFT(D21,LEN(D21)-1),Xtra!$C$6:$N$53,12,FALSE),"") -> #NAME? | M21: =SUM(F21:L21) -> #NAME? | N21: =M21/5 -> #NAME? | O21: =Partic!S21/(COUNTA(Partic!D$1:S$1)-1) -> 0.2 | P21: =VLOOKUP(LEFT(D21,LEN(D21)-1),Tareas!$A$2:$Q$31,17,FALSE) -> 0.071428571 | Q21: =IF(E21="Retirado","R",N21+MAX(O21:P21)) -> #NAME?
A22: 32401366 | B22: Ruiz | C22: José | D22: joseruiz@correo.unimet.edu.ve. | F22: =VLOOKUP(LEFT(D22,LEN(D22)-1),'Eval. Cont.'!$A$2:$Q$31,17,FALSE) -> 14.880714 | G22: ='Quiz 1'!G23/2 -> 8 | H22: =_xludf.ifna(VLOOKUP(VALUE(A22),'Parcial 1'!$A$2:$H$28,8,FALSE),"") -> #NAME? | I22: =IF('Quiz 2'!K23<>"",'Quiz 2'!K23/2,"") -> 1.875 | J22: =_xludf.ifna(VLOOKUP(VALUE(A22),Proyecto!$A$3:$AA$23,27,FALSE),"") -> #NAME? | K22: =_xludf.ifna(VLOOKUP(VALUE(A22),'Parcial 2'!$A$2:$G$21,7,FALSE),"") -> #NAME? | L22: =_xludf.ifna(VLOOKUP(LEFT(D22,LEN(D22)-1),Xtra!$C$6:$N$53,12,FALSE),"") -> #NAME? | M22: =SUM(F22:L22) -> #NAME? | N22: =M22/5 -> #NAME? | O22: =Partic!S22/(COUNTA(Partic!D$1:S$1)-1) -> 0.13333333 | P22: =VLOOKUP(LEFT(D22,LEN(D22)-1),Tareas!$A$2:$Q$31,17,FALSE) -> 0.5 | Q22: =IF(E22="Retirado","R",N22+MAX(O22:P22)) -> #NAME?
A23: 32121917 | B23: Salimbeni | C23: César | D23: cesar.salimbeni@correo.unimet.edu.ve. | F23: =VLOOKUP(LEFT(D23,LEN(D23)-1),'Eval. Cont.'!$A$2:$Q$31,17,FALSE) -> 17.059286 | G23: ='Quiz 1'!G24/2 -> 6.5 | H23: =_xludf.ifna(VLOOKUP(VALUE(A23),'Parcial 1'!$A$2:$H$28,8,FALSE),"") -> #NAME? | I23: =IF('Quiz 2'!K24<>"",'Quiz 2'!K24/2,"") -> 4.5 | J23: =_xludf.ifna(VLOOKUP(VALUE(A23),Proyecto!$A$3:$AA$23,27,FALSE),"") -> #NAME? | K23: =_xludf.ifna(VLOOKUP(VALUE(A23),'Parcial 2'!$A$2:$G$21,7,FALSE),"") -> #NAME? | L23: =_xludf.ifna(VLOOKUP(LEFT(D23,LEN(D23)-1),Xtra!$C$6:$N$53,12,FALSE),"") -> #NAME? | M23: =SUM(F23:L23) -> #NAME? | N23: =M23/5 -> #NAME? | O23: =Partic!S23/(COUNTA(Partic!D$1:S$1)-1) -> 1.1333333 | P23: =VLOOKUP(LEFT(D23,LEN(D23)-1),Tareas!$A$2:$Q$31,17,FALSE) -> 0.42857143 | Q23: 19
A24: 33921124 | B24: Sanchez | C24: David | D24: d.sanchez@correo.unimet.edu.ve. | F24: =VLOOKUP(LEFT(D24,LEN(D24)-1),'Eval. Cont.'!$A$2:$Q$31,17,FALSE) -> 15.738571 | G24: ='Quiz 1'!G25/2 -> 0.5 | H24: =_xludf.ifna(VLOOKUP(VALUE(A24),'Parcial 1'!$A$2:$H$28,8,FALSE),"") -> #NAME? | I24: =IF('Quiz 2'!K25<>"",'Quiz 2'!K25/2,"") -> 3.625 | J24: =_xludf.ifna(VLOOKUP(VALUE(A24),Proyecto!$A$3:$AA$23,27,FALSE),"") -> #NAME? | K24: =_xludf.ifna(VLOOKUP(VALUE(A24),'Parcial 2'!$A$2:$G$21,7,FALSE),"") -> #NAME? | L24: =_xludf.ifna(VLOOKUP(LEFT(D24,LEN(D24)-1),Xtra!$C$6:$N$53,12,FALSE),"") -> #NAME? | M24: =SUM(F24:L24) -> #NAME? | N24: =M24/5 -> #NAME? | O24: =Partic!S24/(COUNTA(Partic!D$1:S$1)-1) -> 0.2 | P24: =VLOOKUP(LEFT(D24,LEN(D24)-1),Tareas!$A$2:$Q$31,17,FALSE) -> 0.21428571 | Q24: =IF(E24="Retirado","R",N24+MAX(O24:P24)) -> #NAME?
A25: 31703910 | B25: Saracual | C25: Daniel | D25: daniel.saracual@correo.unimet.edu.ve. | F25: =VLOOKUP(LEFT(D25,LEN(D25)-1),'Eval. Cont.'!$A$2:$Q$31,17,FALSE) -> 16.464286 | G25: ='Quiz 1'!G26/2 -> 0 | H25: =_xludf.ifna(VLOOKUP(VALUE(A25),'Parcial 1'!$A$2:$H$28,8,FALSE),"") -> #NAME? | I25: =IF('Quiz 2'!K26<>"",'Quiz 2'!K26/2,"") -> 0.75 | J25: =_xludf.ifna(VLOOKUP(VALUE(A25),Proyecto!$A$3:$AA$23,27,FALSE),"") -> #NAME? | K25: =_xludf.ifna(VLOOKUP(VALUE(A25),'Parcial 2'!$A$2:$G$21,7,FALSE),"") -> #NAME? | L25: =_xludf.ifna(VLOOKUP(LEFT(D25,LEN(D25)-1),Xtra!$C$6:$N$53,12,FALSE),"") -> #NAME? | M25: =SUM(F25:L25) -> #NAME? | N25: =M25/5 -> #NAME? | O25: =Partic!S25/(COUNTA(Partic!D$1:S$1)-1) -> 0.2 | P25: =VLOOKUP(LEFT(D25,LEN(D25)-1),Tareas!$A$2:$Q$31,17,FALSE) -> 0.14285714 | Q25: =IF(E25="Retirado","R",N25+MAX(O25:P25)) -> #NAME?
A26: 32122110 | B26: Silva | C26: Elva | D26: elva.silva@correo.unimet.edu.ve. | F26: =VLOOKUP(LEFT(D26,LEN(D26)-1),'Eval. Cont.'!$A$2:$Q$31,17,FALSE) -> 12.345 | G26: ='Quiz 1'!G27/2 -> 2.75 | H26: =_xludf.ifna(VLOOKUP(VALUE(A26),'Parcial 1'!$A$2:$H$28,8,FALSE),"") -> #NAME? | I26: =IF('Quiz 2'!K27<>"",'Quiz 2'!K27/2,"") -> 2.875 | J26: =_xludf.ifna(VLOOKUP(VALUE(A26),Proyecto!$A$3:$AA$23,27,FALSE),"") -> #NAME? | K26: =_xludf.ifna(VLOOKUP(VALUE(A26),'Parcial 2'!$A$2:$G$21,7,FALSE),"") -> #NAME? | L26: =_xludf.ifna(VLOOKUP(LEFT(D26,LEN(D26)-1),Xtra!$C$6:$N$53,12,FALSE),"") -> #NAME? | M26: =SUM(F26:L26) -> #NAME? | N26: =M26/5 -> #NAME? | O26: =Partic!S26/(COUNTA(Partic!D$1:S$1)-1) -> 0.66666667 | P26: =VLOOKUP(LEFT(D26,LEN(D26)-1),Tareas!$A$2:$Q$31,17,FALSE) -> 0.21428571 | Q26: =IF(E26="Retirado","R",N26+MAX(O26:P26)) -> #NAME?
A27: 30720123 | B27: Steinmetz | C27: Erik | D27: s.erik@correo.unimet.edu.ve. | F27: =VLOOKUP(LEFT(D27,LEN(D27)-1),'Eval. Cont.'!$A$2:$Q$31,17,FALSE) -> 14.512143 | G27: ='Quiz 1'!G28/2 -> 5 | H27: =_xludf.ifna(VLOOKUP(VALUE(A27),'Parcial 1'!$A$2:$H$28,8,FALSE),"") -> #NAME? | I27: =IF('Quiz 2'!K28<>"",'Quiz 2'!K28/2,"") -> 5.875 | J27: =_xludf.ifna(VLOOKUP(VALUE(A27),Proyecto!$A$3:$AA$23,27,FALSE),"") -> #NAME? | K27: =_xludf.ifna(VLOOKUP(VALUE(A27),'Parcial 2'!$A$2:$G$21,7,FALSE),"") -> #NAME? | L27: =_xludf.ifna(VLOOKUP(LEFT(D27,LEN(D27)-1),Xtra!$C$6:$N$53,12,FALSE),"") -> #NAME? | M27: =SUM(F27:L27) -> #NAME? | N27: =M27/5 -> #NAME? | O27: =Partic!S27/(COUNTA(Partic!D$1:S$1)-1) -> 0 | P27: =VLOOKUP(LEFT(D27,LEN(D27)-1),Tareas!$A$2:$Q$31,17,FALSE) -> 0.14285714 | Q27: =IF(E27="Retirado","R",N27+MAX(O27:P27)) -> #NAME?
A28: 29895575 | B28: Trezza | C28: Sofia | D28: sofia.trezza@correo.unimet.edu.ve. | F28: =VLOOKUP(LEFT(D28,LEN(D28)-1),'Eval. Cont.'!$A$2:$Q$31,17,FALSE) -> 15.071429 | G28: ='Quiz 1'!G29/2 -> 4.5 | H28: =_xludf.ifna(VLOOKUP(VALUE(A28),'Parcial 1'!$A$2:$H$28,8,FALSE),"") -> #NAME? | I28: =IF('Quiz 2'!K29<>"",'Quiz 2'!K29/2,"") | J28: =_xludf.ifna(VLOOKUP(VALUE(A28),Proyecto!$A$3:$AA$23,27,FALSE),"") -> #NAME? | K28: =_xludf.ifna(VLOOKUP(VALUE(A28),'Parcial 2'!$A$2:$G$21,7,FALSE),"") -> #NAME? | L28: =_xludf.ifna(VLOOKUP(LEFT(D28,LEN(D28)-1),Xtra!$C$6:$N$53,12,FALSE),"") -> #NAME? | M28: =SUM(F28:L28) -> #NAME? | N28: =M28/5 -> #NAME? | O28: =Partic!S28/(COUNTA(Partic!D$1:S$1)-1) -> 0.73333333 | P28: =VLOOKUP(LEFT(D28,LEN(D28)-1),Tareas!$A$2:$Q$31,17,FALSE) -> 0.5 | Q28: =IF(E28="Retirado","R",N28+MAX(O28:P28)) -> #NAME?
A29: 31615220 | B29: Ugarte Pelayo | C29: Nicole | D29: nicole.ugartepelayo@correo.unimet.edu.ve. | E29: Retirado | F29: =VLOOKUP(LEFT(D29,LEN(D29)-1),'Eval. Cont.'!$A$2:$Q$31,17,FALSE) -> 1.2857143 | G29: ='Quiz 1'!G30/2 -> 0 | H29: =_xludf.ifna(VLOOKUP(VALUE(A29),'Parcial 1'!$A$2:$H$28,8,FALSE),"") -> #NAME? | I29: =IF('Quiz 2'!K30<>"",'Quiz 2'!K30/2,"") -> 1.75 | J29: =_xludf.ifna(VLOOKUP(VALUE(A29),Proyecto!$A$3:$AA$23,27,FALSE),"") -> #NAME? | K29: =_xludf.ifna(VLOOKUP(VALUE(A29),'Parcial 2'!$A$2:$G$21,7,FALSE),"") -> #NAME? | L29: =_xludf.ifna(VLOOKUP(LEFT(D29,LEN(D29)-1),Xtra!$C$6:$N$53,12,FALSE),"") -> #NAME? | M29: =SUM(F29:L29) -> #NAME? | N29: =M29/5 -> #NAME? | O29: =Partic!S29/(COUNTA(Partic!D$1:S$1)-1) -> 0 | P29: =VLOOKUP(LEFT(D29,LEN(D29)-1),Tareas!$A$2:$Q$31,17,FALSE) -> 0.14285714 | Q29: =IF(E29="Retirado","R",N29+MAX(O29:P29)) -> R
A30: 30022208 | B30: Viñas | C30: Gabriel | D30: gvinas@correo.unimet.edu.ve. | F30: =VLOOKUP(LEFT(D30,LEN(D30)-1),'Eval. Cont.'!$A$2:$Q$31,17,FALSE) -> 13.178571 | G30: ='Quiz 1'!G31/2 -> 0.25 | H30: =_xludf.ifna(VLOOKUP(VALUE(A30),'Parcial 1'!$A$2:$H$28,8,FALSE),"") -> #NAME? | I30: =IF('Quiz 2'!K31<>"",'Quiz 2'!K31/2,"") -> 3.375 | J30: =_xludf.ifna(VLOOKUP(VALUE(A30),Proyecto!$A$3:$AA$23,27,FALSE),"") -> #NAME? | K30: =_xludf.ifna(VLOOKUP(VALUE(A30),'Parcial 2'!$A$2:$G$21,7,FALSE),"") -> #NAME? | L30: =_xludf.ifna(VLOOKUP(LEFT(D30,LEN(D30)-1),Xtra!$C$6:$N$53,12,FALSE),"") -> #NAME? | M30: =SUM(F30:L30) -> #NAME? | N30: =M30/5 -> #NAME? | O30: =Partic!S30/(COUNTA(Partic!D$1:S$1)-1) -> 0.33333333 | P30: =VLOOKUP(LEFT(D30,LEN(D30)-1),Tareas!$A$2:$Q$31,17,FALSE) -> 0.28571429 | Q30: =IF(E30="Retirado","R",N30+MAX(O30:P30)) -> #NAME?
A31: 31963201 | B31: Zerpa | C31: Azael | D31: azael.zerpa@correo.unimet.edu.ve. | F31: =VLOOKUP(LEFT(D31,LEN(D31)-1),'Eval. Cont.'!$A$2:$Q$31,17,FALSE) -> 18.583571 | G31: ='Quiz 1'!G32/2 -> 1 | H31: =_xludf.ifna(VLOOKUP(VALUE(A31),'Parcial 1'!$A$2:$H$28,8,FALSE),"") -> #NAME? | I31: =IF('Quiz 2'!K32<>"",'Quiz 2'!K32/2,"") -> 2 | J31: =_xludf.ifna(VLOOKUP(VALUE(A31),Proyecto!$A$3:$AA$23,27,FALSE),"") -> #NAME? | K31: =_xludf.ifna(VLOOKUP(VALUE(A31),'Parcial 2'!$A$2:$G$21,7,FALSE),"") -> #NAME? | L31: =_xludf.ifna(VLOOKUP(LEFT(D31,LEN(D31)-1),Xtra!$C$6:$N$53,12,FALSE),"") -> #NAME? | M31: =SUM(F31:L31) -> #NAME? | N31: =M31/5 -> #NAME? | O31: =Partic!S31/(COUNTA(Partic!D$1:S$1)-1) -> 0.13333333 | P31: =VLOOKUP(LEFT(D31,LEN(D31)-1),Tareas!$A$2:$Q$31,17,FALSE) -> 0.071428571 | Q31: =IF(E31="Retirado","R",N31+MAX(O31:P31)) -> #NAME?

Sheet Quiz 1
A1: NOMBRE | B1: P1 (5.00) | C1: P2 (9.00) | D1: P3(4.00) | E1: P4(2.00) | F1: BONO (3.00) | G1: TOTAL (23.00)
B2: Funcionamiento | C2: Fun+Mtx+Sqr | D2: Funcionamiento | E2: Funcionamiento | F2: Funcionamiento
A3: Sebastian Alfonzo
A4: Matthias Amelinckx | B4: 0 | C4: 0 | D4: 0 | E4: 0 | F4: 1.25 | G4: 1.25
A5: Flavia Aray | B5: 0 | C5: 2.5 | D5: 0 | E5: 1 | F5: 0.5 | G5: 4
A6: Angelica Blanco | B6: 0 | C6: 0 | D6: 0 | E6: 0 | F6: 0 | G6: 0
A7: Gabriel Brusco | B7: 0 | C7: 0 | D7: 0 | E7: 0 | F7: 0 | G7: 0
A8: Diego Callender | B8: 5 | C8: 1.5 | D8: 2 | E8: 2 | F8: 0 | G8: 10.5
A9: Elohym Casais*** | B9: 0 | C9: 0 | D9: 0 | E9: 0 | F9: 0 | G9: 0
A10: Santiago Fiandaca | B10: 0 | C10: 0 | D10: 0 | E10: 2 | F10: 2 | G10: 4
A11: Paola Haiek | B11: 0 | C11: 0 | D11: 0 | E11: 0 | F11: 0 | G11: 0
A12: Adrea Hernández | B12: 2 | C12: 0 | D12: 0 | E12: 0 | F12: 1.5 | G12: 3.5
A14: Mohamad Kchour | B14: 0 | C14: 0 | D14: 0 | E14: 0 | F14: 0 | G14: 0
A15: Paola Livinaly | B15: 0 | C15: 0 | D15: 0 | E15: 0 | F15: 0 | G15: 0
A16: Laura Medina*** | B16: 0 | C16: 0 | D16: 0 | E16: 1 | F16: 1 | G16: 2
... A32: Azael Zerpa | B32: 0 | C32: 1 | D32: 0 | E32: 0 | F32: 1 | G32: 2

Sheet Parcial 1
A1: CEDULA | B1: APELLIDO | C1: NOMBRE | D1: V/F | E1: Selec | F1: Complet | G1: Desarrollo | H1: Total
A2: 31046285 | B2: Rodriguez | C2: Rafael | D2: 2 | E2: 3 | H2: =SUM(D2:G2) -> 5
A3: 30598031 | B3: Livinaly | C3: Paola | D3: 3 | E3: 3 | F3: 0 | H3: =SUM(D3:G3) -> 6
A4: 29895575 | B4: Trezza | C4: Sofia | D4: 3 | E4: 3 | F4: 5 | G4: 5 | H4: =SUM(D4:G4) -> 16
A5: 32121917 | B5: Salimbeni | C5: César | D5: 2 | E5: 3 | F5: 6 | G5: 7 | H5: =SUM(D5:G5) -> 18
A6: 31448943 | B6: Pamphile | C6: Samuel | D6: 3 | E6: 3 | F6: 0 | H6: =SUM(D6:G6) -> 6
A7: 29666935 | B7: Aray | C7: Flavia | D7: 2 | E7: 3 | F7: 5 | G7: 2 | H7: =SUM(D7:G7) -> 12
A8: 30765878 | B8: Blanco | C8: Angélica | D8: 2 | E8: 3 | F8: 4.5 | G8: 2 | H8: =SUM(D8:G8) -> 11.5
A9: 28410856 | B9: Alfonzo | C9: Sebastian | D9: 2 | E9: 3 | H9: 0
A10: 31112818 | B10: Haiek | C10: Paola | D10: 2 | E10: 3 | F10: 4.5 | H10: 0
A11: 30849611 | B11: Amelinckx | C11: Matthias | D11: 2 | E11: 3 | F11: 4.5 | H11: =SUM(D11:G11) -> 9.5
A12: 31703910 | B12: Saracual | C12: Daniel | D12: 4 | E12: 3 | F12: 1 | G12: 0 | H12: =SUM(D12:G12) -> 8
A13: 31988236 | B13: Fiandaca | C13: Santiago | D13: 4 | E13: 3 | F13: 6 | G13: 0 | H13: =SUM(D13:G13) -> 13
A14: 32242412 | B14: Kchour | C14: Mohamad | D14: 2 | E14: 3 | F14: 3 | G14: 0 | H14: =SUM(D14:G14) -> 8
A15: 32122110 | B15: Silva | C15: Elva | D15: 2 | E15: 3 | F15: 4 | G15: 6 | H15: =SUM(D15:G15) -> 15
A16: 33921124 | B16: Sanchez | C16: David | D16: 2 | E16: 3 | F16: 2 | G16: 1 | H16: =SUM(D16:G16) -> 8
A17: 30720123 | B17: Steinmetz | C17: Erik | D17: 3 | E17: 3 | F17: 6 | H17: 0
A18: 30022208 | B18: Viñas | C18: Gabriel | D18: 3 | E18: 3 | F18: 2 | G18: 1 | H18: =SUM(D18:G18) -> 9
A19: 32729082 | B19: Brusco | C19: Gabriel | D19: 3 | E19: 3 | H19: =SUM(D19:G19) -> 6
A20: 30030485 | B20: Hernandez | C20: Andrea | D20: 3 | E20: 3 | F20: 5 | G20: 7 | H20: =SUM(D20:G20) -> 18
A21: 31071592 | B21: Callender | C21: Diego | D21: 2 | E21: 3 | F21: 6 | G21: 6 | H21: =SUM(D21:G21) -> 17
A22: 31852058 | B22: Medina | C22: Laura | D22: 2 | E22: 3 | F22: 6 | G22: 2 | H22: =SUM(D22:G22) -> 13
A23: 32401366 | B23: Ruiz | C23: José Alejandro | D23: 3 | E23: 3 | F23: 6 | G23: 4 | H23: =SUM(D23:G23) -> 16
A24: 31255343 | B24: Rojas | C24: Luciano | D24: 4 | E24: 3 | F24: 0 | H24: =SUM(D24:G24) -> 7
A25: 30114012 | B25: Mercado | C25: Flavia | D25: 4 | E25: 3 | F25: 3 | G25: 4 | H25: =SUM(D25:G25) -> 14
A26: 31963201 | B26: Zerpa | C26: Azael | D26: 3 | E26: 3 | F26: 5 | G26: 4 | H26: =SUM(D26:G26) -> 15
A27: 31423000 | B27: Pizza | C27: Emmanuel | D27: 3 | E27: 3 | F27: 1 | G27: 0 | H27: =SUM(D27:G27) -> 7
A28: 32491310 | B28: Casais | C28: Elohym | D28: 4 | E28: 3 | F28: 0 | G28: 0 | H28: =SUM(D28:G28) -> 7

Sheet Quiz 2
A1: NOMBRE | B1: Ejercicio (20.00) | I1: BONO (3.00) | K1: TOTAL (23.00)
B2: Clases (6) | C2: Carga de info (4) | D2: Transferencias (3) | E2: Ver (3) | F2: Menú (1) | G2: Robustez (1) | H2: Est (2) | I2: Est 1 (1.5) | J2: Registro (1.5)
A5: Flavia Aray | B5: 5.5 | C5: 0 | D5: 0 | E5: 0 | F5: 0.5 | G5: 0.25 | H5: 0 | I5: 0 | J5: 0 | K5: =SUM(B5:J5) -> 6.25
A7: Gabriel Brusco | B7: 5.5 | C7: 4 | D7: 0 | E7: 0.5 | F7: 1 | G7: 1 | H7: 2 | I7: 0 | J7: 0 | K7: =SUM(B7:J7) -> 14
A8: Diego Callender | B8: 4.75 | C8: 0 | D8: 0 | E8: 1.5 | F8: 0.5 | G8: 0.25 | H8: 1 | I8: 0 | J8: 0 | K8: =SUM(B8:J8) -> 8
A9: Elohym Casais | B9: 4 | C9: 2 | D9: 0 | E9: 0 | F9: 1 | G9: 1 | H9: 0 | I9: 0 | J9: 0 | K9: =SUM(B9:J9) -> 8
A12: Adrea Hernández | B12: 4 | C12: 0 | D12: 0 | E12: 0 | F12: 0 | G12: 0 | H12: 0 | I12: 0 | J12: 0 | K12: =SUM(B12:J12) -> 4
A14: Mohamad Kchour | B14: 3 | C14: 0 | D14: 0 | E14: 0 | F14: 0 | G14: 0 | H14: 0 | I14: 0 | J14: 0 | K14: =SUM(B14:J14) -> 3
A16: Laura Medina | B16: 4 | C16: 2 | D16: 0 | E16: 1 | F16: 1 | G16: 1 | H16: 0 | I16: 0 | J16: 0 | K16: =SUM(B16:J16) -> 9
A17: Flavia Mercado | B17: 1.5 | C17: 0 | D17: 0 | E17: 0 | F17: 0 | G17: 0 | H17: 0 | I17: 0 | J17: 0 | K17: =SUM(B17:J17) -> 1.5
A19: Samuel Pamphile
A20: Emmanuel Pizza | B20: 1 | C20: 0 | D20: 0 | E20: 0 | F20: 1 | G20: 0.5 | H20: 0 | I20: 0 | J20: 0 | K20: =SUM(B20:J20) -> 2.5
A22: Luciano Rojas | B22: 2 | C22: 1.5 | D22: 0 | E22: 1 | F22: 0 | G22: 0 | H22: 2 | I22: 0 | J22: 0 | K22: =SUM(B22:J22) -> 6.5
A23: Jose Ruiz | B23: 2.5 | C23: 0 | D23: 0 | E23: 0 | F23: 0 | G23: 0 | H23: 0 | I23: 0 | J23: 1.25 | K23: =SUM(B23:J23) -> 3.75
A24: Cesar Salimbeni | B24: 4 | C24: 4 | D24: 0 | E24: 0 | F24: 0.5 | G24: 0.5 | H24: 0 | I24: 0 | J24: 0 | K24: =SUM(B24:J24) -> 9
A25: David Sanchéz | B25: 5 | C25: 1.5 | D25: 0 | E25: 0 | F25: 0.25 | G25: 0.5 | H25: 0 | I25: 0 | J25: 0 | K25: =SUM(B25:J25) -> 7.25
A26: Daniel Sacarual | B26: 1.5 | C26: 0 | D26: 0 | E26: 0 | F26: 0 | G26: 0 | H26: 0 | I26: 0 | J26: 0 | K26: =SUM(B26:J26) -> 1.5
A27: Elva Silva | B27: 4.75 | C27: 0 | D27: 0 | E27: 0 | F27: 0.5 | G27: 0.5 | H27: 0 | I27: 0 | J27: 0 | K27: =SUM(B27:J27) -> 5.75
A28: Erik Steinmetz | B28: 5.75 | C28: 2 | D28: 1 | E28: 1 | F28: 1 | G28: 1 | H28: 0 | I28: 0 | J28: 0 | K28: =SUM(B28:J28) -> 11.75
A30: Sofia Trezza | B30: 3.5 | C30: 0 | D30: 0 | E30: 0 | F30: 0 | G30: 0 | H30: 0 | I30: 0 | J30: 0 | K30: =SUM(B30:J30) -> 3.5
A31: Gabriel Viñas | B31: 5.5 | C31: 0.5 | D31: 0 | E31: 0 | F31: 0.5 | G31: 0.25 | H31: 0 | I31: 0 | J31: 0 | K31: =SUM(B31:J31) -> 6.75
A32: Azael Zerpa | B32: 4 | C32: 0 | D32: 0 | E32: 0 | F32: 0 | G32: 0 | H32: 0 | I32: 0 | J32: 0 | K32: =SUM(B32:J32) -> 4

Sheet Parcial 2
A1: Cédula | B1: Nombre | C1: V/F | D1: Selec | E1: E.Error | F1: Desarrollo | G1: Total
A2: 30598031 | B2: Paola Liviani | C2: 3 | D2: 2 | E2: 0 | F2: 1 | G2: 6
A3: 31423000 | B3: Emmanuel Pizza | C3: 4 | D3: 2 | E3: 3 | F3: 2 | G3: 11
A4: 30114012 | B4: Flavia Mercado | C4: 4 | D4: 3 | E4: 3 | F4: 3 | G4: 13
A5: 32121917 | B5: César Salimbeni | C5: 2 | D5: 3 | E5: 3 | F5: 8 | G5: 16
A6: 29666935 | B6: Flavia Aray | C6: 3 | D6: 2 | E6: 3 | F6: 8 | G6: 16
A7: 32242412 | B7: Mohamad Kchour | C7: 4 | D7: 3 | E7: 3 | F7: 1 | G7: 11
A8: 33921124 | B8: David Sánchez | C8: 1 | D8: 1 | E8: 3 | F8: 1 | G8: 6
A9: 31255343 | B9: Luciano Rojas | C9: 4 | D9: 2 | E9: 3 | F9: 1 | G9: 10
A10: 31963201 | B10: Azael Zerpa | C10: 1 | D10: 1 | E10: 3 | F10: 5 | G10: 10
A11: 29895575 | B11: Sofia Trezza | C11: 4 | D11: 3 | E11: 3 | F11: 6 | G11: 16
A12: 31703910 | B12: Daniel Saracual | C12: 4 | D12: 2 | E12: 3 | F12: 3 | G12: 12
A13: 31071592 | B13: Diego Callender | C13: 3 | D13: 1 | E13: 3 | F13: 6 | G13: 13
... A19: 32401366 | B19: José Ruiz | C19: 4 | D19: 3 | E19: 3 | F19: 4 | G19: 14
A20: 30849611 | B20: Matthias Amelinckx | C20: 4 | D20: 3 | E20: 3 | F20: 6 | G20: =SUM(C20:F20) -> 16
A21: 31988236 | B21: Santiago Fiandaca | C21: 4 | D21: 1.5 | E21: 3 | F21: 3.5 | G21: =SUM(C21:F21) -> 12

Sheet Proyecto
F1: Defensa | K1: Módulo 1: reactivos | N1: Módulo 2: experimentos | Q1: Módulo 3: resultados | T1: Módulo 4: Estadísticas | W1: Uso API | Y1: Archivos
A2: Cédula | B2: Apellido | C2: Nombre | D2: Ord. Entrega | E2: Ord. Defensa | F2: Expo-sicion | G2: Pregunta Prof | H2: Preg. de público | I2: Preg. a Compañero | J2: Diagra-ma | K2: Reagent Code | L2: Reagent Exec | M2: Reagent Bonus | N2: Exprmt. Code | O2: Exprmt. Exec | P2: Exprmt. Bonus | Q2: Result Code | R2: Result Exec | S2: Result Bonus | T2: Stat Code | U2: Stat Exec | V2: Stat Bonus | W2: API Code | X2: API exec | Y2: File Mgmt | Z2: File struc | AA2: Total
A3: 32121917 | B3: Salimbeni | C3: César | D3: 4 | E3: 2 | F3: 2 | G3: 0.25 | H3: 0.5 | I3: 2 | J3: 2 | K3: 0.8 | L3: 2 | N3: 1 | O3: 2 | P3: 3 | Q3: 0.9 | R3: 1 | T3: 1 | U3: 2 | W3: 1 | X3: 1 | Y3: 1 | Z3: 1 | AA3: 24.45
A4: 31852058 | B4: Medina | C4: Laura | D4: 13 | E4: 5 | F4: 2 | G4: 1 | H4: 1.5 | I4: 1.5 | J4: 1.7 | K4: 1 | L4: 1.9 | N4: 1 | O4: 2 | Q4: 1 | R4: 1 | T4: 1 | U4: 1.8 | V4: 4 | W4: 1 | X4: 1 | Y4: 1 | Z4: 1 | AA4: 26.4
A5: 29666935 | B5: Aray | C5: Flavia | D5: 6 | E5: 1 | F5: 2 | G5: 1 | H5: 1 | I5: 1 | J5: 2 | K5: 1 | L5: 1.8 | N5: 1 | O5: 1.8 | Q5: 0.25 | R5: 0.25 | T5: 2 | U5: 1.9 | V5: 1 | W5: 1 | X5: 0.5 | Y5: 1 | Z5: 1 | AA5: 21.5
A6: 32401366 | B6: Ruiz | C6: José | D6: 11 | E6: 3 | F6: 1.5 | G6: 1 | H6: 1 | I6: 0.5 | J6: 1.5 | K6: 0.5 | L6: 0 | N6: 1 | O6: 0 | Q6: 0 | R6: 0 | T6: 0 | U6: 0 | W6: 1 | X6: 0 | Y6: 0 | Z6: 0 | AA6: 8
A7: 29895575 | B7: Trezza | C7: Sofia | D7: 2 | E7: 4 | F7: 45690 | G7: 45658 | H7: 0.0/0.5 | I7: 0.5/0.5 | J7: 45659 | K7: 0.75/1 | L7: 45659 | N7: 0.5/1 | O7: 0/2 | Q7: 0.25/1 | R7: 0/1 | T7: 0.25/1 | U7: 0/2 | W7: 45658 | X7: 0.25/1 | Y7: 0.5/1 | Z7: 0/1 | AA7: 9
A8: 31255343 | B8: Rojas | C8: Luciano | D8: 5 | E8: 6 | F8: 2 | G8: 0 | H8: 1 | I8: 1.5 | J8: 2 | K8: 0.75 | L8: 0 | N8: 1 | O8: 0 | P8: 1 | Q8: 0.5 | R8: 0 | T8: 1 | U8: 0 | V8: 1 | W8: 0.5 | X8: 0 | Y8: 0.5 | Z8: 0 | AA8: 12.75
A9: 30114012 | B9: Mercado | C9: Flavia | D9: 12 | E9: 7 | F9: 2 | G9: 1 | H9: 0.5 | I9: 0.5 | J9: 1 | K9: 0.75 | L9: 1 | N9: 1 | O9: 1.75 | Q9: 0.5 | R9: 0.5 | T9: 0.75 | U9: 2 | W9: 1 | X9: 1 | Y9: 0.5 | Z9: 1 | AA9: 16.75
A10: 30030485 | B10: Hernandez | C10: Andrea | D10: 16 | E10: 9 | F10: 2 | G10: 1 | H10: 1 | I10: 1 | J10: 1 | K10: 0.75 | L10: 1.75 | N10: 0.75 | O10: 1.5 | Q10: 0.75 | R10: 0 | S10: 1 | T10: 0 | U10: 0 | W10: 0.5 | X10: 1 | Y10: 1 | Z10: 0.5 | AA10: 15.5
A11: 31703910 | B11: Saracual | C11: Daniel | D11: 14 | E11: 10 | F11: 2 | G11: 1 | H11: 1.5 | I11: 1.5 | J11: 1 | K11: 1 | L11: 1 | N11: 1 | O11: 1 | Q11: 0.5 | R11: 0.5 | T11: 1 | U11: 2 | W11: 1 | X11: 1 | Y11: 1 | Z11: 0 | AA11: 18
A12: 30849611 | B12: Amelinckx | C12: Matthias | D12: 1 | E12: 11 | F12: 2 | G12: 1 | H12: 2 | I12: 0.5 | J12: 1.5 | K12: 0.75 | L12: 2 | N12: 0.75 | O12: 2 | Q12: 1 | R12: 1 | S12: 1 | T12: 1 | U12: 2 | V12: 3 | W12: 1 | X12: 1 | Y12: 1 | Z12: 0 | AA12: 24.5
A13: 30598031 | B13: Livinaly | C13: Paola | D13: 3 | E13: 16 | F13: 1.75 | G13: 0.5 | H13: 2.5 | J13: 1 | K13: 1 | L13: 2 | N13: 0.75 | O13: 1.9 | P13: 3 | Q13: 1 | R13: 0 | S13: 2 | T13: 1 | U13: 2 | W13: 1 | X13: 1 | Y13: 0.75 | Z13: 0 | AA13: 23.15
A14: 33921124 | B14: Sanchez | C14: David | D14: 15 | E14: 13 | F14: 2 | G14: 1 | H14: 1.5 | I14: 0.5 | K14: 0.75 | L14: 1.5 | N14: 0.5 | O14: 1 | Q14: 0 | R14: 0.5 | T14: 0 | U14: 0 | W14: 1 | Y14: 0 | Z14: 0 | AA14: 10.25
A15: 31963201 | B15: Zerpa | C15: Azael | D15: 18 | E15: 14 | F15: 1 | G15: 1 | H15: 1 | I15: 1.5 | J15: 2 | K15: 0.5 | L15: 1 | N15: 0.75 | O15: 1.5 | Q15: 0 | R15: 0 | T15: 1 | U15: 2 | W15: 1 | X15: 1 | Y15: 0.5 | Z15: 1 | AA15: 16.75
A16: 32122110 | B16: Silva | C16: Elva | D16: 22 | E16: 17 | F16: 1.75 | G16: 1 | H16: 1 | J16: 2 | K16: 0.5 | L16: 1 | N16: 1 | O16: 0.5 | Q16: 0 | R16: 0 | T16: 0 | U16: 0 | W16: 1 | X16: 1 | Y16: 0 | Z16: 0 | AA16: 10.75
A17: 30022208 | B17: Viñas | C17: Gabriel | D17: 17 | F17: 2 | G17: 1 | H17: 0.5 | I17: 1 | J17: 0.75 | K17: 0.75 | L17: 1 | N17: 0.5 | O17: 1 | Q17: 0.5 | R17: 0.75 | T17: 0 | U17: 0 | W17: 0.5 | X17: 1 | Y17: 1 | Z17: 0.75 | AA17: 13
A18: 32242412 | B18: Kchour | C18: Mohamad | D18: 7 | F18: 2 | G18: 1 | H18: 0.5 | I18: 3 | K18: 0.5 | L18: 0 | N18: 0.25 | O18: 1 | Q18: 0.5 | R18: 0.5 | T18: 0.25 | U18: 0 | W18: 0.75 | X18: 0.5 | Y18: 0 | Z18: 0.5 | AA18: =SUM(F18:Z18) -> 11.25
A19: 32491310 | B19: Casais | C19: Elohym | D19: 19 | F19: 2 | G19: 1 | H19: 0.5 | I19: 1.5 | J19: 1.5 | K19: 0.5 | L19: 0 | N19: 0.5 | O19: 0 | P19: 1 | Q19: 0.5 | R19: 0 | S19: 1 | T19: 0.5 | U19: 0 | W19: 0.5 | X19: 0 | Y19: 0.25 | Z19: 0 | AA19: 11.25
A20: 31423000 | B20: Pizza | C20: Emmanuel | D20: 20 | F20: 0 | G20: 0 | H20: 0 | I20: 0 | J20: 0 | K20: 0.5 | L20: 0.5 | N20: 0 | O20: 0 | Q20: 0 | R20: 0 | T20: 0 | U20: 0 | W20: 0.5 | X20: 1 | Y20: 0 | Z20: 0 | AA20: 2.5
A21: 31988236 | B21: Fiandaca | C21: Santiago | D21: 21 | F21: 2 | G21: 1 | H21: 0.25 | I21: 0.5 | J21: 0 | K21: 0.5 | L21: 1 | N21: 0.75 | O21: 1 | P21: 1 | Q21: 0.75 | R21: 0 | T21: 0 | U21: 0 | W21: 0 | X21: 0 | Y21: 0 | Z21: 1 | AA21: 9.75

Sheet Eval. Cont.
A1: Correo Unimet | B1: Nombre | C1: Quiz 1 de EvaluaciÃ³n Continua - IntroducciÃ³n (52110139) | D1: Quiz 2 de EvaluaciÃ³n Continua - Operaciones (52110120) | E1: Quiz 3 de EvaluaciÃ³n Continua - Condicionales (52110140) | F1: Quiz 4 de EvaluaciÃ³n continua - Bucles (52110129) | G1: Quiz 5 de EvaluaciÃ³n continua - Listas (52110132) | H1: Quiz 6 de EvaluaciÃ³n Continua - diccionarios (52110122) | I1: Quiz 7 de EvaluaciÃ³n Continua - Funciones (52110136) | J1: Quiz 8 de EvaluaciÃ³n Continua - ProgramaciÃ³n Orientada a Objetos (52110123) | K1: Quiz 9 de EvaluaciÃ³n Continua - Herencia (52110124) | L1: Quiz 10 de EvaluaciÃ³n Continua - Diagrama de Clases (52110128) | M1: Quiz 11 de EvaluaciÃ³n Continua - APIs y Archivos (52110138) | N1: Quiz 13 de EvaluaciÃ³n ContÃ­nua - Recursividad (52110127) | O1: Quiz 14 de EvaluaciÃ³n ContÃ­nua - Ordenamiento (52110126) | P1: Quiz 15 de EvaluaciÃ³n ContÃ­nua - Complejidad (52110133) | Q1: Acum
A2: sebastian.alfonzo@correo.unimet.edu.ve | B2: Alfonzo. Sebastian | C2: 16 | D2: 16.33 | E2: 12 | F2: 10 | J2: 10 | K2: 14 | L2: 13.5 | Q2: =SUM(C2:P2)/COUNTA(C$1:P$1) -> 6.5592857
A3: matthias.amelinckx@correo.unimet.edu.ve | B3: Amelinckx. Matthias | C3: 15.33 | D3: 20 | E3: 10 | F3: 13 | G3: 0 | H3: 12 | I3: 14 | J3: 10 | K3: 13 | L3: 20 | M3: 20 | N3: 10 | O3: 14 | Q3: =SUM(C3:P3)/COUNTA(C$1:P$1) -> 12.237857
A4: flavia.aray@correo.unimet.edu.ve | B4: Aray. Flavia | C4: 18 | D4: 17 | E4: 18 | F4: 20 | G4: 18 | H4: 18 | I4: 20 | J4: 19 | K4: 16 | L4: 10 | M4: 18 | N4: 18 | O4: 16 | P4: 18 | Q4: =SUM(C4:P4)/COUNTA(C$1:P$1) -> 17.428571
A5: angelica.blanco@correo.unimet.edu.ve | B5: Blanco. AngÃ©lica | C5: 16 | D5: 17 | E5: 14 | F5: 17.5 | G5: 16 | H5: 18 | I5: 14 | J5: 15 | K5: 16 | L5: 20 | M5: 16 | N5: 14 | Q5: =SUM(C5:P5)/COUNTA(C$1:P$1) -> 13.821429
A6: gabriel.brusco@correo.unimet.edu.ve | B6: Brusco. Gabriel | C6: 14 | D6: 10.33 | E6: 15 | F6: 10 | G6: 10 | H6: 10 | I6: 10 | J6: 18 | K6: 12 | L6: 16 | M6: 16 | N6: 10 | O6: 10 | P6: 10 | Q6: =SUM(C6:P6)/COUNTA(C$1:P$1) -> 12.237857
A7: casais.elohym@correo.unimet.edu.ve | B7: Casais. Elohym | C7: 12 | D7: 14 | E7: 12 | F7: 10 | G7: 18 | H7: 10 | I7: 10 | J7: 10 | K7: 10 | L7: 12 | M7: 15 | N7: 14 | P7: 14 | Q7: =SUM(C7:P7)/COUNTA(C$1:P$1) -> 11.5
A8: diego.callender@correo.unimet.edu.ve | B8: Diego. Callender | C8: 18 | D8: 14.33 | E8: 18 | F8: 17 | G8: 18 | H8: 18 | I8: 14 | J8: 15 | K8: 18 | L8: 10 | M8: 16 | N8: 10 | O8: 10 | P8: 10 | Q8: =SUM(C8:P8)/COUNTA(C$1:P$1) -> 14.737857
A9: sfiandaca@correo.unimet.edu.ve | B9: Fiandaca. Santiago | C9: 16 | D9: 17 | E9: 12 | F9: 15.5 | G9: 18 | H9: 15.5 | I9: 14 | J9: 10 | K9: 11.6 | L9: 10 | M9: 10 | N9: 10 | O9: 10 | P9: 10 | Q9: =SUM(C9:P9)/COUNTA(C$1:P$1) -> 12.828571
A10: flavia.mercado@correo.unimet.edu.ve | B10: Flavia. Mercado | C10: 18.67 | D10: 17 | E10: 15 | F10: 14 | G10: 18 | H10: 12.5 | I10: 18 | J10: 18 | K10: 19 | L10: 18.5 | M10: 18 | N10: 16 | O10: 14 | P10: 20 | Q10: =SUM(C10:P10)/COUNTA(C$1:P$1) -> 16.905
A11: paola.haiek@correo.unimet.edu.ve | B11: Haiek. Paola | C11: 20 | D11: 19 | E11: 16 | F11: 16 | G11: 18 | H11: 20 | I11: 16 | J11: 19 | K11: 19 | L11: 19.6 | M11: 16 | N11: 14 | Q11: =SUM(C11:P11)/COUNTA(C$1:P$1) -> 15.185714
A12: h.andrea@correo.unimet.edu.ve | B12: HernÃ¡ndez. Andrea | C12: 18 | D12: 19 | E12: 13 | F12: 19.5 | G12: 20 | H12: 20 | I12: 18 | J12: 14 | K12: 15 | L12: 18 | M12: 16 | N12: 20 | O12: 18 | P12: 14 | Q12: =SUM(C12:P12)/COUNTA(C$1:P$1) -> 17.321429
A13: idrobo.jose@correo.unimet.edu.ve | B13: Idrobo. Jose | C13: 20 | D13: 0 | E13: 15 | Q13: =SUM(C13:P13)/COUNTA(C$1:P$1) -> 2.5
A14: mohamad.kchour@correo.unimet.edu.ve | B14: Kchour. Mohamad | C14: 14 | D14: 13 | E14: 15 | F14: 11 | G14: 13 | H14: 16 | I14: 18 | J14: 18 | K14: 17 | L14: 18.67 | M14: 18 | N14: 18 | O14: 16 | P14: 14 | Q14: =SUM(C14:P14)/COUNTA(C$1:P$1) -> 15.690714
A15: plivinaly@correo.unimet.edu.ve | B15: Livinaly. Paola | C15: 14 | D15: 15 | E15: 12 | F15: 9.5 | G15: 16 | H15: 18 | I15: 10 | J15: 19.33 | K15: 18 | L15: 19.6 | M15: 20 | N15: 18 | O15: 18 | P15: 18 | Q15: =SUM(C15:P15)/COUNTA(C$1:P$1) -> 16.102143
A16: laura.medina@correo.unimet.edu.ve | B16: Medina. Laura | C16: 20 | D16: 16.67 | E16: 16 | F16: 20 | G16: 18 | H16: 20 | I16: 20 | J16: 14 | K16: 19 | L16: 17.33 | M16: 18 | N16: 18 | O16: 20 | P16: 20 | Q16: =SUM(C16:P16)/COUNTA(C$1:P$1) -> 18.357143
A17: angel.moya@correo.unimet.edu.ve | B17: Moya. Angel | C17: 16 | D17: 15 | E17: 10 | F17: 10 | G17: 12 | H17: 13.5 | I17: 14 | Q17: =SUM(C17:P17)/COUNTA(C$1:P$1) -> 6.4642857
A18: samuel.pamphile@correo.unimet.edu.ve | B18: Pamphile. Samuel | Q18: =SUM(C18:P18)/COUNTA(C$1:P$1) -> 0
A19: pizzap@correo.unimet.edu.ve | B19: Pizza. Emmanuel | C19: 16 | D19: 17 | E19: 18 | F19: 14 | G19: 18 | H19: 16.5 | I19: 16 | J19: 16 | K19: 11 | L19: 10 | M19: 10 | N19: 10 | O19: 18 | P19: 12 | Q19: =SUM(C19:P19)/COUNTA(C$1:P$1) -> 14.464286
A20: rodriguez.rafael@correo.unimet.edu.ve | B20: Rodriguez. Rafael | C20: 18 | D20: 9.67 | E20: 10 | Q20: =SUM(C20:P20)/COUNTA(C$1:P$1) -> 2.6907143
A21: luciano.rojas@correo.unimet.edu.ve | B21: Rojas. Luciano | C21: 19.33 | D21: 20 | E21: 16 | F21: 18 | G21: 20 | H21: 17.5 | I21: 18 | J21: 16 | K21: 17.33 | L21: 19.6 | M21: 19 | N21: 20 | O21: 16 | P21: 16 | Q21: =SUM(C21:P21)/COUNTA(C$1:P$1) -> 18.054286
A22: joseruiz@correo.unimet.edu.ve | B22: Ruiz. JosÃ© | C22: 20 | D22: 18.33 | E22: 16 | F22: 18 | G22: 20 | H22: 20 | I22: 10 | J22: 10 | K22: 15 | L22: 10 | M22: 15 | N22: 14 | O22: 12 | P22: 10 | Q22: =SUM(C22:P22)/COUNTA(C$1:P$1) -> 14.880714
A23: cesar.salimbeni@correo.unimet.edu.ve | B23: Salimbeni. CÃ©sar | C23: 12 | D23: 17 | E23: 13.33 | F23: 16 | G23: 20 | H23: 17.5 | I23: 18 | J23: 17.33 | K23: 16.67 | L23: 17 | M23: 20 | N23: 16 | O23: 20 | P23: 18 | Q23: =SUM(C23:P23)/COUNTA(C$1:P$1) -> 17.059286
A24: d.sanchez@correo.unimet.edu.ve | B24: Sanchez. David | C24: 10 | D24: 17 | E24: 15 | F24: 11.5 | G24: 16 | H24: 13.5 | I24: 16 | J24: 10.67 | K24: 17 | L24: 19 | M24: 20 | N24: 16 | O24: 18.67 | P24: 20 | Q24: =SUM(C24:P24)/COUNTA(C$1:P$1) -> 15.738571
A25: daniel.saracual@correo.unimet.edu.ve | B25: Saracual. Daniel | C25: 18 | D25: 18 | E25: 16 | F25: 13 | G25: 12 | H25: 17.5 | I25: 18 | J25: 14 | K25: 14 | L25: 18 | M25: 20 | N25: 14 | O25: 20 | P25: 18 | Q25: =SUM(C25:P25)/COUNTA(C$1:P$1) -> 16.464286
A26: elva.silva@correo.unimet.edu.ve | B26: Silva. Elva | C26: 18 | D26: 19 | E26: 14.33 | F26: 11.5 | G26: 10 | H26: 10 | I26: 10 | J26: 16 | K26: 14 | L26: 10 | M26: 10 | N26: 10 | O26: 10 | P26: 10 | Q26: =SUM(C26:P26)/COUNTA(C$1:P$1) -> 12.345
A27: s.erik@correo.unimet.edu.ve | B27: Steinmetz. Erik | C27: 12 | D27: 18 | E27: 14 | F27: 12 | G27: 20 | H27: 15.5 | I27: 18 | J27: 16.67 | K27: 14 | L27: 15 | M27: 18 | N27: 12 | P27: 18 | Q27: =SUM(C27:P27)/COUNTA(C$1:P$1) -> 14.512143
A28: sofia.trezza@correo.unimet.edu.ve | B28: Trezza. Sofia | C28: 16 | D28: 16 | E28: 16 | F28: 10 | G28: 16 | H28: 18 | I28: 16 | J28: 10 | K28: 17 | L28: 20 | M28: 10 | N28: 10 | O28: 16 | P28: 20 | Q28: =SUM(C28:P28)/COUNTA(C$1:P$1) -> 15.071429
A29: nicole.ugartepelayo@correo.unimet.edu.ve | B29: Ugarte-Pelayo. Nicole | C29: 18 | Q29: =SUM(C29:P29)/COUNTA(C$1:P$1) -> 1.2857143
A30: gvinas@correo.unimet.edu.ve | B30: ViÃ±as. Gabriel | C30: 18 | D30: 13 | E30: 15 | F30: 15.5 | G30: 17 | H30: 14 | I30: 10 | J30: 9 | K30: 15 | L30: 14 | M30: 10 | N30: 14 | O30: 6 | P30: 14 | Q30: =SUM(C30:P30)/COUNTA(C$1:P$1) -> 13.178571
A31: azael.zerpa@correo.unimet.edu.ve | B31: Zerpa. Azael | C31: 16 | D31: 16.67 | E31: 18 | F31: 20 | G31: 18 | H31: 19.5 | I31: 20 | J31: 18 | K31: 20 | L31: 20 | M31: 20 | N31: 18 | O31: 20 | P31: 16 | Q31: =SUM(C31:P31)/COUNTA(C$1:P$1) -> 18.583571

Sheet Partic
A1: CI | B1: Nombre de Pila | C1: Nombre y apellido | D1: 45664 | E1: 45666 | F1: 45671 | G1: 45673 | H1: 45678 | I1: 45680 | J1: 45685 | K1: 45687 | L1: 45694 | M1: 45701 | N1: 45706 | O1: 45708 | P1: 45713 | Q1: 45715 | R1: 45729 | S1: TOTAL
A2: =Lista!B8 -> 28410856 | B2: =Lista!E8&" "&Lista!F8 -> Sebastian Eduardo | C2: =Lista!E8&" "&Lista!D8 -> Sebastian Alfonzo | D2: 1 | S2: =SUM(D2:R2) -> 1
A3: =Lista!B9 -> 30849611 | B3: =Lista!E9&" "&Lista!F9 -> Matthias | C3: =Lista!E9&" "&Lista!D9 -> Matthias Amelinckx | D3: 1 | F3: 2 | S3: =SUM(D3:R3) -> 3
A4: =Lista!B10 -> 29666935 | B4: =Lista!E10&" "&Lista!F10 -> Flavia Isabel | C4: =Lista!E10&" "&Lista!D10 -> Flavia Aray | D4: 1 | F4: 5 | H4: 3 | J4: 3 | L4: 3 | N4: 3 | O4: 1 | Q4: 1 | S4: =SUM(D4:R4) -> 20
A5: =Lista!B11 -> 30765878 | B5: =Lista!E11&" "&Lista!F11 -> Angélica | C5: =Lista!E11&" "&Lista!D11 -> Angélica Blanco | D5: 1 | E5: 2 | K5: 1 | S5: =SUM(D5:R5) -> 4
A6: =Lista!B12 -> 32729082 | B6: =Lista!E12&" "&Lista!F12 -> Gabriel Alejandro | C6: =Lista!E12&" "&Lista!D12 -> Gabriel Brusco | H6: 2 | S6: =SUM(D6:R6) -> 2
A7: =Lista!B13 -> 31071592 | B7: =Lista!E13&" "&Lista!F13 -> Diego Alejandro | C7: =Lista!E13&" "&Lista!D13 -> Diego Callender | F7: 1 | G7: 2 | H7: 2 | P7: 2 | Q7: 1 | S7: =SUM(D7:R7) -> 8
A8: =Lista!B14 -> 32491310 | B8: =Lista!E14&" "&Lista!F14 -> Elohym Joham | C8: =Lista!E14&" "&Lista!D14 -> Elohym Casais | S8: =SUM(D8:R8) -> 0
A9: =Lista!B15 -> 31988236 | B9: =Lista!E15&" "&Lista!F15 -> Santiago De Jesús | C9: =Lista!E15&" "&Lista!D15 -> Santiago Fiandaca | K9: 1 | S9: =SUM(D9:R9) -> 1
A10: =Lista!B16 -> 31112818 | B10: =Lista!E16&" "&Lista!F16 -> Paola Marie | C10: =Lista!E16&" "&Lista!D16 -> Paola Haiek | I10: 2 | K10: 1 | M10: 2 | O10: 2 | S10: =SUM(D10:R10) -> 7
A11: =Lista!B17 -> 30030485 | B11: =Lista!E17&" "&Lista!F17 -> Andrea | C11: =Lista!E17&" "&Lista!D17 -> Andrea Hernandez | R11: 2 | S11: =SUM(D11:R11) -> 2
A12: =Lista!B18 -> 30793086 | B12: =Lista!E18&" "&Lista!F18 -> Jose Daniel | C12: =Lista!E18&" "&Lista!D18 -> Jose Idrobo | S12: =SUM(D12:R12) -> 0
A13: =Lista!B19 -> 32242412 | B13: =Lista!E19&" "&Lista!F19 -> Mohamad Ali | C13: =Lista!E19&" "&Lista!D19 -> Mohamad Kchour | J13: 1 | L13: 1 | N13: 3 | O13: 1 | P13: 1 | R13: 1 | S13: =SUM(D13:R13) -> 8
A14: =Lista!B20 -> 30598031 | B14: =Lista!E20&" "&Lista!F20 -> Paola Graciela | C14: =Lista!E20&" "&Lista!D20 -> Paola Livinaly | F14: 2 | H14: 2 | K14: 2 | M14: 1 | N14: 2 | S14: =SUM(D14:R14) -> 9
A15: =Lista!B21 -> 31852058 | B15: =Lista!E21&" "&Lista!F21 -> Laura Maria | C15: =Lista!E21&" "&Lista!D21 -> Laura Medina | G15: 3 | H15: 2 | I15: 1 | J15: 1 | K15: 1 | N15: 1 | O15: 1 | P15: 1 | Q15: 1 | R15: 1 | S15: =SUM(D15:R15) -> 13
A16: =Lista!B22 -> 30114012 | B16: =Lista!E22&" "&Lista!F22 -> Flavia | C16: =Lista!E22&" "&Lista!D22 -> Flavia Mercado | D16: 2 | F16: 1 | G16: 1 | I16: 1 | L16: 3 | O16: 1 | P16: 1 | S16: =SUM(D16:R16) -> 10
A17: =Lista!B23 -> 26954417 | B17: =Lista!E23&" "&Lista!F23 -> Angel Jose | C17: =Lista!E23&" "&Lista!D23 -> Angel Moya | S17: =SUM(D17:R17) -> 0
A18: =Lista!B24 -> 31448943 | B18: =Lista!E24&" "&Lista!F24 -> Samuel Abraham | C18: =Lista!E24&" "&Lista!D24 -> Samuel Pamphile | D18: 2 | E18: 1 | H18: 2 | S18: =SUM(D18:R18) -> 5
A19: =Lista!B25 -> 31423000 | B19: =Lista!E25&" "&Lista!F25 -> Emmanuel Giuseppe | C19: =Lista!E25&" "&Lista!D25 -> Emmanuel Pizza | I19: 1 | M19: 1 | P19: 1 | S19: =SUM(D19:R19) -> 3
A20: =Lista!B26 -> 31046285 | B20: =Lista!E26&" "&Lista!F26 -> Rafael | C20: =Lista!E26&" "&Lista!D26 -> Rafael Rodriguez | L20: 1 | S20: =SUM(D20:R20) -> 1
A21: =Lista!B27 -> 31255343 | B21: =Lista!E27&" "&Lista!F27 -> Luciano Nicola | C21: =Lista!E27&" "&Lista!D27 -> Luciano Rojas | F21: 1 | G21: 1 | J21: 1 | S21: =SUM(D21:R21) -> 3
A22: =Lista!B28 -> 32401366 | B22: =Lista!E28&" "&Lista!F28 -> José Alejandro | C22: =Lista!E28&" "&Lista!D28 -> José Ruiz | R22: 2 | S22: =SUM(D22:R22) -> 2
A23: =Lista!B29 -> 32121917 | B23: =Lista!E29&" "&Lista!F29 -> César Alexander | C23: =Lista!E29&" "&Lista!D29 -> César Salimbeni | F23: 2 | G23: 2 | I23: 1 | J23: 2 | K23: 2 | L23: 1 | M23: 2 | O23: 1 | P23: 2 | R23: 2 | S23: =SUM(D23:R23) -> 17
A24: =Lista!B30 -> 33921124 | B24: =Lista!E30&" "&Lista!F30 -> David Eduardo | C24: =Lista!E30&" "&Lista!D30 -> David Sanchez | N24: 1 | O24: 1 | R24: 1 | S24: =SUM(D24:R24) -> 3
A25: =Lista!B31 -> 31703910 | B25: =Lista!E31&" "&Lista!F31 -> Daniel Antonio | C25: =Lista!E31&" "&Lista!D31 -> Daniel Saracual | G25: 2 | Q25: 1 | S25: =SUM(D25:R25) -> 3
A26: =Lista!B32 -> 32122110 | B26: =Lista!E32&" "&Lista!F32 -> Elva María | C26: =Lista!E32&" "&Lista!D32 -> Elva Silva | D26: 1 | F26: 2 | I26: 2 | M26: 2 | N26: 2 | R26: 1 | S26: =SUM(D26:R26) -> 10
A27: =Lista!B33 -> 30720123 | B27: =Lista!E33&" "&Lista!F33 -> Erik | C27: =Lista!E33&" "&Lista!D33 -> Erik Steinmetz | S27: =SUM(D27:R27) -> 0
A28: =Lista!B34 -> 29895575 | B28: =Lista!E34&" "&Lista!F34 -> Sofia Gisela | C28: =Lista!E34&" "&Lista!D34 -> Sofia Trezza | H28: 2 | J28: 2 | K28: 1 | L28: 2 | N28: 2 | O28: 2 | S28: =SUM(D28:R28) -> 11
A29: =Lista!B35 -> 31615220 | B29: =Lista!E35&" "&Lista!F35 -> Nicole Alejandra | C29: =Lista!E35&" "&Lista!D35 -> Nicole Ugarte Pelayo | S29: =SUM(D29:R29) -> 0
A30: =Lista!B36 -> 30022208 | B30: =Lista!E36&" "&Lista!F36 -> Gabriel Alejandro | C30: =Lista!E36&" "&Lista!D36 -> Gabriel Viñas | E30: 1 | K30: 2 | N30: 1 | R30: 1 | S30: =SUM(D30:R30) -> 5
A31: =Lista!B37 -> 31963201 | B31: =Lista!E37&" "&Lista!F37 -> Azael Alonso | C31: =Lista!E37&" "&Lista!D37 -> Azael Zerpa | I31: 1 | N31: 1 | S31: =SUM(D31:R31) -> 2
B32: TOTAL | D32: =SUM(D2:D31) -> 9 | E32: =SUM(E2:E31) -> 4 | F32: =SUM(F2:F31) -> 16 | G32: =SUM(G2:G31) -> 11 | H32: =SUM(H2:H31) -> 15 | I32: =SUM(I2:I31) -> 9 | J32: =SUM(J2:J31) -> 10 | K32: =SUM(K2:K31) -> 11 | ... R32: =SUM(R2:R31) -> 11 | S32: =SUM(D32:R32) -> 153

Sheet Tareas
A1: Correo Unimet | B1: Nombre | C1: Tarea 1: GitHub (52110170) | D1: Tarea 2: Arepas DinÃ¡micas (52110169) | E1: Tarea 3: Perfil de usuario (52110171) | F1: Tarea 4: AÃ±o Bisiesto (52110172) | G1: Tarea 5: Â¡Batalla! (juego de cartas) (52110173) | H1: Tarea 6: Batalla pokÃ©mon (52110174) | I1: Tarea 7: Batalla PokÃ©mon con Funciones (52110175) | J1: Tarea 8: Registro de vehÃ­culos (52110176) | K1: Tarea 9: Marcar tarjeta (52110177) | L1: Tarea 10: Diagrama de Clases (52110162) | M1: Tarea 11: PokÃ©dex (52110163) | N1: Tarea 13: RecursiÃ³n (52110165) | O1: Tarea 14: Algoritmos de Ordenamiento (52110166) | P1: Tarea 15: Complejidad (52110168) | Q1: Total
A2: sebastian.alfonzo@correo.unimet.edu.ve | B2: Alfonzo. Sebastian | C2: TRUE | D2: TRUE | E2: TRUE | F2: FALSE | G2: FALSE | H2: FALSE | I2: FALSE | J2: FALSE | K2: FALSE | L2: FALSE | M2: FALSE | N2: FALSE | O2: FALSE | P2: FALSE | Q2: =COUNTIF(C2:P2,TRUE)/COUNTA(C$1:P$1) -> 0.21428571
A3: matthias.amelinckx@correo.unimet.edu.ve | B3: Amelinckx. Matthias | C3: TRUE | D3: TRUE | E3: TRUE | F3: FALSE | G3: TRUE | H3: FALSE | I3: FALSE | J3: FALSE | K3: FALSE | L3: FALSE | M3: FALSE | N3: FALSE | O3: FALSE | P3: FALSE | Q3: =COUNTIF(C3:P3,TRUE)/COUNTA(C$1:P$1) -> 0.28571429
A4: flavia.aray@correo.unimet.edu.ve | B4: Aray. Flavia | C4: TRUE | D4: TRUE | E4: TRUE | F4: FALSE | G4: FALSE | H4: FALSE | I4: FALSE | J4: FALSE | K4: FALSE | L4: FALSE | M4: FALSE | N4: FALSE | O4: FALSE | P4: FALSE | Q4: =COUNTIF(C4:P4,TRUE)/COUNTA(C$1:P$1) -> 0.21428571
A5: angelica.blanco@correo.unimet.edu.ve | B5: Blanco. AngÃ©lica | C5: TRUE | D5: TRUE | E5: TRUE | F5: FALSE | G5: TRUE | H5: TRUE | I5: FALSE | J5: FALSE | K5: FALSE | L5: FALSE | M5: FALSE | N5: FALSE | O5: FALSE | P5: FALSE | Q5: =COUNTIF(C5:P5,TRUE)/COUNTA(C$1:P$1) -> 0.35714286
A6: gabriel.brusco@correo.unimet.edu.ve | B6: Brusco. Gabriel | C6: FALSE | D6: FALSE | E6: TRUE | F6: FALSE | G6: FALSE | H6: FALSE | I6: FALSE | J6: FALSE | K6: FALSE | L6: FALSE | M6: FALSE | N6: FALSE | O6: FALSE | P6: FALSE | Q6: =COUNTIF(C6:P6,TRUE)/COUNTA(C$1:P$1) -> 0.071428571
